<?xml version="1.0" ?>
<!-- Generated using onshape-to-robot -->
<!-- Onshape https://cad.onshape.com/documents/fb645318a27646d1d8840be6/w/d1cae8805fb652b4d1614997/e/804a1da43f242001a05129b4 -->
<mujoco model="mjcf">
  <compiler angle="radian" meshdir="assets" autolimits="true"/>
  <default>
    <default class="mjcf">
      <joint frictionloss="0.1" armature="0.005"/>
      <position kp="50" dampratio="1"/>
      <default class="visual">
        <geom type="mesh" contype="0" conaffinity="0" group="2"/>
      </default>
      <default class="collision">
        <geom group="3"/>
      </default>
    </default>
  </default>
  <!-- Additional sensors.xml -->
  <sensor>
    <gyro name="imu_ang_vel" site="torso"/>
    <velocimeter name="imu_lin_vel" site="torso"/>
    <accelerometer name="imu_lin_acc" site="torso"/>
    <subtreeangmom name="root_angmom" body="torso_subassembly"/>
  </sensor>
  <worldbody>
    <!-- Link torso_subassembly -->
    <body name="torso_subassembly" pos="0 0 0" quat="1 0 0 0" childclass="mjcf">
      <freejoint name="torso_subassembly_freejoint"/>
      <inertial pos="-0.00114344 -0.000332817 0.0495407" mass="2.90375" fullinertia="0.0354956 0.00454723 0.0341916 -5.22042e-06 6.42201e-05 4.37957e-05"/>
      <!-- Part rs00 -->
      <!-- Part torso22 -->
      <geom type="mesh" class="visual" pos="-0.000263039 0.233572 -0.0901625" quat="0 0 -0.990051 0.140711" mesh="torso22" material="torso22_material"/>
      <!-- Part bno055 -->
      <geom type="mesh" class="visual" pos="-0.00011057 -0.000137208 0.11838" quat="0.00176287 0 -0.999998 -0" mesh="bno055" material="bno055_material"/>
      <!-- Part hex_socket_head_cap_screw_m4x0_70_x_20__832e47d784177ea3f1dabbaab534416e -->
      <!-- Part rs00_2 -->
      <!-- Part hex_socket_head_cap_screw_m4x0_70_x_20__832e47d784177ea3f1dabbaab534416e_2 -->
      <!-- Part hex_socket_head_cap_screw_m3x0_50_x_8__d566997e1880d7fd3377c5b0ee12206c -->
      <!-- Part hex_socket_head_cap_screw_m3x0_50_x_8__d566997e1880d7fd3377c5b0ee12206c_2 -->
      <!-- Part bearing_35_72_17 -->
      <geom type="mesh" class="visual" pos="-0.000887454 -0.130401 0.0222352" quat="0.0013181 -0.00114402 -0.655472 -0.755218" mesh="bearing_35_72_17" material="bearing_35_72_17_material"/>
      <!-- Part hex_socket_head_cap_screw_m4x0_70_x_20__832e47d784177ea3f1dabbaab534416e_3 -->
      <!-- Part hex_socket_head_cap_screw_m4x0_70_x_20__832e47d784177ea3f1dabbaab534416e_4 -->
      <!-- Part hex_socket_head_cap_screw_m4x0_70_x_20__832e47d784177ea3f1dabbaab534416e_5 -->
      <!-- Part robstrideo0 -->
      <geom type="mesh" class="visual" pos="0.672139 -0.149366 0.0777701" quat="0.0013181 -0.00114402 -0.655472 -0.755218" mesh="robstrideo0" material="robstrideo0_material"/>
      <!-- Part hex_socket_head_cap_screw_m3x0_50_x_8__d566997e1880d7fd3377c5b0ee12206c_3 -->
      <!-- Part hex_socket_head_cap_screw_m4x0_70_x_20__832e47d784177ea3f1dabbaab534416e_6 -->
      <!-- Part hex_socket_head_cap_screw_m3x0_50_x_8__d566997e1880d7fd3377c5b0ee12206c_4 -->
      <!-- Part imu -->
      <geom type="mesh" class="visual" pos="-0.000105634 -0.000137208 0.11978" quat="0 -0.00176287 0 -0.999998" mesh="imu" material="imu_material"/>
      <!-- Part hex_socket_head_cap_screw_m4x0_70_x_20__832e47d784177ea3f1dabbaab534416e_7 -->
      <!-- Part hex_socket_head_cap_screw_m4x0_70_x_20__832e47d784177ea3f1dabbaab534416e_8 -->
      <!-- Part hex_socket_head_cap_screw_m3x0_50_x_8__d566997e1880d7fd3377c5b0ee12206c_5 -->
      <!-- Part part_11 -->
      <geom type="mesh" class="visual" pos="-0.000172141 -0.00359564 -0.0311848" quat="0 0 -1 -0" mesh="part_11" material="part_11_material"/>
      <!-- Part hex_socket_head_cap_screw_m4x0_70_x_20__832e47d784177ea3f1dabbaab534416e_9 -->
      <!-- Part hex_socket_head_cap_screw_m3x0_50_x_8__d566997e1880d7fd3377c5b0ee12206c_6 -->
      <!-- Part robstrideo0_2 -->
      <geom type="mesh" class="visual" pos="0.672139 0.127661 0.0808551" quat="0.00114402 -0.0013181 -0.755218 -0.655472" mesh="robstrideo0" material="robstrideo0_material"/>
      <!-- Part hex_socket_head_cap_screw_m3x0_50_x_8__d566997e1880d7fd3377c5b0ee12206c_7 -->
      <!-- Part hex_socket_head_cap_screw_m3x0_50_x_8__d566997e1880d7fd3377c5b0ee12206c_8 -->
      <!-- Part hex_socket_head_cap_screw_m4x0_70_x_20__832e47d784177ea3f1dabbaab534416e_10 -->
      <!-- Part usbcan -->
      <geom type="mesh" class="visual" pos="-0.000263039 4.05842e-07 0.053309" quat="0 -0.707107 -0.707107 -0" mesh="usbcan" material="usbcan_material"/>
      <!-- Part torso12 -->
      <geom type="mesh" class="visual" pos="-0.000263039 4.05842e-07 -0.056966" quat="0 0 -1 -0" mesh="torso12" material="torso12_material"/>
      <!-- Part part_6 -->
      <geom type="mesh" class="visual" pos="-0.000235323 4.06463e-07 -0.056966" quat="0 -1 -0 0" mesh="part_6" material="part_6_material"/>
      <!-- Part hex_socket_head_cap_screw_m4x0_70_x_20__832e47d784177ea3f1dabbaab534416e_11 -->
      <!-- Part hex_socket_head_cap_screw_m4x0_70_x_20__832e47d784177ea3f1dabbaab534416e_12 -->
      <!-- Part torso22_2 -->
      <geom type="mesh" class="visual" pos="-0.000263039 4.05842e-07 -0.056966" quat="0 0 -1 -0" mesh="torso22" material="torso22_material"/>
      <!-- Part hex_socket_head_cap_screw_m4x0_70_x_20__832e47d784177ea3f1dabbaab534416e_13 -->
      <!-- Part bearing_35_72_17_2 -->
      <geom type="mesh" class="visual" pos="-0.000887454 0.130402 0.0222352" quat="0.00114402 -0.0013181 -0.755218 -0.655472" mesh="bearing_35_72_17" material="bearing_35_72_17_material"/>
      <!-- Part part_5 -->
      <geom type="mesh" class="visual" pos="-0.000263039 4.05842e-07 -0.056966" quat="0 0 -1 -0" mesh="part_5" material="part_5_material"/>
      <!-- Part part_10 -->
      <geom type="mesh" class="visual" pos="-0.000172839 -0.00362378 -0.0313828" quat="0 -0 -1 -0" mesh="part_10" material="part_10_material"/>
      <!-- Part hex_socket_head_cap_screw_m3x0_50_x_8__d566997e1880d7fd3377c5b0ee12206c_9 -->
      <!-- Part part_7 -->
      <geom type="mesh" class="visual" pos="-0.00062991 -0.000137208 -0.0289195" quat="0.00176287 0 -0.999998 -0" mesh="part_7" material="part_7_material"/>
      <!-- Part hex_socket_head_cap_screw_m3x0_50_x_8__d566997e1880d7fd3377c5b0ee12206c_10 -->
      <!-- Part hex_socket_head_cap_screw_m3x0_50_x_8__d566997e1880d7fd3377c5b0ee12206c_11 -->
      <!-- Part hex_socket_head_cap_screw_m4x0_70_x_20__832e47d784177ea3f1dabbaab534416e_14 -->
      <!-- Part xt_30_2x2_f -->
      <geom type="mesh" class="visual" pos="-3.97731e-05 -0.105809 0.0903709" quat="0.464297 0.534952 -0.533088 0.46268" mesh="xt_30_2x2_f" material="xt_30_2x2_f_material"/>
      <!-- Part hex_socket_head_cap_screw_m4x0_70_x_20__832e47d784177ea3f1dabbaab534416e_15 -->
      <!-- Part hex_socket_head_cap_screw_m4x0_70_x_20__832e47d784177ea3f1dabbaab534416e_16 -->
      <!-- Part hex_socket_head_cap_screw_m3x0_50_x_8__d566997e1880d7fd3377c5b0ee12206c_12 -->
      <!-- Part gpio -->
      <!-- Part gpio_2 -->
      <!-- Part gpio_3 -->
      <!-- Part gpio_4 -->
      <!-- Part gpio_5 -->
      <!-- Part gpio_6 -->
      <!-- Part gpio_7 -->
      <!-- Part gpio_8 -->
      <!-- Part gpio_9 -->
      <!-- Part mounting_holes -->
      <geom type="mesh" class="visual" pos="-0.0706979 -0.0361374 0.113628" quat="0.999998 0 0.00176287 0" mesh="mounting_holes" material="mounting_holes_material"/>
      <!-- Part gpio_10 -->
      <!-- Part gpio_11 -->
      <!-- Part switch -->
      <geom type="mesh" class="visual" pos="-0.0706979 -0.0361374 0.113628" quat="0.999998 0 0.00176287 0" mesh="switch" material="switch_material"/>
      <!-- Part gpio_12 -->
      <!-- Part gpio_13 -->
      <!-- Part gpio_14 -->
      <!-- Part gpio_15 -->
      <!-- Part gpio_16 -->
      <!-- Part gpio_17 -->
      <!-- Part rp1 -->
      <geom type="mesh" class="visual" pos="-0.0706979 -0.0361374 0.113628" quat="0.999998 0 0.00176287 0" mesh="rp1" material="rp1_material"/>
      <!-- Part gpio_18 -->
      <!-- Part hdmi_micro -->
      <geom type="mesh" class="visual" pos="-0.000536923 -0.000137433 0.102431" quat="0.707106 0.707106 0.00124654 -0.00124654" mesh="hdmi_micro" material="hdmi_micro_material"/>
      <!-- Part gpio_19 -->
      <!-- Part switch_2 -->
      <geom type="mesh" class="visual" pos="-0.0706979 -0.0361374 0.113628" quat="0.999998 0 0.00176287 0" mesh="switch__2" material="switch__2_material"/>
      <!-- Part gpio_20 -->
      <!-- Part gpio_21 -->
      <!-- Part gpio_22 -->
      <!-- Part gpio_23 -->
      <!-- Part usb_c -->
      <geom type="mesh" class="visual" pos="-0.0706979 -0.0361374 0.113628" quat="0.999998 0 0.00176287 0" mesh="usb_c" material="usb_c_material"/>
      <!-- Part ethernet -->
      <geom type="mesh" class="visual" pos="-0.000236925 -0.0356874 0.10243" quat="0.707106 0.707106 0.00124654 -0.00124654" mesh="ethernet" material="ethernet_material"/>
      <!-- Part gpio_24 -->
      <!-- Part gpio_25 -->
      <!-- Part pmic -->
      <geom type="mesh" class="visual" pos="-0.0706979 -0.0361374 0.113628" quat="0.999998 0 0.00176287 0" mesh="pmic" material="pmic_material"/>
      <!-- Part hdmi_micro_2 -->
      <geom type="mesh" class="visual" pos="-0.000536923 -0.000137433 0.102431" quat="0.707106 0.707106 0.00124654 -0.00124654" mesh="hdmi_micro__2" material="hdmi_micro__2_material"/>
      <!-- Part gpio_26 -->
      <!-- Part gpio_27 -->
      <!-- Part mounting_holes_2 -->
      <geom type="mesh" class="visual" pos="-0.0706979 -0.0361374 0.113628" quat="0.999998 0 0.00176287 0" mesh="mounting_holes__2" material="mounting_holes__2_material"/>
      <!-- Part ethernet_2 -->
      <geom type="mesh" class="visual" pos="-0.000236925 -0.0356874 0.10243" quat="0.707106 0.707106 0.00124654 -0.00124654" mesh="ethernet__2" material="ethernet__2_material"/>
      <!-- Part ir -->
      <geom type="mesh" class="visual" pos="-0.0706979 -0.0361374 0.113628" quat="0.999998 0 0.00176287 0" mesh="ir" material="ir_material"/>
      <!-- Part gpio_28 -->
      <!-- Part pcie -->
      <geom type="mesh" class="visual" pos="-0.0706979 -0.0361374 0.113628" quat="0.999998 0 0.00176287 0" mesh="pcie" material="pcie_material"/>
      <!-- Part pwr_connector -->
      <geom type="mesh" class="visual" pos="-0.0706979 -0.0361374 0.113628" quat="0.999998 0 0.00176287 0" mesh="pwr_connector" material="pwr_connector_material"/>
      <!-- Part pcie_2 -->
      <geom type="mesh" class="visual" pos="-0.0706979 -0.0361374 0.113628" quat="0.999998 0 0.00176287 0" mesh="pcie__2" material="pcie__2_material"/>
      <!-- Part gpio_29 -->
      <!-- Part gpio_30 -->
      <!-- Part pcb -->
      <geom type="mesh" class="visual" pos="-0.0706979 -0.0361374 0.113628" quat="0.999998 0 0.00176287 0" mesh="pcb" material="pcb_material"/>
      <!-- Part gpio_31 -->
      <!-- Part uart -->
      <geom type="mesh" class="visual" pos="-0.0706979 -0.0361374 0.113628" quat="0.999998 0 0.00176287 0" mesh="uart" material="uart_material"/>
      <!-- Part gpio_32 -->
      <!-- Part ethernet_3 -->
      <geom type="mesh" class="visual" pos="-0.000236925 -0.0356874 0.10243" quat="0.707106 0.707106 0.00124654 -0.00124654" mesh="ethernet__3" material="ethernet__3_material"/>
      <!-- Part gpio_33 -->
      <!-- Part gpio_34 -->
      <!-- Part mounting_holes_3 -->
      <geom type="mesh" class="visual" pos="-0.0706979 -0.0361374 0.113628" quat="0.999998 0 0.00176287 0" mesh="mounting_holes__3" material="mounting_holes__3_material"/>
      <!-- Part gpio_35 -->
      <!-- Part gpio_36 -->
      <!-- Part gpio_37 -->
      <!-- Part ir_2 -->
      <geom type="mesh" class="visual" pos="-0.0706979 -0.0361374 0.113628" quat="0.999998 0 0.00176287 0" mesh="ir__2" material="ir__2_material"/>
      <!-- Part mounting_holes_4 -->
      <geom type="mesh" class="visual" pos="-0.0706979 -0.0361374 0.113628" quat="0.999998 0 0.00176287 0" mesh="mounting_holes__4" material="mounting_holes__4_material"/>
      <!-- Part connector -->
      <geom type="mesh" class="visual" pos="-0.0706979 -0.0361374 0.113628" quat="0.999998 0 0.00176287 0" mesh="connector" material="connector_material"/>
      <!-- Part gpio_38 -->
      <!-- Part gpio_39 -->
      <!-- Part gpio_40 -->
      <!-- Part hdmi_micro_3 -->
      <geom type="mesh" class="visual" pos="-0.0140368 -0.000137433 0.102479" quat="0.707106 0.707106 0.00124654 -0.00124654" mesh="hdmi_micro__2" material="hdmi_micro__2_material"/>
      <!-- Part ethernet_4 -->
      <geom type="mesh" class="visual" pos="-0.000236925 -0.0356874 0.10243" quat="0.707106 0.707106 0.00124654 -0.00124654" mesh="ethernet__4" material="ethernet__4_material"/>
      <!-- Part gpio_41 -->
      <!-- Part hdmi_micro_4 -->
      <geom type="mesh" class="visual" pos="-0.0140368 -0.000137433 0.102479" quat="0.707106 0.707106 0.00124654 -0.00124654" mesh="hdmi_micro" material="hdmi_micro_material"/>
      <!-- Part pcba_components_geometry -->
      <geom type="mesh" class="visual" pos="-0.0706979 -0.0361374 0.113628" quat="0.999998 0 0.00176287 0" mesh="pcba_components_geometry" material="pcba_components_geometry_material"/>
      <!-- Part chips -->
      <geom type="mesh" class="visual" pos="-0.0706979 -0.0361374 0.113628" quat="0.999998 0 0.00176287 0" mesh="chips" material="chips_material"/>
      <!-- Part chips_2 -->
      <geom type="mesh" class="visual" pos="-0.0706979 -0.0361374 0.113628" quat="0.999998 0 0.00176287 0" mesh="chips__2" material="chips__2_material"/>
      <!-- Part chips_3 -->
      <geom type="mesh" class="visual" pos="-0.0706979 -0.0361374 0.113628" quat="0.999998 0 0.00176287 0" mesh="chips__3" material="chips__3_material"/>
      <!-- Part chips_4 -->
      <geom type="mesh" class="visual" pos="-0.0706979 -0.0361374 0.113628" quat="0.999998 0 0.00176287 0" mesh="chips__4" material="chips__4_material"/>
      <!-- Part chips_5 -->
      <geom type="mesh" class="visual" pos="-0.0706979 -0.0361374 0.113628" quat="0.999998 0 0.00176287 0" mesh="chips__5" material="chips__5_material"/>
      <!-- Part pcba_components_geometry_2 -->
      <geom type="mesh" class="visual" pos="-0.0706979 -0.0361374 0.113628" quat="0.999998 0 0.00176287 0" mesh="pcba_components_geometry__2" material="pcba_components_geometry__2_material"/>
      <!-- Part pcba_components_geometry_3 -->
      <geom type="mesh" class="visual" pos="-0.0706979 -0.0361374 0.113628" quat="0.999998 0 0.00176287 0" mesh="pcba_components_geometry__3" material="pcba_components_geometry__3_material"/>
      <!-- Part chips_6 -->
      <geom type="mesh" class="visual" pos="-0.0706979 -0.0361374 0.113628" quat="0.999998 0 0.00176287 0" mesh="chips__6" material="chips__6_material"/>
      <!-- Part chips_7 -->
      <geom type="mesh" class="visual" pos="-0.0706979 -0.0361374 0.113628" quat="0.999998 0 0.00176287 0" mesh="chips__7" material="chips__7_material"/>
      <!-- Part chips_8 -->
      <geom type="mesh" class="visual" pos="-0.0706979 -0.0361374 0.113628" quat="0.999998 0 0.00176287 0" mesh="chips__8" material="chips__8_material"/>
      <!-- Part chips_9 -->
      <geom type="mesh" class="visual" pos="-0.0706979 -0.0361374 0.113628" quat="0.999998 0 0.00176287 0" mesh="chips__9" material="chips__9_material"/>
      <!-- Part pcba_components_geometry_4 -->
      <geom type="mesh" class="visual" pos="-0.0706979 -0.0361374 0.113628" quat="0.999998 0 0.00176287 0" mesh="pcba_components_geometry__4" material="pcba_components_geometry__4_material"/>
      <!-- Part chips_10 -->
      <geom type="mesh" class="visual" pos="-0.0706979 -0.0361374 0.113628" quat="0.999998 0 0.00176287 0" mesh="chips__10" material="chips__10_material"/>
      <!-- Part chips_11 -->
      <geom type="mesh" class="visual" pos="-0.0706979 -0.0361374 0.113628" quat="0.999998 0 0.00176287 0" mesh="chips__11" material="chips__11_material"/>
      <!-- Part pcba_components_geometry_5 -->
      <geom type="mesh" class="visual" pos="-0.0706979 -0.0361374 0.113628" quat="0.999998 0 0.00176287 0" mesh="pcba_components_geometry__5" material="pcba_components_geometry__5_material"/>
      <!-- Part pcba_components_geometry_6 -->
      <geom type="mesh" class="visual" pos="-0.0706979 -0.0361374 0.113628" quat="0.999998 0 0.00176287 0" mesh="pcba_components_geometry__6" material="pcba_components_geometry__6_material"/>
      <!-- Part pcba_components_geometry_7 -->
      <geom type="mesh" class="visual" pos="-0.0706979 -0.0361374 0.113628" quat="0.999998 0 0.00176287 0" mesh="pcba_components_geometry__7" material="pcba_components_geometry__7_material"/>
      <!-- Part csi_dsi_connector -->
      <geom type="mesh" class="visual" pos="-0.0644979 -0.0361374 0.113607" quat="0.999998 0 0.00176287 0" mesh="csi_dsi_connector" material="csi_dsi_connector_material"/>
      <!-- Part csi_dsi_connector_2 -->
      <geom type="mesh" class="visual" pos="-0.0644979 -0.0361374 0.113607" quat="0.999998 0 0.00176287 0" mesh="csi_dsi_connector__2" material="csi_dsi_connector__2_material"/>
      <!-- Part usb2_port -->
      <geom type="mesh" class="visual" pos="-0.00101117 0.0198626 0.0939326" quat="0.707106 0.707106 0.00124654 -0.00124654" mesh="usb2_port" material="usb2_port_material"/>
      <!-- Part usb2_port_2 -->
      <geom type="mesh" class="visual" pos="-0.00101117 0.0198626 0.0939326" quat="0.707106 0.707106 0.00124654 -0.00124654" mesh="usb2_port__2" material="usb2_port__2_material"/>
      <!-- Part usb_2_bank_geometry -->
      <geom type="mesh" class="visual" pos="-0.000981199 0.0198626 0.102433" quat="0.707106 0.707106 0.00124654 -0.00124654" mesh="usb_2_bank_geometry" material="usb_2_bank_geometry_material"/>
      <!-- Part usb2_port_3 -->
      <geom type="mesh" class="visual" pos="-0.000981199 0.0198626 0.102433" quat="0.707106 0.707106 0.00124654 -0.00124654" mesh="usb2_port__2" material="usb2_port__2_material"/>
      <!-- Part usb2_port_4 -->
      <geom type="mesh" class="visual" pos="-0.000981199 0.0198626 0.102433" quat="0.707106 0.707106 0.00124654 -0.00124654" mesh="usb2_port" material="usb2_port_material"/>
      <!-- Part poe_pins -->
      <geom type="mesh" class="visual" pos="-0.0706979 -0.0361374 0.113628" quat="0.999998 0 0.00176287 0" mesh="poe_pins" material="poe_pins_material"/>
      <!-- Part poe_pins_2 -->
      <geom type="mesh" class="visual" pos="-0.0706979 -0.0361374 0.113628" quat="0.999998 0 0.00176287 0" mesh="poe_pins__2" material="poe_pins__2_material"/>
      <!-- Part poe_pins_3 -->
      <geom type="mesh" class="visual" pos="-0.0706979 -0.0361374 0.113628" quat="0.999998 0 0.00176287 0" mesh="poe_pins__3" material="poe_pins__3_material"/>
      <!-- Part poe_pins_4 -->
      <geom type="mesh" class="visual" pos="-0.0706979 -0.0361374 0.113628" quat="0.999998 0 0.00176287 0" mesh="poe_pins__4" material="poe_pins__4_material"/>
      <!-- Part poe_geometry -->
      <geom type="mesh" class="visual" pos="-0.0706979 -0.0361374 0.113628" quat="0.999998 0 0.00176287 0" mesh="poe_geometry" material="poe_geometry_material"/>
      <!-- Part usb3_port -->
      <geom type="mesh" class="visual" pos="-0.000811169 0.00196257 0.0939319" quat="0.707106 0.707106 0.00124654 -0.00124654" mesh="usb3_port" material="usb3_port_material"/>
      <!-- Part usb3_port_2 -->
      <geom type="mesh" class="visual" pos="-0.000811169 0.00196257 0.0939319" quat="0.707106 0.707106 0.00124654 -0.00124654" mesh="usb3_port__2" material="usb3_port__2_material"/>
      <!-- Part usb3_port_3 -->
      <geom type="mesh" class="visual" pos="-0.000781201 0.00196257 0.102432" quat="0.707106 0.707106 0.00124654 -0.00124654" mesh="usb3_port" material="usb3_port_material"/>
      <!-- Part usb3_port_4 -->
      <geom type="mesh" class="visual" pos="-0.000781201 0.00196257 0.102432" quat="0.707106 0.707106 0.00124654 -0.00124654" mesh="usb3_port__2" material="usb3_port__2_material"/>
      <!-- Part usb_3_bank_geometry -->
      <geom type="mesh" class="visual" pos="-0.000781201 0.00196257 0.102432" quat="0.707106 0.707106 0.00124654 -0.00124654" mesh="usb_3_bank_geometry" material="usb_3_bank_geometry_material"/>
      <!-- Part csi_dsi_connector_3 -->
      <geom type="mesh" class="visual" pos="-0.0706979 -0.0361374 0.113628" quat="0.999998 0 0.00176287 0" mesh="csi_dsi_connector__2" material="csi_dsi_connector__2_material"/>
      <!-- Part csi_dsi_connector_4 -->
      <geom type="mesh" class="visual" pos="-0.0706979 -0.0361374 0.113628" quat="0.999998 0 0.00176287 0" mesh="csi_dsi_connector" material="csi_dsi_connector_material"/>
      <!-- Frame torso -->
      <site group="3" name="torso" pos="-0.000116211 -0.000137208 0.11678" quat="0.999998 0 0.00176287 0"/>
      <!-- Link hipx_subassembly -->
      <body name="hipx_subassembly" pos="-0.000819037 -0.133159 0.04164" quat="0.821908 0.0571233 0.0414078 -0.565234">
        <!-- Joint from torso_subassembly to hipx_subassembly -->
        <joint axis="0 0 1" name="hipz_right" type="hinge" range="-0.3490658504 0.3490658504" frictionloss="1.35093364028" armature="0.0226574181459" damping="0.513890006059"/>
        <inertial pos="-0.0174892 -0.0267104 -0.0909238" mass="1.05831" fullinertia="0.00121944 0.00118799 0.00120815 -4.05239e-05 -0.000116419 -0.000177107"/>
        <!-- Part rs02 -->
        <!-- Part hex_socket_head_cap_screw_m4x0_70_x_40__14321d45d56569246e7feb4574a6bae6 -->
        <!-- Part hex_socket_head_cap_screw_m3x0_50_x_8__d566997e1880d7fd3377c5b0ee12206c_13 -->
        <!-- Part hex_socket_head_cap_screw_m3x0_50_x_8__d566997e1880d7fd3377c5b0ee12206c_14 -->
        <!-- Part hex_socket_head_cap_screw_m4x0_70_x_40__14321d45d56569246e7feb4574a6bae6_2 -->
        <!-- Part hex_socket_head_cap_screw_m3x0_50_x_8__d566997e1880d7fd3377c5b0ee12206c_15 -->
        <!-- Part xt_30_2x2_f_2 -->
        <geom type="mesh" class="visual" pos="-0.0280156 -0.000591536 -0.0506633" quat="0.372266 0.524562 -0.593709 0.48349" mesh="xt_30_2x2_f" material="xt_30_2x2_f_material"/>
        <!-- Part hex_socket_head_cap_screw_m3x0_50_x_8__d566997e1880d7fd3377c5b0ee12206c_16 -->
        <!-- Part hex_socket_head_cap_screw_m4x0_70_x_40__14321d45d56569246e7feb4574a6bae6_3 -->
        <!-- Part hex_socket_head_cap_screw_m4x0_70_x_40__14321d45d56569246e7feb4574a6bae6_4 -->
        <!-- Part hex_socket_head_cap_screw_m3x0_50_x_8__d566997e1880d7fd3377c5b0ee12206c_17 -->
        <!-- Part hipz12 -->
        <geom type="mesh" class="visual" pos="0 0 -0.1" quat="0 1 0 0" mesh="hipz12" material="hipz12_material"/>
        <!-- Part hex_socket_head_cap_screw_m4x0_70_x_40__14321d45d56569246e7feb4574a6bae6_5 -->
        <!-- Part hex_socket_head_cap_screw_m3x0_50_x_8__d566997e1880d7fd3377c5b0ee12206c_18 -->
        <!-- Part hex_socket_head_cap_screw_m3x0_50_x_8__d566997e1880d7fd3377c5b0ee12206c_19 -->
        <!-- Part robstride02 -->
        <geom type="mesh" class="visual" pos="-0.575896 0.0494047 -0.172196" quat="0.792908 -0.60316 -0.0524169 -0.0689068" mesh="robstride02" material="robstride02_material"/>
        <!-- Part hex_socket_head_cap_screw_m4x0_70_x_40__14321d45d56569246e7feb4574a6bae6_6 -->
        <!-- Part hex_socket_head_cap_screw_m3x0_50_x_8__d566997e1880d7fd3377c5b0ee12206c_20 -->
        <!-- Part hex_socket_head_cap_screw_m4x0_70_x_40__14321d45d56569246e7feb4574a6bae6_7 -->
        <!-- Part hex_socket_head_cap_screw_m4x0_70_x_40__14321d45d56569246e7feb4574a6bae6_8 -->
        <!-- Part hex_socket_head_cap_screw_m3x0_50_x_8__d566997e1880d7fd3377c5b0ee12206c_21 -->
        <!-- Part bearing_35_72_17_3 -->
        <geom type="mesh" class="visual" pos="-0.01759 -0.0267968 -0.104484" quat="0.60316 0.792908 -0.0689068 0.0524169" mesh="bearing_35_72_17" material="bearing_35_72_17_material"/>
        <!-- Part hex_socket_head_cap_screw_m3x0_50_x_8__d566997e1880d7fd3377c5b0ee12206c_22 -->
        <!-- Part hex_socket_head_cap_screw_m3x0_50_x_8__d566997e1880d7fd3377c5b0ee12206c_23 -->
        <!-- Part hex_socket_head_cap_screw_m4x0_70_x_40__14321d45d56569246e7feb4574a6bae6_9 -->
        <!-- Part hex_socket_head_cap_screw_m3x0_50_x_8__d566997e1880d7fd3377c5b0ee12206c_24 -->
        <!-- Part hipz22 -->
        <geom type="mesh" class="visual" pos="0 0 -0.1" quat="0 1 -0 -0" mesh="hipz22" material="hipz22_material"/>
        <!-- Part hex_socket_head_cap_screw_m3x0_50_x_8__d566997e1880d7fd3377c5b0ee12206c_25 -->
        <!-- Part hex_socket_head_cap_screw_m3x0_50_x_8__d566997e1880d7fd3377c5b0ee12206c_26 -->
        <!-- Part hex_socket_head_cap_screw_m3x0_50_x_8__d566997e1880d7fd3377c5b0ee12206c_27 -->
        <!-- Part hex_socket_head_cap_screw_m4x0_70_x_40__14321d45d56569246e7feb4574a6bae6_10 -->
        <!-- Link hipy_subassembly -->
        <body name="hipy_subassembly" pos="-0.01897 -0.0289 -0.09689" quat="0.388859 0.13275 0.0879729 -0.907429">
          <!-- Joint from hipx_subassembly to hipy_subassembly -->
          <joint axis="0 0 1" name="hipx_right" type="hinge" range="-0.3490658504 0.3490658504" frictionloss="1.15781879707" armature="0.133269754407" damping="0.737616370831"/>
          <inertial pos="0.00443984 -0.00140958 -0.0603705" mass="0.451845" fullinertia="0.000889028 0.000809829 0.000829135 4.17064e-05 1.0373e-06 -3.88246e-05"/>
          <!-- Part hex_socket_head_cap_screw_m4x0_70_x_20__832e47d784177ea3f1dabbaab534416e_17 -->
          <!-- Part hipxy -->
          <geom type="mesh" class="visual" pos="-0 0 0" quat="1 -0 -0 -0" mesh="hipxy" material="hipxy_material"/>
          <!-- Part hex_socket_head_cap_screw_m4x0_70_x_20__832e47d784177ea3f1dabbaab534416e_18 -->
          <!-- Part hex_socket_head_cap_screw_m4x0_70_x_20__832e47d784177ea3f1dabbaab534416e_19 -->
          <!-- Part hex_socket_head_cap_screw_m4x0_70_x_12__c825518ee8edf1afced0eee1b019b750 -->
          <!-- Part hex_socket_head_cap_screw_m4x0_70_x_20__832e47d784177ea3f1dabbaab534416e_20 -->
          <!-- Part hex_socket_head_cap_screw_m4x0_70_x_12__c825518ee8edf1afced0eee1b019b750_2 -->
          <!-- Part hex_socket_head_cap_screw_m4x0_70_x_12__c825518ee8edf1afced0eee1b019b750_3 -->
          <!-- Part hex_socket_head_cap_screw_m4x0_70_x_20__832e47d784177ea3f1dabbaab534416e_21 -->
          <!-- Part hex_socket_head_cap_screw_m4x0_70_x_20__832e47d784177ea3f1dabbaab534416e_22 -->
          <!-- Part hex_socket_head_cap_screw_m4x0_70_x_12__c825518ee8edf1afced0eee1b019b750_4 -->
          <!-- Part hex_socket_head_cap_screw_m4x0_70_x_12__c825518ee8edf1afced0eee1b019b750_5 -->
          <!-- Part hex_socket_head_cap_screw_m4x0_70_x_12__c825518ee8edf1afced0eee1b019b750_6 -->
          <!-- Link tigh_subassembly -->
          <body name="tigh_subassembly" pos="0.012638 -0.0276823 -0.112055" quat="0.289457 0.00726416 0.730479 -0.618516">
            <!-- Joint from hipy_subassembly to tigh_subassembly -->
            <joint axis="0 0 1" name="hipy_right" type="hinge" range="-1.0471975512 1.0471975512" frictionloss="1.3122407137" armature="0.14077316233" damping="1.45524910678"/>
            <inertial pos="0.050629 0.0799706 -0.035375" mass="2.60644" fullinertia="0.0182936 0.0088455 0.0246433 -0.00853541 0.000926243 0.00152373"/>
            <!-- Part hex_socket_head_cap_screw_m3x0_50_x_10__9c80fcbba574884e63b580474e1ee150 -->
            <!-- Part hex_socket_head_cap_screw_m2_5x0_45_x_6__ec244025d76f8b83b2775022a2cb3232 -->
            <!-- Part hex_socket_head_cap_screw_m4x0_70_x_8__a416dc2a8d778a4ef6150c0739aa89d1 -->
            <!-- Part hex_socket_head_cap_screw_m2_5x0_45_x_6__ec244025d76f8b83b2775022a2cb3232_2 -->
            <!-- Part hex_socket_head_cap_screw_m4x0_70_x_8__a416dc2a8d778a4ef6150c0739aa89d1_2 -->
            <!-- Part hex_socket_head_cap_screw_m3x0_50_x_10__9c80fcbba574884e63b580474e1ee150_2 -->
            <!-- Part hex_socket_head_cap_screw_m4x0_70_x_16__8d628c0d7a90368385b1c4c7479647eb -->
            <!-- Part hex_socket_head_cap_screw_m4x0_70_x_8__a416dc2a8d778a4ef6150c0739aa89d1_3 -->
            <!-- Part hex_socket_head_cap_screw_m4x0_70_x_16__8d628c0d7a90368385b1c4c7479647eb_2 -->
            <!-- Part hex_socket_head_cap_screw_m4x0_70_x_8__a416dc2a8d778a4ef6150c0739aa89d1_4 -->
            <!-- Part knee_rod22 -->
            <geom type="mesh" class="visual" pos="0.210506 0.184547 -0.0305" quat="0.612372 0.612372 -0.353553 -0.353553" mesh="knee_rod22" material="knee_rod22_material"/>
            <!-- Part hex_socket_head_cap_screw_m4x0_70_x_8__a416dc2a8d778a4ef6150c0739aa89d1_5 -->
            <!-- Part hex_socket_head_cap_screw_m4x0_70_x_16__8d628c0d7a90368385b1c4c7479647eb_3 -->
            <!-- Part hex_socket_head_cap_screw_m4x0_70_x_16__8d628c0d7a90368385b1c4c7479647eb_4 -->
            <!-- Part hex_socket_head_cap_screw_m4x0_70_x_8__a416dc2a8d778a4ef6150c0739aa89d1_6 -->
            <!-- Part bearing_15_21_4 -->
            <geom type="mesh" class="visual" pos="0.117923 0.320381 -0.0185" quat="0.612372 -0.612372 0.353553 -0.353553" mesh="bearing_15_21_4" material="bearing_15_21_4_material"/>
            <!-- Part bearing_15_21_4_2 -->
            <geom type="mesh" class="visual" pos="0.0130854 0.122429 -0.0245" quat="0.707107 -0.707107 0 -0" mesh="bearing_15_21_4" material="bearing_15_21_4_material"/>
            <!-- Part hex_socket_head_cap_screw_m2_5x0_45_x_6__ec244025d76f8b83b2775022a2cb3232_3 -->
            <!-- Part hex_socket_head_cap_screw_m4x0_70_x_8__a416dc2a8d778a4ef6150c0739aa89d1_7 -->
            <!-- Part robstrideo3 -->
            <geom type="mesh" class="visual" pos="-0.437806 0.570998 -0.07" quat="0.683013 -0.683013 0.183013 -0.183013" mesh="robstrideo3" material="robstrideo3_material"/>
            <!-- Part hex_socket_head_cap_screw_m4x0_70_x_16__8d628c0d7a90368385b1c4c7479647eb_5 -->
            <!-- Part bearing_15_21_4_3 -->
            <geom type="mesh" class="visual" pos="0 -0 -0.0635" quat="0.683013 0.683013 -0.183013 -0.183013" mesh="bearing_15_21_4" material="bearing_15_21_4_material"/>
            <!-- Part bearing_15_21_4_4 -->
            <geom type="mesh" class="visual" pos="0.0130854 0.122429 -0.0365" quat="0.707107 0.707107 -0 -0" mesh="bearing_15_21_4" material="bearing_15_21_4_material"/>
            <!-- Part hex_socket_head_cap_screw_m4x0_70_x_40__14321d45d56569246e7feb4574a6bae6_11 -->
            <!-- Part bearing_15_21_4_5 -->
            <geom type="mesh" class="visual" pos="0.117923 0.320381 -0.0425" quat="0.612372 0.612372 -0.353553 -0.353553" mesh="bearing_15_21_4" material="bearing_15_21_4_material"/>
            <!-- Part hex_socket_head_cap_screw_m4x0_70_x_40__14321d45d56569246e7feb4574a6bae6_12 -->
            <!-- Part hex_socket_head_cap_screw_m4x0_70_x_8__a416dc2a8d778a4ef6150c0739aa89d1_8 -->
            <!-- Part hex_socket_head_cap_screw_m2_5x0_45_x_6__ec244025d76f8b83b2775022a2cb3232_4 -->
            <!-- Part hex_socket_head_cap_screw_m2_5x0_45_x_6__ec244025d76f8b83b2775022a2cb3232_5 -->
            <!-- Part hex_socket_head_cap_screw_m4x0_70_x_8__a416dc2a8d778a4ef6150c0739aa89d1_9 -->
            <!-- Part knee_rod12 -->
            <geom type="mesh" class="visual" pos="0.210506 0.184547 -0.0305" quat="0.612372 0.612372 -0.353553 -0.353553" mesh="knee_rod12" material="knee_rod12_material"/>
            <!-- Part hex_socket_head_cap_screw_m4x0_70_x_8__a416dc2a8d778a4ef6150c0739aa89d1_10 -->
            <!-- Part bearing_5_16_5 -->
            <geom type="mesh" class="visual" pos="0.17 0.294449 -0.05" quat="0.683013 -0.683013 0.183013 -0.183013" mesh="bearing_5_16_5" material="bearing_5_16_5_material"/>
            <!-- Part hex_socket_head_cap_screw_m4x0_70_x_8__a416dc2a8d778a4ef6150c0739aa89d1_11 -->
            <!-- Part hex_socket_head_cap_screw_m4x0_70_x_8__a416dc2a8d778a4ef6150c0739aa89d1_12 -->
            <!-- Part hex_socket_head_cap_screw_m4x0_70_x_8__a416dc2a8d778a4ef6150c0739aa89d1_13 -->
            <!-- Part hex_socket_head_cap_screw_m4x0_70_x_40__14321d45d56569246e7feb4574a6bae6_13 -->
            <!-- Part knee_actuation -->
            <geom type="mesh" class="visual" pos="0.058 0.324459 -0.0305" quat="0.707107 0.707107 -0 -0" mesh="knee_actuation" material="knee_actuation_material"/>
            <!-- Part hex_socket_head_cap_screw_m4x0_70_x_16__8d628c0d7a90368385b1c4c7479647eb_6 -->
            <!-- Part hex_socket_head_cap_screw_m3x0_50_x_10__9c80fcbba574884e63b580474e1ee150_3 -->
            <!-- Part hex_socket_head_cap_screw_m4x0_70_x_8__a416dc2a8d778a4ef6150c0739aa89d1_14 -->
            <!-- Part bearing_5_16_5_2 -->
            <geom type="mesh" class="visual" pos="0.17 0.294449 -0.01425" quat="0.683013 -0.683013 0.183013 -0.183013" mesh="bearing_5_16_5" material="bearing_5_16_5_material"/>
            <!-- Part femur_22 -->
            <geom type="mesh" class="visual" pos="0.17 0.294449 -0.0305" quat="0.683013 0.683013 -0.183013 -0.183013" mesh="femur_22" material="femur_22_material"/>
            <!-- Part hex_socket_head_cap_screw_m4x0_70_x_40__14321d45d56569246e7feb4574a6bae6_14 -->
            <!-- Part femur_12 -->
            <geom type="mesh" class="visual" pos="0.17 0.294449 -0.0305" quat="0.683013 0.683013 -0.183013 -0.183013" mesh="femur_12" material="femur_12_material"/>
            <geom name="femur_right_collision" type="mesh" class="collision" pos="0.17 0.294449 -0.0305" quat="0.683013 0.683013 -0.183013 -0.183013" mesh="femur_12" material="femur_12_material"/>
            <!-- Part hat_femur -->
            <geom type="mesh" class="visual" pos="0.17 0.294449 -0.0305" quat="0.683013 0.683013 -0.183013 -0.183013" mesh="hat_femur" material="hat_femur_material"/>
            <!-- Part part_3 -->
            <geom type="mesh" class="visual" pos="0 -0 -0.0938" quat="0.183013 -0.683013 0.183013 0.683013" mesh="part_3" material="part_3_material"/>
            <!-- Part robstrideo3_2 -->
            <geom type="mesh" class="visual" pos="-0.495806 0.470539 -0.0275" quat="0.683013 -0.683013 0.183013 -0.183013" mesh="robstrideo3" material="robstrideo3_material"/>
            <!-- Part hex_socket_head_cap_screw_m2_5x0_45_x_6__ec244025d76f8b83b2775022a2cb3232_6 -->
            <!-- Part 1_1_31_qt_942_1 -->
            <geom type="mesh" class="visual" pos="0 -0 -0.04" quat="0.5 -0 -0 -0.866025" mesh="1_1_31_qt_942_1" material="1_1_31_qt_942_1_material"/>
            <!-- Part 1_1_06_eb903_538_1 -->
            <geom type="mesh" class="visual" pos="0 -0 -0.0566" quat="0.5 -0 -0 -0.866025" mesh="1_1_06_eb903_538_1" material="1_1_06_eb903_538_1_material"/>
            <!-- Part 1_1_31_qt_942_1_2 -->
            <geom type="mesh" class="visual" pos="0.058 0.100459 -0.0825" quat="0.258819 -0 0 0.965926" mesh="1_1_31_qt_942_1" material="1_1_31_qt_942_1_material"/>
            <!-- Part 1_1_06_eb903_538_1_2 -->
            <geom type="mesh" class="visual" pos="0.058 0.100459 -0.0991" quat="0.258819 -0 0 0.965926" mesh="1_1_06_eb903_538_1" material="1_1_06_eb903_538_1_material"/>
            <!-- Part 1_1_06_eb903_537_af0_1 -->
            <geom type="mesh" class="visual" pos="0 -0 -0.0375" quat="0.965926 -0 -0 -0.258819" mesh="1_1_06_eb903_537_af0_1" material="1_1_06_eb903_537_af0_1_material"/>
            <!-- Part 1_1_02_eb901_558_1 -->
            <geom type="mesh" class="visual" pos="0 0 0" quat="0 1 0 0" mesh="1_1_02_eb901_558_1" material="1_1_02_eb901_558_1_material"/>
            <!-- Part 1_1_06_eb903_537_af0_1_2 -->
            <geom type="mesh" class="visual" pos="0.058 0.100459 -0.08" quat="0.5 -0 -0 -0.866025" mesh="1_1_06_eb903_537_af0_1" material="1_1_06_eb903_537_af0_1_material"/>
            <!-- Part 1_1_02_eb901_558_1_2 -->
            <geom type="mesh" class="visual" pos="0.058 0.100459 -0.0425" quat="0 0.707107 -0.707107 0" mesh="1_1_02_eb901_558_1" material="1_1_02_eb901_558_1_material"/>
            <!-- Link shin_subassembly -->
            <body name="shin_subassembly" pos="0.17 0.294449 -0.0305" quat="0 0.963177 -0.26887 0">
              <!-- Joint from tigh_subassembly to shin_subassembly -->
              <joint axis="0 0 1" name="knee_right" type="hinge" range="-0.5235987756 0.5235987756" frictionloss="0.91947125507" armature="0.123300247512" damping="2.26406194864"/>
              <inertial pos="-0.0751425 -0.0482284 5.91249e-05" mass="0.637285" fullinertia="0.000654315 0.00148161 0.00182965 -0.000652411 -0.000111479 -6.66625e-05"/>
              <!-- Part hex_socket_head_cap_screw_m2_5x0_45_x_8__dec2226ceabd7d7ca0bb403ec234d89b -->
              <!-- Part rmdx43 -->
              <geom type="mesh" class="visual" pos="-0.2967 0.369726 0.019" quat="0.616799 0.616799 -0.345773 -0.345773" mesh="rmdx43" material="rmdx43_material"/>
              <!-- Part xt_30_2x2_f_3 -->
              <geom type="mesh" class="visual" pos="-0.0609783 -0.00254913 -0.0142" quat="0.345773 0.616799 -0.345773 0.616799" mesh="xt_30_2x2_f" material="xt_30_2x2_f_material"/>
              <!-- Part hex_socket_head_cap_screw_m3x0_50_x_20__7252065e4445f5ec71347b53fcae11e4 -->
              <!-- Part hex_socket_head_cap_screw_m3x0_50_x_10__9c80fcbba574884e63b580474e1ee150_4 -->
              <!-- Part tibias22 -->
              <geom type="mesh" class="visual" pos="-0.221803 -0.135659 0.019" quat="0.616799 -0.616799 0.345773 -0.345773" mesh="tibias22" material="tibias22_material"/>
              <!-- Part 27628_01_050_catpart -->
              <geom type="mesh" class="visual" pos="0.00455194 -0.0324886 0.02" quat="0.658548 -0.658548 0.257517 -0.257517" mesh="27628_01_050_catpart" material="27628_01_050_catpart_material"/>
              <!-- Part hex_socket_head_cap_screw_m3x0_50_x_10__9c80fcbba574884e63b580474e1ee150_5 -->
              <!-- Part hex_socket_head_cap_screw_m3x0_50_x_10__9c80fcbba574884e63b580474e1ee150_6 -->
              <!-- Part hex_socket_head_cap_screw_m3x0_50_x_10__9c80fcbba574884e63b580474e1ee150_7 -->
              <!-- Part hex_thin_nut_grade_a___b_m4x0_7__a8228d9ce5dcc05f24da0a2f74d882f3 -->
              <geom type="mesh" class="visual" pos="-0 0 0.0247603" quat="1 0 -0 -0" mesh="hex_thin_nut_grade_a___b_m4x0_7__a8228d9ce5dcc05f24da0a2f74d882f3" material="hex_thin_nut_grade_a___b_m4x0_7__a8228d9ce5dcc05f24da0a2f74d882f3_material"/>
              <!-- Part 07534_05x40_catpart -->
              <geom type="mesh" class="visual" pos="-0 0 -0.025" quat="0.5 -0.5 -0.5 -0.5" mesh="07534_05x40_catpart" material="07534_05x40_catpart_material"/>
              <!-- Part hex_thin_nut_grade_a___b_m4x0_7__a8228d9ce5dcc05f24da0a2f74d882f3_2 -->
              <geom type="mesh" class="visual" pos="-0.0406618 -0.0601422 -0.0112397" quat="0 -0.998828 0.0484075 -0" mesh="hex_thin_nut_grade_a___b_m4x0_7__a8228d9ce5dcc05f24da0a2f74d882f3" material="hex_thin_nut_grade_a___b_m4x0_7__a8228d9ce5dcc05f24da0a2f74d882f3_material"/>
              <!-- Part hex_socket_head_cap_screw_m3x0_50_x_20__7252065e4445f5ec71347b53fcae11e4_2 -->
              <!-- Part hex_socket_head_cap_screw_m3x0_50_x_10__9c80fcbba574884e63b580474e1ee150_8 -->
              <!-- Part 07534_05x20_catpart -->
              <geom type="mesh" class="visual" pos="-0.0406618 -0.0601422 -0.041" quat="0.0342293 0.706278 -0.0342293 0.706278" mesh="07534_05x20_catpart" material="07534_05x20_catpart_material"/>
              <!-- Part actuation_ankle -->
              <geom type="mesh" class="visual" pos="-0.0303217 0.125625 -0.019" quat="0.706278 0.706278 -0.0342293 -0.0342293" mesh="actuation_ankle" material="actuation_ankle_material"/>
              <!-- Part hex_socket_head_cap_screw_m3x0_50_x_30__cb22dc4460edbee8e1cbddf29677c00f -->
              <!-- Part rmdx43_2 -->
              <geom type="mesh" class="visual" pos="-0.341913 0.342073 0.006" quat="0.616799 0.616799 -0.345773 -0.345773" mesh="rmdx43" material="rmdx43_material"/>
              <!-- Part hex_socket_head_cap_screw_m3x0_50_x_10__9c80fcbba574884e63b580474e1ee150_9 -->
              <!-- Part hex_socket_head_cap_screw_m3x0_50_x_20__7252065e4445f5ec71347b53fcae11e4_3 -->
              <!-- Part hex_socket_head_cap_screw_m3x0_50_x_10__9c80fcbba574884e63b580474e1ee150_10 -->
              <!-- Part hex_socket_head_cap_screw_m3x0_50_x_10__9c80fcbba574884e63b580474e1ee150_11 -->
              <!-- Part hex_socket_head_cap_screw_m3x0_50_x_10__9c80fcbba574884e63b580474e1ee150_12 -->
              <!-- Part hex_socket_head_cap_screw_m4x0_70_x_12__c825518ee8edf1afced0eee1b019b750_7 -->
              <!-- Part hex_socket_head_cap_screw_m3x0_50_x_20__7252065e4445f5ec71347b53fcae11e4_4 -->
              <!-- Part hex_socket_head_cap_screw_m3x0_50_x_20__7252065e4445f5ec71347b53fcae11e4_5 -->
              <!-- Part hex_socket_head_cap_screw_m3x0_50_x_10__9c80fcbba574884e63b580474e1ee150_13 -->
              <!-- Part hex_socket_head_cap_screw_m3x0_50_x_10__9c80fcbba574884e63b580474e1ee150_14 -->
              <!-- Part hex_socket_head_cap_screw_m3x0_50_x_10__9c80fcbba574884e63b580474e1ee150_15 -->
              <!-- Part hex_socket_head_cap_screw_m3x0_50_x_10__9c80fcbba574884e63b580474e1ee150_16 -->
              <!-- Part hex_socket_head_cap_screw_m3x0_50_x_20__7252065e4445f5ec71347b53fcae11e4_6 -->
              <!-- Part hex_socket_head_cap_screw_m3x0_50_x_10__9c80fcbba574884e63b580474e1ee150_17 -->
              <!-- Part hex_socket_head_cap_screw_m3x0_50_x_10__9c80fcbba574884e63b580474e1ee150_18 -->
              <!-- Part hex_socket_head_cap_screw_m3x0_50_x_10__9c80fcbba574884e63b580474e1ee150_19 -->
              <!-- Part hex_socket_head_cap_screw_m2_5x0_45_x_8__dec2226ceabd7d7ca0bb403ec234d89b_2 -->
              <!-- Part hex_socket_head_cap_screw_m4x0_70_x_12__c825518ee8edf1afced0eee1b019b750_8 -->
              <!-- Part hat_big -->
              <geom type="mesh" class="visual" pos="-0.221803 -0.135659 0.019" quat="0.616799 -0.616799 0.345773 -0.345773" mesh="hat_big" material="hat_big_material"/>
              <!-- Part 07534_05x20_catpart_2 -->
              <geom type="mesh" class="visual" pos="0.00455195 -0.0324886 0.041" quat="0.0342293 -0.706278 0.0342293 0.706278" mesh="07534_05x20_catpart" material="07534_05x20_catpart_material"/>
              <!-- Part hex_socket_head_cap_screw_m4x0_70_x_12__c825518ee8edf1afced0eee1b019b750_9 -->
              <!-- Part hex_thin_nut_grade_a___b_m4x0_7__a8228d9ce5dcc05f24da0a2f74d882f3_3 -->
              <geom type="mesh" class="visual" pos="0.00455195 -0.0324886 0.0134398" quat="0.998828 -0 0 -0.0484075" mesh="hex_thin_nut_grade_a___b_m4x0_7__a8228d9ce5dcc05f24da0a2f74d882f3" material="hex_thin_nut_grade_a___b_m4x0_7__a8228d9ce5dcc05f24da0a2f74d882f3_material"/>
              <!-- Part hex_socket_head_cap_screw_m2_5x0_45_x_8__dec2226ceabd7d7ca0bb403ec234d89b_3 -->
              <!-- Part tibias12 -->
              <geom type="mesh" class="visual" pos="-0.221803 -0.135659 0.019" quat="0.616799 -0.616799 0.345773 -0.345773" mesh="tibias12" material="tibias12_material"/>
              <!-- Part hex_socket_head_cap_screw_m3x0_50_x_10__9c80fcbba574884e63b580474e1ee150_20 -->
              <!-- Part hex_socket_head_cap_screw_m3x0_50_x_20__7252065e4445f5ec71347b53fcae11e4_7 -->
              <!-- Part hex_socket_head_cap_screw_m3x0_50_x_10__9c80fcbba574884e63b580474e1ee150_21 -->
              <!-- Part hex_socket_head_cap_screw_m3x0_50_x_10__9c80fcbba574884e63b580474e1ee150_22 -->
              <!-- Part xt_30_2x2_f_4 -->
              <geom type="mesh" class="visual" pos="-0.105595 -0.0298375 0.0145" quat="0.616799 0.345773 0.616799 -0.345773" mesh="xt_30_2x2_f" material="xt_30_2x2_f_material"/>
              <!-- Part hex_socket_head_cap_screw_m3x0_50_x_10__9c80fcbba574884e63b580474e1ee150_23 -->
              <!-- Part hex_socket_head_cap_screw_m3x0_50_x_20__7252065e4445f5ec71347b53fcae11e4_8 -->
              <!-- Part actuation_ankle_2 -->
              <geom type="mesh" class="visual" pos="-0.105319 -0.208585 0.019" quat="0.706278 -0.706278 0.0342293 -0.0342293" mesh="actuation_ankle" material="actuation_ankle_material"/>
              <!-- Part hex_socket_head_cap_screw_m3x0_50_x_10__9c80fcbba574884e63b580474e1ee150_24 -->
              <!-- Part hex_socket_head_cap_screw_m4x0_70_x_12__c825518ee8edf1afced0eee1b019b750_10 -->
              <!-- Part hex_socket_head_cap_screw_m3x0_50_x_20__7252065e4445f5ec71347b53fcae11e4_9 -->
              <!-- Part hex_socket_head_cap_screw_m3x0_50_x_20__7252065e4445f5ec71347b53fcae11e4_10 -->
              <!-- Part 27628_01_050_catpart_2 -->
              <geom type="mesh" class="visual" pos="-0.0406619 -0.060142 -0.023" quat="0.642927 -0.642927 -0.294356 0.294356" mesh="27628_01_050_catpart" material="27628_01_050_catpart_material"/>
              <!-- Part hex_socket_head_cap_screw_m3x0_50_x_10__9c80fcbba574884e63b580474e1ee150_25 -->
              <!-- Part hex_socket_head_cap_screw_m3x0_50_x_20__7252065e4445f5ec71347b53fcae11e4_11 -->
              <!-- Part hex_socket_head_cap_screw_m3x0_50_x_20__7252065e4445f5ec71347b53fcae11e4_12 -->
              <!-- Part hex_socket_head_cap_screw_m3x0_50_x_10__9c80fcbba574884e63b580474e1ee150_26 -->
              <!-- Part hex_socket_head_cap_screw_m3x0_50_x_10__9c80fcbba574884e63b580474e1ee150_27 -->
              <!-- Part 1_1_31_eb463_510_fl46blw10_48v_5n_m_de_2__fl46blw10_48v_5n_m_de -->
              <geom type="mesh" class="visual" pos="-0.0904274 -0.0553071 -0.0195" quat="0 -0.760127 0.649775 -0" mesh="1_1_31_eb463_510_fl46blw10_48v_5n_m_de_2__fl46blw10_48v_5n_m_de" material="1_1_31_eb463_510_fl46blw10_48v_5n_m_de_2__fl46blw10_48v_5n_m_de_material"/>
              <!-- Part 1_1_02_eb461_502_fl46blw10_48v_5n_m_de_2__fl46blw10_48v_5n_m_de -->
              <geom type="mesh" class="visual" pos="-0.0904274 -0.0553071 -0.0095" quat="0 -0.760127 0.649775 -0" mesh="1_1_02_eb461_502_fl46blw10_48v_5n_m_de_2__fl46blw10_48v_5n_m_de" material="1_1_02_eb461_502_fl46blw10_48v_5n_m_de_2__fl46blw10_48v_5n_m_de_material"/>
              <!-- Part 1_1_06_eb463_509_fl46blw10_48v_5n_m_de_2__fl46blw10_48v_5n_m_de -->
              <geom type="mesh" class="visual" pos="-0.0904274 -0.0553071 0.022" quat="0 0.993018 -0.117964 0" mesh="1_1_06_eb463_509_fl46blw10_48v_5n_m_de_2__fl46blw10_48v_5n_m_de" material="1_1_06_eb463_509_fl46blw10_48v_5n_m_de_2__fl46blw10_48v_5n_m_de_material"/>
              <!-- Part 1_1_06_eb463_507_fl46blw10_48v_5n_m_de_2__fl46blw10_48v_5n_m_de -->
              <geom type="mesh" class="visual" pos="-0.0904274 -0.0553071 0.0085" quat="0 0.872286 -0.488996 -0" mesh="1_1_06_eb463_507_fl46blw10_48v_5n_m_de_2__fl46blw10_48v_5n_m_de" material="1_1_06_eb463_507_fl46blw10_48v_5n_m_de_2__fl46blw10_48v_5n_m_de_material"/>
              <!-- Part 1_1_31_eb463_510_fl46blw10_48v_5n_m_de_2__fl46blw10_48v_5n_m_de_2 -->
              <geom type="mesh" class="visual" pos="-0.0452137 -0.0276536 0.0195" quat="0.950924 0 0 -0.309426" mesh="1_1_31_eb463_510_fl46blw10_48v_5n_m_de_2__fl46blw10_48v_5n_m_de" material="1_1_31_eb463_510_fl46blw10_48v_5n_m_de_2__fl46blw10_48v_5n_m_de_material"/>
              <!-- Part 1_1_02_eb461_502_fl46blw10_48v_5n_m_de_2__fl46blw10_48v_5n_m_de_2 -->
              <geom type="mesh" class="visual" pos="-0.0452137 -0.0276536 0.0095" quat="0.950924 0 0 -0.309426" mesh="1_1_02_eb461_502_fl46blw10_48v_5n_m_de_2__fl46blw10_48v_5n_m_de" material="1_1_02_eb461_502_fl46blw10_48v_5n_m_de_2__fl46blw10_48v_5n_m_de_material"/>
              <!-- Part 1_1_06_eb463_509_fl46blw10_48v_5n_m_de_2__fl46blw10_48v_5n_m_de_2 -->
              <geom type="mesh" class="visual" pos="-0.0452137 -0.0276536 -0.022" quat="0.618756 -0 -0 -0.785583" mesh="1_1_06_eb463_509_fl46blw10_48v_5n_m_de_2__fl46blw10_48v_5n_m_de" material="1_1_06_eb463_509_fl46blw10_48v_5n_m_de_2__fl46blw10_48v_5n_m_de_material"/>
              <!-- Part 1_1_06_eb463_507_fl46blw10_48v_5n_m_de_2__fl46blw10_48v_5n_m_de_2 -->
              <geom type="mesh" class="visual" pos="-0.0452137 -0.0276536 -0.0085" quat="0.872286 -0 0 -0.488996" mesh="1_1_06_eb463_507_fl46blw10_48v_5n_m_de_2__fl46blw10_48v_5n_m_de" material="1_1_06_eb463_507_fl46blw10_48v_5n_m_de_2__fl46blw10_48v_5n_m_de_material"/>
              <!-- Part 0001755652_1_1_30_gr_2202_asm_1_asm_1_1_30_gr_2202_asm_fl46blw10_48v_5n_m_de_2__fl46blw10_48v_5n_m_de -->
              <geom type="mesh" class="visual" pos="-0.0823231 -0.0503503 -0.024" quat="0.488996 -0 0 0.872286" mesh="0001755652_1_1_30_gr_2202_asm_1_asm_1_1_30_gr_2202_asm_fl46blw10_48v_5n_m_de_2__fl46blw10_48v_5n_m_de" material="0001755652_1_1_30_gr_2202_asm_1_asm_1_1_30_gr_2202_asm_fl46blw10_48v_5n_m_de_2__fl46blw10_48v_5n_m_de_material"/>
              <!-- Part 0001755652_1_1_30_gr_2202_asm_1_asm_1_1_30_gr_2202_asm_fl46blw10_48v_5n_m_de_2__fl46blw10_48v_5n_m_de_2 -->
              <geom type="mesh" class="visual" pos="-0.0987723 -0.0507669 -0.024" quat="0.488996 -0 0 0.872286" mesh="0001755652_1_1_30_gr_2202_asm_1_asm_1_1_30_gr_2202_asm_fl46blw10_48v_5n_m_de_2__fl46blw10_48v_5n_m_de" material="0001755652_1_1_30_gr_2202_asm_1_asm_1_1_30_gr_2202_asm_fl46blw10_48v_5n_m_de_2__fl46blw10_48v_5n_m_de_material"/>
              <!-- Part 0001755652_1_1_30_gr_2202_asm_1_asm_1_1_30_gr_2202_asm_fl46blw10_48v_5n_m_de_2__fl46blw10_48v_5n_m_de_3 -->
              <geom type="mesh" class="visual" pos="-0.0533181 -0.0326103 0.024" quat="0 -0.488996 -0.872286 0" mesh="0001755652_1_1_30_gr_2202_asm_1_asm_1_1_30_gr_2202_asm_fl46blw10_48v_5n_m_de_2__fl46blw10_48v_5n_m_de" material="0001755652_1_1_30_gr_2202_asm_1_asm_1_1_30_gr_2202_asm_fl46blw10_48v_5n_m_de_2__fl46blw10_48v_5n_m_de_material"/>
              <!-- Part 0001755652_1_1_30_gr_2202_asm_1_asm_1_1_30_gr_2202_asm_fl46blw10_48v_5n_m_de_2__fl46blw10_48v_5n_m_de_4 -->
              <geom type="mesh" class="visual" pos="-0.0454542 -0.0181566 0.024" quat="0 -0.488996 -0.872286 0" mesh="0001755652_1_1_30_gr_2202_asm_1_asm_1_1_30_gr_2202_asm_fl46blw10_48v_5n_m_de_2__fl46blw10_48v_5n_m_de" material="0001755652_1_1_30_gr_2202_asm_1_asm_1_1_30_gr_2202_asm_fl46blw10_48v_5n_m_de_2__fl46blw10_48v_5n_m_de_material"/>
              <!-- Part 0001755652_00mini_000_asm_1_asm_1_asm_00mini__20250103_a0001_asm_1_as_asm_1_1_30_gr_2202_asm_1_asm_1_1_30_gr_2202_asm_fl46blw10_48v_5n_m_de_2__fl46blw10_48v_5n_m_de -->
              <geom type="mesh" class="visual" pos="-0.0901869 -0.0648041 -0.024" quat="0.488996 -0 0 0.872286" mesh="0001755652_00mini_000_asm_1_asm_1_asm_00mini__20250103_a0001_asm_1_as_asm_1_1_30_gr_2202_asm_1_asm_1_1_30_gr_2202_asm_fl46blw10_48v_5n_m_de_2__fl46blw10_48v_5n_m_de" material="0001755652_00mini_000_asm_1_asm_1_asm_00mini__20250103_a0001_asm_1_as_asm_1_1_30_gr_2202_asm_1_asm_1_1_30_gr_2202_asm_fl46blw10_48v_5n_m_de_2__fl46blw10_48v_5n_m_de_material"/>
              <!-- Part 6706__300001_1_1_00mini_000_asm_1_asm_1_asm_00mini__20250103_a0001_asm_1_as_asm_1_1_30_gr_2202_asm_1_asm_1_1_30_gr_2202_asm_fl46blw10_48v_5n_m_de_2__fl46blw10_48v_5n_m_de -->
              <geom type="mesh" class="visual" pos="-0.0904274 -0.0553071 -0.0205" quat="0.488996 -0 0 0.872286" mesh="6706__300001_1_1_00mini_000_asm_1_asm_1_asm_00mini__20250103_a0001_asm_1_as_asm_1_1_30_gr_2202_asm_1_asm_1_1_30_gr_2202_asm_fl46blw10_48v_5n_m_de_2__fl46blw10_48v_5n_m_de" material="6706__300001_1_1_00mini_000_asm_1_asm_1_asm_00mini__20250103_a0001_asm_1_as_asm_1_1_30_gr_2202_asm_1_asm_1_1_30_gr_2202_asm_fl46blw10_48v_5n_m_de_2__fl46blw10_48v_5n_m_de_material"/>
              <!-- Part 0001755650_00mini_000_asm_1_asm_1_asm_00mini__20250103_a0001_asm_1_as_asm_1_1_30_gr_2202_asm_1_asm_1_1_30_gr_2202_asm_fl46blw10_48v_5n_m_de_2__fl46blw10_48v_5n_m_de -->
              <geom type="mesh" class="visual" pos="-0.0904274 -0.0553071 -0.0209" quat="0.488996 -0 0 0.872286" mesh="0001755650_00mini_000_asm_1_asm_1_asm_00mini__20250103_a0001_asm_1_as_asm_1_1_30_gr_2202_asm_1_asm_1_1_30_gr_2202_asm_fl46blw10_48v_5n_m_de_2__fl46blw10_48v_5n_m_de" material="0001755650_00mini_000_asm_1_asm_1_asm_00mini__20250103_a0001_asm_1_as_asm_1_1_30_gr_2202_asm_1_asm_1_1_30_gr_2202_asm_fl46blw10_48v_5n_m_de_2__fl46blw10_48v_5n_m_de_material"/>
              <!-- Part 0001755652_00mini_000_asm_1_asm_1_asm_00mini__20250103_a0001_asm_1_as_asm_1_1_30_gr_2202_asm_1_asm_1_1_30_gr_2202_asm_fl46blw10_48v_5n_m_de_2__fl46blw10_48v_5n_m_de_2 -->
              <geom type="mesh" class="visual" pos="-0.0368689 -0.0321937 0.024" quat="0 -0.488996 -0.872286 0" mesh="0001755652_00mini_000_asm_1_asm_1_asm_00mini__20250103_a0001_asm_1_as_asm_1_1_30_gr_2202_asm_1_asm_1_1_30_gr_2202_asm_fl46blw10_48v_5n_m_de_2__fl46blw10_48v_5n_m_de" material="0001755652_00mini_000_asm_1_asm_1_asm_00mini__20250103_a0001_asm_1_as_asm_1_1_30_gr_2202_asm_1_asm_1_1_30_gr_2202_asm_fl46blw10_48v_5n_m_de_2__fl46blw10_48v_5n_m_de_material"/>
              <!-- Part 6706__300001_1_1_00mini_000_asm_1_asm_1_asm_00mini__20250103_a0001_asm_1_as_asm_1_1_30_gr_2202_asm_1_asm_1_1_30_gr_2202_asm_fl46blw10_48v_5n_m_de_2__fl46blw10_48v_5n_m_de_2 -->
              <geom type="mesh" class="visual" pos="-0.0452137 -0.0276536 0.0205" quat="0 -0.488996 -0.872286 0" mesh="6706__300001_1_1_00mini_000_asm_1_asm_1_asm_00mini__20250103_a0001_asm_1_as_asm_1_1_30_gr_2202_asm_1_asm_1_1_30_gr_2202_asm_fl46blw10_48v_5n_m_de_2__fl46blw10_48v_5n_m_de" material="6706__300001_1_1_00mini_000_asm_1_asm_1_asm_00mini__20250103_a0001_asm_1_as_asm_1_1_30_gr_2202_asm_1_asm_1_1_30_gr_2202_asm_fl46blw10_48v_5n_m_de_2__fl46blw10_48v_5n_m_de_material"/>
              <!-- Part 0001755650_00mini_000_asm_1_asm_1_asm_00mini__20250103_a0001_asm_1_as_asm_1_1_30_gr_2202_asm_1_asm_1_1_30_gr_2202_asm_fl46blw10_48v_5n_m_de_2__fl46blw10_48v_5n_m_de_2 -->
              <geom type="mesh" class="visual" pos="-0.0452137 -0.0276536 0.0209" quat="0 -0.488996 -0.872286 0" mesh="0001755650_00mini_000_asm_1_asm_1_asm_00mini__20250103_a0001_asm_1_as_asm_1_1_30_gr_2202_asm_1_asm_1_1_30_gr_2202_asm_fl46blw10_48v_5n_m_de_2__fl46blw10_48v_5n_m_de" material="0001755650_00mini_000_asm_1_asm_1_asm_00mini__20250103_a0001_asm_1_as_asm_1_1_30_gr_2202_asm_1_asm_1_1_30_gr_2202_asm_fl46blw10_48v_5n_m_de_2__fl46blw10_48v_5n_m_de_material"/>
              <!-- Link ankle_subassembly -->
              <body name="ankle_subassembly" pos="-0.221803 -0.135659 0.02" quat="0 0.835223 0.549911 0">
                <!-- Joint from shin_subassembly to ankle_subassembly -->
                <joint axis="0 0 1" name="ankley_right" type="hinge" range="-0.1745329252 0.3490658504" frictionloss="0.171194932409" armature="0.0300692570618" damping="0.0286354337613"/>
                <inertial pos="-8.342e-09 -0.00037364 0.02" mass="0.032674" fullinertia="1.20385e-05 8.75802e-06 4.66865e-06 3e-12 4e-12 -1e-12"/>
                <!-- Part hex_socket_head_cap_screw_m2_5x0_45_x_6__ec244025d76f8b83b2775022a2cb3232_7 -->
                <!-- Part 07534_05x40_catpart_2 -->
                <geom type="mesh" class="visual" pos="0 0.0249999 0.02" quat="0 -0.707107 0.707107 0" mesh="07534_05x40_catpart" material="07534_05x40_catpart_material"/>
                <!-- Part ujoint -->
                <geom type="mesh" class="visual" pos="-0 0 0.02" quat="0 0.707107 0 -0.707107" mesh="ujoint" material="ujoint_material"/>
                <!-- Part hex_socket_head_cap_screw_m2_5x0_45_x_6__ec244025d76f8b83b2775022a2cb3232_8 -->
                <!-- Part spacer_ujoint -->
                <geom type="mesh" class="visual" pos="-0 -0 0.02" quat="0.714619 -0 -0.699514 -0" mesh="spacer_ujoint" material="spacer_ujoint_material"/>
                <!-- Part hex_thin_nut_grade_a___b_m4x0_7__a8228d9ce5dcc05f24da0a2f74d882f3_4 -->
                <geom type="mesh" class="visual" pos="0 -0.02204 0.02" quat="0.505312 -0.505312 -0.494631 -0.494631" mesh="hex_thin_nut_grade_a___b_m4x0_7__a8228d9ce5dcc05f24da0a2f74d882f3" material="hex_thin_nut_grade_a___b_m4x0_7__a8228d9ce5dcc05f24da0a2f74d882f3_material"/>
                <!-- Part part_3_2 -->
                <geom type="mesh" class="visual" pos="0 -0 0.0195" quat="0 0.707107 0 -0.707107" mesh="part_3" material="part_3_material"/>
                <!-- Part bearing_5_16_5_3 -->
                <geom type="mesh" class="visual" pos="-0 -0.01594 0.02" quat="0.714619 -0 -0.699514 0" mesh="bearing_5_16_5" material="bearing_5_16_5_material"/>
                <!-- Part bearing_15_21_4_6 -->
                <geom type="mesh" class="visual" pos="0 0 0" quat="0.707107 0.707107 -0 -0" mesh="bearing_15_21_4" material="bearing_15_21_4_material"/>
                <!-- Part hex_socket_head_cap_screw_m2_5x0_45_x_6__ec244025d76f8b83b2775022a2cb3232_9 -->
                <!-- Part hex_socket_head_cap_screw_m2_5x0_45_x_6__ec244025d76f8b83b2775022a2cb3232_10 -->
                <!-- Part part_3_3 -->
                <geom type="mesh" class="visual" pos="0 -0 0.0205" quat="0 -0.707107 -0 -0.707107" mesh="part_3" material="part_3_material"/>
                <!-- Part hex_socket_head_cap_screw_m2_5x0_45_x_6__ec244025d76f8b83b2775022a2cb3232_11 -->
                <!-- Part hex_socket_head_cap_screw_m2_5x0_45_x_6__ec244025d76f8b83b2775022a2cb3232_12 -->
                <!-- Part bearing_5_16_5_4 -->
                <geom type="mesh" class="visual" pos="-0 0.0209456 0.02" quat="0.00732917 0 0.999973 -0" mesh="bearing_5_16_5" material="bearing_5_16_5_material"/>
                <!-- Part spacer_ujoint_2 -->
                <geom type="mesh" class="visual" pos="-0 5.64895e-06 0.02" quat="0 0.71227 -0 -0.701905" mesh="spacer_ujoint" material="spacer_ujoint_material"/>
                <!-- Part bearing_15_21_4_7 -->
                <geom type="mesh" class="visual" pos="0 0 0.04" quat="0 0 0.707107 -0.707107" mesh="bearing_15_21_4" material="bearing_15_21_4_material"/>
                <!-- Link foot_subassembly -->
                <body name="foot_subassembly" pos="-0 -0.01594 0.02" quat="0.5 0.5 0.5 -0.5">
                  <!-- Joint from ankle_subassembly to foot_subassembly -->
                  <joint axis="0 0 1" name="anklex_right" type="hinge" range="-0.1745329252 0.1745329252" frictionloss="0.233720916986" armature="0.0299366151844" damping="0.213671067131"/>
                  <inertial pos="8.523e-09 -0.0138418 -0.052232" mass="0.122498" fullinertia="0.000163413 0.000162266 7.07692e-05 -1.15e-10 -3e-11 1.11374e-05"/>
                  <!-- Part hex_socket_head_cap_screw_m2_5x0_45_x_6__ec244025d76f8b83b2775022a2cb3232_13 -->
                  <!-- Part 27628_01_050_catpart_3 -->
                  <geom type="mesh" class="visual" pos="0.021 3.5379e-08 -0.0660002" quat="0 0.707107 0.707107 -0" mesh="27628_01_050_catpart" material="27628_01_050_catpart_material"/>
                  <!-- Part hex_socket_head_cap_screw_m2_5x0_45_x_6__ec244025d76f8b83b2775022a2cb3232_14 -->
                  <!-- Part 07534_05x20_catpart_3 -->
                  <geom type="mesh" class="visual" pos="0.036 0 -0.066" quat="0 0 -1 0" mesh="07534_05x20_catpart" material="07534_05x20_catpart_material"/>
                  <!-- Part 27628_01_050_catpart_4 -->
                  <geom type="mesh" class="visual" pos="-0.021 -1.895e-08 -0.066" quat="0 -0.707107 -0.707107 -0" mesh="27628_01_050_catpart" material="27628_01_050_catpart_material"/>
                  <!-- Part 07534_05x20_catpart_4 -->
                  <geom type="mesh" class="visual" pos="-0.036 0 -0.066" quat="1 -0 0 -0" mesh="07534_05x20_catpart" material="07534_05x20_catpart_material"/>
                  <!-- Part hat_small -->
                  <geom type="mesh" class="visual" pos="0 -0.035 -0.0385" quat="0.5 -0.5 -0.5 -0.5" mesh="hat_small" material="hat_small_material"/>
                  <!-- Part hex_socket_head_cap_screw_m2_5x0_45_x_6__ec244025d76f8b83b2775022a2cb3232_15 -->
                  <!-- Part foot -->
                  <geom type="mesh" class="visual" pos="0 -0.035 -0.0385" quat="0.5 -0.5 -0.5 -0.5" mesh="foot" material="foot_material"/>
                  <geom name="right_foot_collision" type="mesh" class="collision" pos="0 -0.035 -0.0385" quat="0.5 -0.5 -0.5 -0.5" mesh="foot" material="foot_material" friction="0.6 0.005 0.0001" condim="3" priority="1" solref="0.005 1" solimp="0.995 0.9995 0.001 0.5 2"/>
                  <!-- Frame foot_right -->
                  <site group="3" name="foot_right" pos="-6.3535e-08 -0.035 -0.0480606" quat="0.5 -0.5 0.5 0.5"/>
                </body>
              </body>
            </body>
          </body>
        </body>
      </body>
      <!-- Link hipx_subassemby_sym -->
      <body name="hipx_subassemby_sym" pos="-0.000819037 0.13316 0.04164" quat="0.817502 -0.0568006 0.0418493 0.571589">
        <!-- Joint from torso_subassembly to hipx_subassemby_sym -->
        <joint axis="0 0 1" name="hipz_left" type="hinge" range="-0.3490658504 0.3490658504" frictionloss="1.35093364028" armature="0.0226574181459" damping="0.513890006059"/>
        <inertial pos="-0.0174888 0.0267097 -0.0909261" mass="1.05831" fullinertia="0.00121943 0.00118798 0.0012082 4.0549e-05 -0.000116358 0.000177075"/>
        <!-- Part rs02_2 -->
        <!-- Part hex_socket_head_cap_screw_m4x0_70_x_40__14321d45d56569246e7feb4574a6bae6_15 -->
        <!-- Part robstride02_2 -->
        <geom type="mesh" class="visual" pos="-0.575896 0.057308 -0.20175" quat="0.60316 -0.792908 -0.0689068 -0.0524169" mesh="robstride02" material="robstride02_material"/>
        <!-- Part hex_socket_head_cap_screw_m3x0_50_x_8__d566997e1880d7fd3377c5b0ee12206c_28 -->
        <!-- Part hex_socket_head_cap_screw_m3x0_50_x_8__d566997e1880d7fd3377c5b0ee12206c_29 -->
        <!-- Part hex_socket_head_cap_screw_m3x0_50_x_8__d566997e1880d7fd3377c5b0ee12206c_30 -->
        <!-- Part hex_socket_head_cap_screw_m3x0_50_x_8__d566997e1880d7fd3377c5b0ee12206c_31 -->
        <!-- Part hipz22_sym -->
        <geom type="mesh" class="visual" pos="0 0 0.1" quat="1 -0 0 0" mesh="hipz22_sym" material="hipz22_sym_material"/>
        <!-- Part hex_socket_head_cap_screw_m4x0_70_x_40__14321d45d56569246e7feb4574a6bae6_16 -->
        <!-- Part hipz12_sym -->
        <geom type="mesh" class="visual" pos="0 -0 0.1" quat="1 0 0 0" mesh="hipz12_sym" material="hipz12_sym_material"/>
        <!-- Part xt_30_2x2_f_5 -->
        <geom type="mesh" class="visual" pos="-0.0280156 0.0769561 -0.0718124" quat="0.498768 0.406175 -0.443127 0.624413" mesh="xt_30_2x2_f" material="xt_30_2x2_f_material"/>
        <!-- Part hex_socket_head_cap_screw_m3x0_50_x_8__d566997e1880d7fd3377c5b0ee12206c_32 -->
        <!-- Part hex_socket_head_cap_screw_m3x0_50_x_8__d566997e1880d7fd3377c5b0ee12206c_33 -->
        <!-- Part hex_socket_head_cap_screw_m3x0_50_x_8__d566997e1880d7fd3377c5b0ee12206c_34 -->
        <!-- Part hex_socket_head_cap_screw_m4x0_70_x_40__14321d45d56569246e7feb4574a6bae6_17 -->
        <!-- Part hex_socket_head_cap_screw_m3x0_50_x_8__d566997e1880d7fd3377c5b0ee12206c_35 -->
        <!-- Part hex_socket_head_cap_screw_m4x0_70_x_40__14321d45d56569246e7feb4574a6bae6_18 -->
        <!-- Part hex_socket_head_cap_screw_m4x0_70_x_40__14321d45d56569246e7feb4574a6bae6_19 -->
        <!-- Part hex_socket_head_cap_screw_m4x0_70_x_40__14321d45d56569246e7feb4574a6bae6_20 -->
        <!-- Part hex_socket_head_cap_screw_m3x0_50_x_8__d566997e1880d7fd3377c5b0ee12206c_36 -->
        <!-- Part hex_socket_head_cap_screw_m4x0_70_x_40__14321d45d56569246e7feb4574a6bae6_21 -->
        <!-- Part hex_socket_head_cap_screw_m3x0_50_x_8__d566997e1880d7fd3377c5b0ee12206c_37 -->
        <!-- Part hex_socket_head_cap_screw_m3x0_50_x_8__d566997e1880d7fd3377c5b0ee12206c_38 -->
        <!-- Part hex_socket_head_cap_screw_m4x0_70_x_40__14321d45d56569246e7feb4574a6bae6_22 -->
        <!-- Part bearing_35_72_17_4 -->
        <geom type="mesh" class="visual" pos="-0.01759 0.0267968 -0.104484" quat="0.792908 0.60316 -0.0524169 0.0689068" mesh="bearing_35_72_17" material="bearing_35_72_17_material"/>
        <!-- Part hex_socket_head_cap_screw_m3x0_50_x_8__d566997e1880d7fd3377c5b0ee12206c_39 -->
        <!-- Part hex_socket_head_cap_screw_m4x0_70_x_40__14321d45d56569246e7feb4574a6bae6_23 -->
        <!-- Part hex_socket_head_cap_screw_m3x0_50_x_8__d566997e1880d7fd3377c5b0ee12206c_40 -->
        <!-- Part hex_socket_head_cap_screw_m3x0_50_x_8__d566997e1880d7fd3377c5b0ee12206c_41 -->
        <!-- Part hex_socket_head_cap_screw_m4x0_70_x_40__14321d45d56569246e7feb4574a6bae6_24 -->
        <!-- Part hex_socket_head_cap_screw_m3x0_50_x_8__d566997e1880d7fd3377c5b0ee12206c_42 -->
        <!-- Link hipy_subassembly_sym -->
        <body name="hipy_subassembly_sym" pos="-0.01897 0.0289 -0.09689" quat="0.39832 -0.133662 0.086581 0.903316">
          <!-- Joint from hipx_subassemby_sym to hipy_subassembly_sym -->
          <joint axis="0 0 1" name="hipx_left" type="hinge" range="-0.3490658504 0.3490658504" frictionloss="1.16683759813" armature="0.133877916753" damping="0.739874062978"/>
          <inertial pos="0.00443977 0.00141012 -0.0603704" mass="0.451847" fullinertia="0.000889033 0.000809832 0.000829147 -4.17071e-05 1.03689e-06 3.88214e-05"/>
          <!-- Part hex_socket_head_cap_screw_m4x0_70_x_12__c825518ee8edf1afced0eee1b019b750_11 -->
          <!-- Part hex_socket_head_cap_screw_m4x0_70_x_12__c825518ee8edf1afced0eee1b019b750_12 -->
          <!-- Part hex_socket_head_cap_screw_m4x0_70_x_12__c825518ee8edf1afced0eee1b019b750_13 -->
          <!-- Part hex_socket_head_cap_screw_m4x0_70_x_12__c825518ee8edf1afced0eee1b019b750_14 -->
          <!-- Part hex_socket_head_cap_screw_m4x0_70_x_20__832e47d784177ea3f1dabbaab534416e_23 -->
          <!-- Part hex_socket_head_cap_screw_m4x0_70_x_20__832e47d784177ea3f1dabbaab534416e_24 -->
          <!-- Part hipxy_sym -->
          <geom type="mesh" class="visual" pos="0 0 0" quat="0 1 0 0" mesh="hipxy_sym" material="hipxy_sym_material"/>
          <!-- Part hex_socket_head_cap_screw_m4x0_70_x_12__c825518ee8edf1afced0eee1b019b750_15 -->
          <!-- Part hex_socket_head_cap_screw_m4x0_70_x_20__832e47d784177ea3f1dabbaab534416e_25 -->
          <!-- Part hex_socket_head_cap_screw_m4x0_70_x_12__c825518ee8edf1afced0eee1b019b750_16 -->
          <!-- Part hex_socket_head_cap_screw_m4x0_70_x_20__832e47d784177ea3f1dabbaab534416e_26 -->
          <!-- Part hex_socket_head_cap_screw_m4x0_70_x_20__832e47d784177ea3f1dabbaab534416e_27 -->
          <!-- Part hex_socket_head_cap_screw_m4x0_70_x_20__832e47d784177ea3f1dabbaab534416e_28 -->
          <!-- Link tigh_subassembly_sym -->
          <body name="tigh_subassembly_sym" pos="0.012638 0.0276823 -0.112055" quat="0.058861 -0.359211 -0.636097 -0.680355">
            <!-- Joint from hipy_subassembly_sym to tigh_subassembly_sym -->
            <joint axis="0 0 1" name="hipy_left" type="hinge" range="-1.0471975512 1.0471975512" frictionloss="1.3122407137" armature="0.14077316233" damping="1.45524910678"/>
            <inertial pos="-0.0441387 -0.0841718 -0.0353782" mass="2.60644" fullinertia="0.0187282 0.00866228 0.0248939 -0.00850175 -0.000852413 -0.00155814"/>
            <!-- Part knee_rod22_sym -->
            <geom type="mesh" class="visual" pos="-0.058 -0.280519 0.0295" quat="0.707107 -0.707107 0 0" mesh="knee_rod22_sym" material="knee_rod22_sym_material"/>
            <!-- Part hex_socket_head_cap_screw_m4x0_70_x_16__8d628c0d7a90368385b1c4c7479647eb_7 -->
            <!-- Part hex_socket_head_cap_screw_m2_5x0_45_x_6__ec244025d76f8b83b2775022a2cb3232_16 -->
            <!-- Part hex_socket_head_cap_screw_m4x0_70_x_8__a416dc2a8d778a4ef6150c0739aa89d1_15 -->
            <!-- Part hex_socket_head_cap_screw_m4x0_70_x_8__a416dc2a8d778a4ef6150c0739aa89d1_16 -->
            <!-- Part hex_socket_head_cap_screw_m4x0_70_x_8__a416dc2a8d778a4ef6150c0739aa89d1_17 -->
            <!-- Part hex_socket_head_cap_screw_m2_5x0_45_x_6__ec244025d76f8b83b2775022a2cb3232_17 -->
            <!-- Part hex_socket_head_cap_screw_m4x0_70_x_16__8d628c0d7a90368385b1c4c7479647eb_8 -->
            <!-- Part hex_socket_head_cap_screw_m4x0_70_x_40__14321d45d56569246e7feb4574a6bae6_25 -->
            <!-- Part hex_socket_head_cap_screw_m4x0_70_x_8__a416dc2a8d778a4ef6150c0739aa89d1_18 -->
            <!-- Part hex_socket_head_cap_screw_m4x0_70_x_8__a416dc2a8d778a4ef6150c0739aa89d1_19 -->
            <!-- Part hex_socket_head_cap_screw_m4x0_70_x_8__a416dc2a8d778a4ef6150c0739aa89d1_20 -->
            <!-- Part hex_socket_head_cap_screw_m4x0_70_x_16__8d628c0d7a90368385b1c4c7479647eb_9 -->
            <!-- Part bearing_15_21_4_8 -->
            <geom type="mesh" class="visual" pos="-0.221927 -0.268257 -0.0185" quat="0.5 -0.5 -0.5 0.5" mesh="bearing_15_21_4" material="bearing_15_21_4_material"/>
            <!-- Part part_3_4 -->
            <geom type="mesh" class="visual" pos="-0 0 -0.0938" quat="0.683013 0.183013 0.683013 -0.183013" mesh="part_3" material="part_3_material"/>
            <!-- Part bearing_15_21_4_9 -->
            <geom type="mesh" class="visual" pos="-0.102915 -0.0784891 -0.0245" quat="0.707107 -0.707107 0 0" mesh="bearing_15_21_4" material="bearing_15_21_4_material"/>
            <!-- Part hex_socket_head_cap_screw_m4x0_70_x_40__14321d45d56569246e7feb4574a6bae6_26 -->
            <!-- Part hex_socket_head_cap_screw_m4x0_70_x_8__a416dc2a8d778a4ef6150c0739aa89d1_21 -->
            <!-- Part bearing_15_21_4_10 -->
            <geom type="mesh" class="visual" pos="-0 0 -0.0675" quat="0.183013 -0.183013 -0.683013 0.683013" mesh="bearing_15_21_4" material="bearing_15_21_4_material"/>
            <!-- Part bearing_15_21_4_11 -->
            <geom type="mesh" class="visual" pos="-0.102915 -0.0784891 -0.0365" quat="0.707107 0.707107 0 -0" mesh="bearing_15_21_4" material="bearing_15_21_4_material"/>
            <!-- Part bearing_15_21_4_12 -->
            <geom type="mesh" class="visual" pos="-0.221927 -0.268257 -0.0465" quat="0.5 -0.5 -0.5 0.5" mesh="bearing_15_21_4" material="bearing_15_21_4_material"/>
            <!-- Part hex_socket_head_cap_screw_m2_5x0_45_x_6__ec244025d76f8b83b2775022a2cb3232_18 -->
            <!-- Part hex_socket_head_cap_screw_m4x0_70_x_16__8d628c0d7a90368385b1c4c7479647eb_10 -->
            <!-- Part hex_socket_head_cap_screw_m4x0_70_x_8__a416dc2a8d778a4ef6150c0739aa89d1_22 -->
            <!-- Part hex_socket_head_cap_screw_m4x0_70_x_40__14321d45d56569246e7feb4574a6bae6_27 -->
            <!-- Part femur_12_sym -->
            <geom type="mesh" class="visual" pos="-0.17 -0.294449 0.0295" quat="0.683013 -0.683013 0.183013 -0.183013" mesh="femur_12_sym" material="femur_12_sym_material"/>
            <geom name="femur_left_collision" type="mesh" class="collision" pos="-0.17 -0.294449 0.0295" quat="0.683013 -0.683013 0.183013 -0.183013" mesh="femur_12_sym" material="femur_12_sym_material"/>
            <!-- Part bearing_5_16_5_5 -->
            <geom type="mesh" class="visual" pos="-0.17 -0.294449 -0.045" quat="0.183013 0.183013 0.683013 0.683013" mesh="bearing_5_16_5" material="bearing_5_16_5_material"/>
            <!-- Part hex_socket_head_cap_screw_m3x0_50_x_10__9c80fcbba574884e63b580474e1ee150_28 -->
            <!-- Part hex_socket_head_cap_screw_m4x0_70_x_40__14321d45d56569246e7feb4574a6bae6_28 -->
            <!-- Part hex_socket_head_cap_screw_m4x0_70_x_16__8d628c0d7a90368385b1c4c7479647eb_11 -->
            <!-- Part hex_socket_head_cap_screw_m2_5x0_45_x_6__ec244025d76f8b83b2775022a2cb3232_19 -->
            <!-- Part hex_socket_head_cap_screw_m4x0_70_x_8__a416dc2a8d778a4ef6150c0739aa89d1_23 -->
            <!-- Part hex_socket_head_cap_screw_m2_5x0_45_x_6__ec244025d76f8b83b2775022a2cb3232_20 -->
            <!-- Part hex_socket_head_cap_screw_m4x0_70_x_16__8d628c0d7a90368385b1c4c7479647eb_12 -->
            <!-- Part knee_actuation_2 -->
            <geom type="mesh" class="visual" pos="-0.058 0.123541 -0.0305" quat="0.707107 0.707107 0 -0" mesh="knee_actuation" material="knee_actuation_material"/>
            <!-- Part femur_22_sym -->
            <geom type="mesh" class="visual" pos="-0.17 -0.294449 0.0295" quat="0.683013 -0.683013 0.183013 -0.183013" mesh="femur_22_sym" material="femur_22_sym_material"/>
            <!-- Part hat_femur_2 -->
            <geom type="mesh" class="visual" pos="-0.17 -0.294449 -0.0305" quat="0.183013 0.183013 0.683013 0.683013" mesh="hat_femur" material="hat_femur_material"/>
            <!-- Part hex_socket_head_cap_screw_m4x0_70_x_8__a416dc2a8d778a4ef6150c0739aa89d1_24 -->
            <!-- Part hex_socket_head_cap_screw_m3x0_50_x_10__9c80fcbba574884e63b580474e1ee150_29 -->
            <!-- Part bearing_5_16_5_6 -->
            <geom type="mesh" class="visual" pos="-0.17 -0.294449 -0.013" quat="0.183013 -0.183013 -0.683013 0.683013" mesh="bearing_5_16_5" material="bearing_5_16_5_material"/>
            <!-- Part robstrideo3_3 -->
            <geom type="mesh" class="visual" pos="0.655402 -0.194111 -0.0025" quat="0.183013 0.183013 0.683013 0.683013" mesh="robstrideo3" material="robstrideo3_material"/>
            <!-- Part hex_socket_head_cap_screw_m4x0_70_x_8__a416dc2a8d778a4ef6150c0739aa89d1_25 -->
            <!-- Part hex_socket_head_cap_screw_m4x0_70_x_8__a416dc2a8d778a4ef6150c0739aa89d1_26 -->
            <!-- Part hex_socket_head_cap_screw_m4x0_70_x_8__a416dc2a8d778a4ef6150c0739aa89d1_27 -->
            <!-- Part knee_rod12_sym -->
            <geom type="mesh" class="visual" pos="-0.058 -0.280519 0.0295" quat="0.707107 -0.707107 0 0" mesh="knee_rod12_sym" material="knee_rod12_sym_material"/>
            <!-- Part hex_socket_head_cap_screw_m3x0_50_x_10__9c80fcbba574884e63b580474e1ee150_30 -->
            <!-- Part hex_socket_head_cap_screw_m2_5x0_45_x_6__ec244025d76f8b83b2775022a2cb3232_21 -->
            <!-- Part hex_socket_head_cap_screw_m4x0_70_x_8__a416dc2a8d778a4ef6150c0739aa89d1_28 -->
            <!-- Part robstrideo3_4 -->
            <geom type="mesh" class="visual" pos="0.597402 -0.29457 -0.045" quat="0.183013 0.183013 0.683013 0.683013" mesh="robstrideo3" material="robstrideo3_material"/>
            <!-- Part 1_1_31_qt_942_1_3 -->
            <geom type="mesh" class="visual" pos="-0 0 -0.04" quat="0.5 0 -0 -0.866025" mesh="1_1_31_qt_942_1" material="1_1_31_qt_942_1_material"/>
            <!-- Part 1_1_06_eb903_538_1_3 -->
            <geom type="mesh" class="visual" pos="-0 0 -0.0566" quat="0.5 0 -0 -0.866025" mesh="1_1_06_eb903_538_1" material="1_1_06_eb903_538_1_material"/>
            <!-- Part 1_1_31_qt_942_1_4 -->
            <geom type="mesh" class="visual" pos="-0.058 -0.100459 -0.0825" quat="0.965926 0 -0 -0.258819" mesh="1_1_31_qt_942_1" material="1_1_31_qt_942_1_material"/>
            <!-- Part 1_1_06_eb903_538_1_4 -->
            <geom type="mesh" class="visual" pos="-0.058 -0.100459 -0.0991" quat="0.965926 0 -0 -0.258819" mesh="1_1_06_eb903_538_1" material="1_1_06_eb903_538_1_material"/>
            <!-- Part 1_1_06_eb903_537_af0_1_3 -->
            <geom type="mesh" class="visual" pos="-0 0 -0.0375" quat="0.965926 0 -0 -0.258819" mesh="1_1_06_eb903_537_af0_1" material="1_1_06_eb903_537_af0_1_material"/>
            <!-- Part 1_1_02_eb901_558_1_3 -->
            <geom type="mesh" class="visual" pos="0 -0 0" quat="0 1 0 0" mesh="1_1_02_eb901_558_1" material="1_1_02_eb901_558_1_material"/>
            <!-- Part 1_1_06_eb903_537_af0_1_4 -->
            <geom type="mesh" class="visual" pos="-0.058 -0.100459 -0.08" quat="0.866025 0 -0 0.5" mesh="1_1_06_eb903_537_af0_1" material="1_1_06_eb903_537_af0_1_material"/>
            <!-- Part 1_1_02_eb901_558_1_4 -->
            <geom type="mesh" class="visual" pos="-0.058 -0.100459 -0.0425" quat="0 -0.707107 -0.707107 -0" mesh="1_1_02_eb901_558_1" material="1_1_02_eb901_558_1_material"/>
            <!-- Link shin_subassembly_sym -->
            <body name="shin_subassembly_sym" pos="-0.17 -0.294449 -0.0305" quat="0.723237 0 0 -0.6906">
              <!-- Joint from tigh_subassembly_sym to shin_subassembly_sym -->
              <joint axis="0 0 1" name="knee_left" type="hinge" range="-0.5235987756 0.5235987756" frictionloss="1.0764965485" armature="0.123303314591" damping="1.96406341827"/>
              <inertial pos="0.00172454 -0.0893774 -1.40814e-05" mass="0.637284" fullinertia="0.00183662 0.000289677 0.00182542 -6.53641e-05 2.67582e-06 0.00013032"/>
              <!-- Part hex_socket_head_cap_screw_m3x0_50_x_20__7252065e4445f5ec71347b53fcae11e4_13 -->
              <!-- Part xt_30_2x2_f_6 -->
              <geom type="mesh" class="visual" pos="0.0212074 -0.0322876 0.0147" quat="0.270598 0.653281 0.270598 -0.653281" mesh="xt_30_2x2_f" material="xt_30_2x2_f_material"/>
              <!-- Part hex_socket_head_cap_screw_m3x0_50_x_20__7252065e4445f5ec71347b53fcae11e4_14 -->
              <!-- Part hex_socket_head_cap_screw_m3x0_50_x_20__7252065e4445f5ec71347b53fcae11e4_15 -->
              <!-- Part hex_socket_head_cap_screw_m3x0_50_x_10__9c80fcbba574884e63b580474e1ee150_31 -->
              <!-- Part 27628_01_050_catpart_5 -->
              <geom type="mesh" class="visual" pos="0.0300907 -0.0130682 -0.0195" quat="0.650205 0.650205 0.277908 0.277908" mesh="27628_01_050_catpart" material="27628_01_050_catpart_material"/>
              <!-- Part hex_socket_head_cap_screw_m3x0_50_x_20__7252065e4445f5ec71347b53fcae11e4_16 -->
              <!-- Part hex_socket_head_cap_screw_m3x0_50_x_30__cb22dc4460edbee8e1cbddf29677c00f_2 -->
              <!-- Part hex_socket_head_cap_screw_m3x0_50_x_10__9c80fcbba574884e63b580474e1ee150_32 -->
              <!-- Part hex_socket_head_cap_screw_m3x0_50_x_10__9c80fcbba574884e63b580474e1ee150_33 -->
              <!-- Part 07534_05x40_catpart_3 -->
              <geom type="mesh" class="visual" pos="0 0 -0.025" quat="0.5 -0.5 -0.5 -0.5" mesh="07534_05x40_catpart" material="07534_05x40_catpart_material"/>
              <!-- Part hex_socket_head_cap_screw_m3x0_50_x_10__9c80fcbba574884e63b580474e1ee150_34 -->
              <!-- Part hex_socket_head_cap_screw_m3x0_50_x_10__9c80fcbba574884e63b580474e1ee150_35 -->
              <!-- Part hex_socket_head_cap_screw_m3x0_50_x_10__9c80fcbba574884e63b580474e1ee150_36 -->
              <!-- Part hex_socket_head_cap_screw_m3x0_50_x_10__9c80fcbba574884e63b580474e1ee150_37 -->
              <!-- Part hex_socket_head_cap_screw_m3x0_50_x_20__7252065e4445f5ec71347b53fcae11e4_17 -->
              <!-- Part 07534_05x20_catpart_5 -->
              <geom type="mesh" class="visual" pos="0.0300908 -0.0660682 0.0405" quat="0.632814 -0.315509 0.632814 0.315509" mesh="07534_05x20_catpart" material="07534_05x20_catpart_material"/>
              <!-- Part tibias12_sym -->
              <geom type="mesh" class="visual" pos="-0 -0.26 0.067" quat="0.707107 -0.707107 0 0" mesh="tibias12_sym" material="tibias12_sym_material"/>
              <!-- Part hex_socket_head_cap_screw_m2_5x0_45_x_8__dec2226ceabd7d7ca0bb403ec234d89b_4 -->
              <!-- Part actuation_ankle_3 -->
              <geom type="mesh" class="visual" pos="0.12299 -0.14568 0.0195" quat="0.632814 -0.632814 -0.315509 0.315509" mesh="actuation_ankle" material="actuation_ankle_material"/>
              <!-- Part hex_socket_head_cap_screw_m3x0_50_x_20__7252065e4445f5ec71347b53fcae11e4_18 -->
              <!-- Part hex_socket_head_cap_screw_m3x0_50_x_10__9c80fcbba574884e63b580474e1ee150_38 -->
              <!-- Part hex_socket_head_cap_screw_m3x0_50_x_10__9c80fcbba574884e63b580474e1ee150_39 -->
              <!-- Part hex_thin_nut_grade_a___b_m4x0_7__a8228d9ce5dcc05f24da0a2f74d882f3_5 -->
              <geom type="mesh" class="visual" pos="0.0300908 -0.0660682 0.0129397" quat="0 0.317305 0.948324 0" mesh="hex_thin_nut_grade_a___b_m4x0_7__a8228d9ce5dcc05f24da0a2f74d882f3" material="hex_thin_nut_grade_a___b_m4x0_7__a8228d9ce5dcc05f24da0a2f74d882f3_material"/>
              <!-- Part hex_socket_head_cap_screw_m3x0_50_x_10__9c80fcbba574884e63b580474e1ee150_40 -->
              <!-- Part hex_socket_head_cap_screw_m3x0_50_x_20__7252065e4445f5ec71347b53fcae11e4_19 -->
              <!-- Part hex_socket_head_cap_screw_m3x0_50_x_20__7252065e4445f5ec71347b53fcae11e4_20 -->
              <!-- Part hex_socket_head_cap_screw_m3x0_50_x_10__9c80fcbba574884e63b580474e1ee150_41 -->
              <!-- Part rmdx43_3 -->
              <geom type="mesh" class="visual" pos="0.470217 -0.113201 -0.006" quat="0 -0 -0.707107 0.707107" mesh="rmdx43" material="rmdx43_material"/>
              <!-- Part hex_socket_head_cap_screw_m2_5x0_45_x_8__dec2226ceabd7d7ca0bb403ec234d89b_5 -->
              <!-- Part hex_socket_head_cap_screw_m4x0_70_x_12__c825518ee8edf1afced0eee1b019b750_17 -->
              <!-- Part hex_socket_head_cap_screw_m3x0_50_x_20__7252065e4445f5ec71347b53fcae11e4_21 -->
              <!-- Part hex_socket_head_cap_screw_m4x0_70_x_12__c825518ee8edf1afced0eee1b019b750_18 -->
              <!-- Part hex_socket_head_cap_screw_m3x0_50_x_10__9c80fcbba574884e63b580474e1ee150_42 -->
              <!-- Part hex_socket_head_cap_screw_m3x0_50_x_10__9c80fcbba574884e63b580474e1ee150_43 -->
              <!-- Part hex_socket_head_cap_screw_m3x0_50_x_10__9c80fcbba574884e63b580474e1ee150_44 -->
              <!-- Part hex_socket_head_cap_screw_m4x0_70_x_12__c825518ee8edf1afced0eee1b019b750_19 -->
              <!-- Part hex_socket_head_cap_screw_m3x0_50_x_20__7252065e4445f5ec71347b53fcae11e4_22 -->
              <!-- Part hex_socket_head_cap_screw_m3x0_50_x_10__9c80fcbba574884e63b580474e1ee150_45 -->
              <!-- Part hex_socket_head_cap_screw_m3x0_50_x_10__9c80fcbba574884e63b580474e1ee150_46 -->
              <!-- Part 07534_05x20_catpart_6 -->
              <geom type="mesh" class="visual" pos="0.0300908 -0.0130682 -0.0405" quat="0.632814 0.315509 -0.632814 0.315509" mesh="07534_05x20_catpart" material="07534_05x20_catpart_material"/>
              <!-- Part rmdx43_4 -->
              <geom type="mesh" class="visual" pos="0.470217 -0.0457991 0.006" quat="0 0 0.707107 0.707107" mesh="rmdx43" material="rmdx43_material"/>
              <!-- Part tibias22_sym -->
              <geom type="mesh" class="visual" pos="-0 -0.26 0.067" quat="0.707107 -0.707107 0 -0" mesh="tibias22_sym" material="tibias22_sym_material"/>
              <!-- Part hex_socket_head_cap_screw_m3x0_50_x_20__7252065e4445f5ec71347b53fcae11e4_23 -->
              <!-- Part hex_socket_head_cap_screw_m4x0_70_x_12__c825518ee8edf1afced0eee1b019b750_20 -->
              <!-- Part hex_socket_head_cap_screw_m3x0_50_x_10__9c80fcbba574884e63b580474e1ee150_47 -->
              <!-- Part xt_30_2x2_f_7 -->
              <geom type="mesh" class="visual" pos="0.0212074 -0.126712 -0.015" quat="0.653281 -0.270598 -0.653281 -0.270598" mesh="xt_30_2x2_f" material="xt_30_2x2_f_material"/>
              <!-- Part hex_thin_nut_grade_a___b_m4x0_7__a8228d9ce5dcc05f24da0a2f74d882f3_6 -->
              <geom type="mesh" class="visual" pos="0 -0 0.0247603" quat="0 -0 1 -0" mesh="hex_thin_nut_grade_a___b_m4x0_7__a8228d9ce5dcc05f24da0a2f74d882f3" material="hex_thin_nut_grade_a___b_m4x0_7__a8228d9ce5dcc05f24da0a2f74d882f3_material"/>
              <!-- Part hex_socket_head_cap_screw_m3x0_50_x_10__9c80fcbba574884e63b580474e1ee150_48 -->
              <!-- Part hex_socket_head_cap_screw_m3x0_50_x_10__9c80fcbba574884e63b580474e1ee150_49 -->
              <!-- Part actuation_ankle_4 -->
              <geom type="mesh" class="visual" pos="-0.12299 -0.0133205 -0.0195" quat="0.632814 0.632814 0.315509 0.315509" mesh="actuation_ankle" material="actuation_ankle_material"/>
              <!-- Part hex_socket_head_cap_screw_m3x0_50_x_10__9c80fcbba574884e63b580474e1ee150_50 -->
              <!-- Part hex_socket_head_cap_screw_m3x0_50_x_10__9c80fcbba574884e63b580474e1ee150_51 -->
              <!-- Part hex_socket_head_cap_screw_m3x0_50_x_10__9c80fcbba574884e63b580474e1ee150_52 -->
              <!-- Part hex_socket_head_cap_screw_m3x0_50_x_10__9c80fcbba574884e63b580474e1ee150_53 -->
              <!-- Part hex_socket_head_cap_screw_m3x0_50_x_20__7252065e4445f5ec71347b53fcae11e4_24 -->
              <!-- Part hat_big_2 -->
              <geom type="mesh" class="visual" pos="-0 -0.26 -0.019" quat="0 0 0.707107 0.707107" mesh="hat_big" material="hat_big_material"/>
              <!-- Part hex_socket_head_cap_screw_m2_5x0_45_x_8__dec2226ceabd7d7ca0bb403ec234d89b_6 -->
              <!-- Part 27628_01_050_catpart_6 -->
              <geom type="mesh" class="visual" pos="0.0300907 -0.066068 0.0225" quat="4.65505e-05 4.65505e-05 -0.707107 -0.707107" mesh="27628_01_050_catpart" material="27628_01_050_catpart_material"/>
              <!-- Part hex_socket_head_cap_screw_m3x0_50_x_10__9c80fcbba574884e63b580474e1ee150_54 -->
              <!-- Part hex_thin_nut_grade_a___b_m4x0_7__a8228d9ce5dcc05f24da0a2f74d882f3_7 -->
              <geom type="mesh" class="visual" pos="0.0300908 -0.0130682 -0.0129397" quat="0.317305 0 0 0.948324" mesh="hex_thin_nut_grade_a___b_m4x0_7__a8228d9ce5dcc05f24da0a2f74d882f3" material="hex_thin_nut_grade_a___b_m4x0_7__a8228d9ce5dcc05f24da0a2f74d882f3_material"/>
              <!-- Part 1_1_31_eb463_510_fl46blw10_48v_5n_m_de_2__fl46blw10_48v_5n_m_de_3 -->
              <geom type="mesh" class="visual" pos="-0 -0.106 0.019" quat="0.19509 -0 0 0.980785" mesh="1_1_31_eb463_510_fl46blw10_48v_5n_m_de_2__fl46blw10_48v_5n_m_de" material="1_1_31_eb463_510_fl46blw10_48v_5n_m_de_2__fl46blw10_48v_5n_m_de_material"/>
              <!-- Part 1_1_02_eb461_502_fl46blw10_48v_5n_m_de_2__fl46blw10_48v_5n_m_de_3 -->
              <geom type="mesh" class="visual" pos="-0 -0.106 0.009" quat="0.19509 -0 0 0.980785" mesh="1_1_02_eb461_502_fl46blw10_48v_5n_m_de_2__fl46blw10_48v_5n_m_de" material="1_1_02_eb461_502_fl46blw10_48v_5n_m_de_2__fl46blw10_48v_5n_m_de_material"/>
              <!-- Part 1_1_06_eb463_509_fl46blw10_48v_5n_m_de_2__fl46blw10_48v_5n_m_de_3 -->
              <geom type="mesh" class="visual" pos="-0 -0.106 -0.0225" quat="0.707107 -0 0 0.707107" mesh="1_1_06_eb463_509_fl46blw10_48v_5n_m_de_2__fl46blw10_48v_5n_m_de" material="1_1_06_eb463_509_fl46blw10_48v_5n_m_de_2__fl46blw10_48v_5n_m_de_material"/>
              <!-- Part 1_1_06_eb463_507_fl46blw10_48v_5n_m_de_2__fl46blw10_48v_5n_m_de_3 -->
              <geom type="mesh" class="visual" pos="-0 -0.106 -0.009" quat="0.382683 -0 0 0.92388" mesh="1_1_06_eb463_507_fl46blw10_48v_5n_m_de_2__fl46blw10_48v_5n_m_de" material="1_1_06_eb463_507_fl46blw10_48v_5n_m_de_2__fl46blw10_48v_5n_m_de_material"/>
              <!-- Part 1_1_31_eb463_510_fl46blw10_48v_5n_m_de_2__fl46blw10_48v_5n_m_de_4 -->
              <geom type="mesh" class="visual" pos="0 -0.053 -0.019" quat="0 0.19509 -0.980785 0" mesh="1_1_31_eb463_510_fl46blw10_48v_5n_m_de_2__fl46blw10_48v_5n_m_de" material="1_1_31_eb463_510_fl46blw10_48v_5n_m_de_2__fl46blw10_48v_5n_m_de_material"/>
              <!-- Part 1_1_02_eb461_502_fl46blw10_48v_5n_m_de_2__fl46blw10_48v_5n_m_de_4 -->
              <geom type="mesh" class="visual" pos="0 -0.053 -0.009" quat="0 0.19509 -0.980785 0" mesh="1_1_02_eb461_502_fl46blw10_48v_5n_m_de_2__fl46blw10_48v_5n_m_de" material="1_1_02_eb461_502_fl46blw10_48v_5n_m_de_2__fl46blw10_48v_5n_m_de_material"/>
              <!-- Part 1_1_06_eb463_509_fl46blw10_48v_5n_m_de_2__fl46blw10_48v_5n_m_de_4 -->
              <geom type="mesh" class="visual" pos="-0 -0.053 0.0225" quat="0 0.707107 -0.707107 0" mesh="1_1_06_eb463_509_fl46blw10_48v_5n_m_de_2__fl46blw10_48v_5n_m_de" material="1_1_06_eb463_509_fl46blw10_48v_5n_m_de_2__fl46blw10_48v_5n_m_de_material"/>
              <!-- Part 1_1_06_eb463_507_fl46blw10_48v_5n_m_de_2__fl46blw10_48v_5n_m_de_4 -->
              <geom type="mesh" class="visual" pos="-0 -0.053 0.009" quat="0 0.382683 -0.92388 0" mesh="1_1_06_eb463_507_fl46blw10_48v_5n_m_de_2__fl46blw10_48v_5n_m_de" material="1_1_06_eb463_507_fl46blw10_48v_5n_m_de_2__fl46blw10_48v_5n_m_de_material"/>
              <!-- Part 0001755652_1_1_30_gr_2202_asm_1_asm_1_1_30_gr_2202_asm_fl46blw10_48v_5n_m_de_2__fl46blw10_48v_5n_m_de_5 -->
              <geom type="mesh" class="visual" pos="0.00671751 -0.0992825 0.0235" quat="0 0.92388 -0.382683 0" mesh="0001755652_1_1_30_gr_2202_asm_1_asm_1_1_30_gr_2202_asm_fl46blw10_48v_5n_m_de_2__fl46blw10_48v_5n_m_de" material="0001755652_1_1_30_gr_2202_asm_1_asm_1_1_30_gr_2202_asm_fl46blw10_48v_5n_m_de_2__fl46blw10_48v_5n_m_de_material"/>
              <!-- Part 0001755652_1_1_30_gr_2202_asm_1_asm_1_1_30_gr_2202_asm_fl46blw10_48v_5n_m_de_2__fl46blw10_48v_5n_m_de_6 -->
              <geom type="mesh" class="visual" pos="0.00245878 -0.115176 0.0235" quat="0 0.92388 -0.382683 0" mesh="0001755652_1_1_30_gr_2202_asm_1_asm_1_1_30_gr_2202_asm_fl46blw10_48v_5n_m_de_2__fl46blw10_48v_5n_m_de" material="0001755652_1_1_30_gr_2202_asm_1_asm_1_1_30_gr_2202_asm_fl46blw10_48v_5n_m_de_2__fl46blw10_48v_5n_m_de_material"/>
              <!-- Part 0001755652_1_1_30_gr_2202_asm_1_asm_1_1_30_gr_2202_asm_fl46blw10_48v_5n_m_de_2__fl46blw10_48v_5n_m_de_7 -->
              <geom type="mesh" class="visual" pos="0.00671751 -0.0597175 -0.0235" quat="0.92388 -0 0 0.382683" mesh="0001755652_1_1_30_gr_2202_asm_1_asm_1_1_30_gr_2202_asm_fl46blw10_48v_5n_m_de_2__fl46blw10_48v_5n_m_de" material="0001755652_1_1_30_gr_2202_asm_1_asm_1_1_30_gr_2202_asm_fl46blw10_48v_5n_m_de_2__fl46blw10_48v_5n_m_de_material"/>
              <!-- Part 0001755652_1_1_30_gr_2202_asm_1_asm_1_1_30_gr_2202_asm_fl46blw10_48v_5n_m_de_2__fl46blw10_48v_5n_m_de_8 -->
              <geom type="mesh" class="visual" pos="0.00245878 -0.0438237 -0.0235" quat="0.92388 -0 0 0.382683" mesh="0001755652_1_1_30_gr_2202_asm_1_asm_1_1_30_gr_2202_asm_fl46blw10_48v_5n_m_de_2__fl46blw10_48v_5n_m_de" material="0001755652_1_1_30_gr_2202_asm_1_asm_1_1_30_gr_2202_asm_fl46blw10_48v_5n_m_de_2__fl46blw10_48v_5n_m_de_material"/>
              <!-- Part 0001755652_00mini_000_asm_1_asm_1_asm_00mini__20250103_a0001_asm_1_as_asm_1_1_30_gr_2202_asm_1_asm_1_1_30_gr_2202_asm_fl46blw10_48v_5n_m_de_2__fl46blw10_48v_5n_m_de_3 -->
              <geom type="mesh" class="visual" pos="-0.0091763 -0.103541 0.0235" quat="0 0.92388 -0.382683 0" mesh="0001755652_00mini_000_asm_1_asm_1_asm_00mini__20250103_a0001_asm_1_as_asm_1_1_30_gr_2202_asm_1_asm_1_1_30_gr_2202_asm_fl46blw10_48v_5n_m_de_2__fl46blw10_48v_5n_m_de" material="0001755652_00mini_000_asm_1_asm_1_asm_00mini__20250103_a0001_asm_1_as_asm_1_1_30_gr_2202_asm_1_asm_1_1_30_gr_2202_asm_fl46blw10_48v_5n_m_de_2__fl46blw10_48v_5n_m_de_material"/>
              <!-- Part 6706__300001_1_1_00mini_000_asm_1_asm_1_asm_00mini__20250103_a0001_asm_1_as_asm_1_1_30_gr_2202_asm_1_asm_1_1_30_gr_2202_asm_fl46blw10_48v_5n_m_de_2__fl46blw10_48v_5n_m_de_3 -->
              <geom type="mesh" class="visual" pos="-0 -0.106 0.02" quat="0 0.92388 -0.382683 0" mesh="6706__300001_1_1_00mini_000_asm_1_asm_1_asm_00mini__20250103_a0001_asm_1_as_asm_1_1_30_gr_2202_asm_1_asm_1_1_30_gr_2202_asm_fl46blw10_48v_5n_m_de_2__fl46blw10_48v_5n_m_de" material="6706__300001_1_1_00mini_000_asm_1_asm_1_asm_00mini__20250103_a0001_asm_1_as_asm_1_1_30_gr_2202_asm_1_asm_1_1_30_gr_2202_asm_fl46blw10_48v_5n_m_de_2__fl46blw10_48v_5n_m_de_material"/>
              <!-- Part 0001755650_00mini_000_asm_1_asm_1_asm_00mini__20250103_a0001_asm_1_as_asm_1_1_30_gr_2202_asm_1_asm_1_1_30_gr_2202_asm_fl46blw10_48v_5n_m_de_2__fl46blw10_48v_5n_m_de_3 -->
              <geom type="mesh" class="visual" pos="-0 -0.106 0.0204" quat="0 0.92388 -0.382683 0" mesh="0001755650_00mini_000_asm_1_asm_1_asm_00mini__20250103_a0001_asm_1_as_asm_1_1_30_gr_2202_asm_1_asm_1_1_30_gr_2202_asm_fl46blw10_48v_5n_m_de_2__fl46blw10_48v_5n_m_de" material="0001755650_00mini_000_asm_1_asm_1_asm_00mini__20250103_a0001_asm_1_as_asm_1_1_30_gr_2202_asm_1_asm_1_1_30_gr_2202_asm_fl46blw10_48v_5n_m_de_2__fl46blw10_48v_5n_m_de_material"/>
              <!-- Part 0001755652_00mini_000_asm_1_asm_1_asm_00mini__20250103_a0001_asm_1_as_asm_1_1_30_gr_2202_asm_1_asm_1_1_30_gr_2202_asm_fl46blw10_48v_5n_m_de_2__fl46blw10_48v_5n_m_de_4 -->
              <geom type="mesh" class="visual" pos="-0.0091763 -0.0554588 -0.0235" quat="0.92388 -0 0 0.382683" mesh="0001755652_00mini_000_asm_1_asm_1_asm_00mini__20250103_a0001_asm_1_as_asm_1_1_30_gr_2202_asm_1_asm_1_1_30_gr_2202_asm_fl46blw10_48v_5n_m_de_2__fl46blw10_48v_5n_m_de" material="0001755652_00mini_000_asm_1_asm_1_asm_00mini__20250103_a0001_asm_1_as_asm_1_1_30_gr_2202_asm_1_asm_1_1_30_gr_2202_asm_fl46blw10_48v_5n_m_de_2__fl46blw10_48v_5n_m_de_material"/>
              <!-- Part 6706__300001_1_1_00mini_000_asm_1_asm_1_asm_00mini__20250103_a0001_asm_1_as_asm_1_1_30_gr_2202_asm_1_asm_1_1_30_gr_2202_asm_fl46blw10_48v_5n_m_de_2__fl46blw10_48v_5n_m_de_4 -->
              <geom type="mesh" class="visual" pos="0 -0.053 -0.02" quat="0.92388 -0 0 0.382683" mesh="6706__300001_1_1_00mini_000_asm_1_asm_1_asm_00mini__20250103_a0001_asm_1_as_asm_1_1_30_gr_2202_asm_1_asm_1_1_30_gr_2202_asm_fl46blw10_48v_5n_m_de_2__fl46blw10_48v_5n_m_de" material="6706__300001_1_1_00mini_000_asm_1_asm_1_asm_00mini__20250103_a0001_asm_1_as_asm_1_1_30_gr_2202_asm_1_asm_1_1_30_gr_2202_asm_fl46blw10_48v_5n_m_de_2__fl46blw10_48v_5n_m_de_material"/>
              <!-- Part 0001755650_00mini_000_asm_1_asm_1_asm_00mini__20250103_a0001_asm_1_as_asm_1_1_30_gr_2202_asm_1_asm_1_1_30_gr_2202_asm_fl46blw10_48v_5n_m_de_2__fl46blw10_48v_5n_m_de_4 -->
              <geom type="mesh" class="visual" pos="0 -0.053 -0.0204" quat="0.92388 -0 0 0.382683" mesh="0001755650_00mini_000_asm_1_asm_1_asm_00mini__20250103_a0001_asm_1_as_asm_1_1_30_gr_2202_asm_1_asm_1_1_30_gr_2202_asm_fl46blw10_48v_5n_m_de_2__fl46blw10_48v_5n_m_de" material="0001755650_00mini_000_asm_1_asm_1_asm_00mini__20250103_a0001_asm_1_as_asm_1_1_30_gr_2202_asm_1_asm_1_1_30_gr_2202_asm_fl46blw10_48v_5n_m_de_2__fl46blw10_48v_5n_m_de_material"/>
              <!-- Link ankle_subassembly_2 -->
              <body name="ankle_subassembly_2" pos="-0 -0.26 -0.02" quat="0.888104 -0 0 -0.459642">
                <!-- Joint from shin_subassembly_sym to ankle_subassembly_2 -->
                <joint axis="0 0 1" name="ankley_left" type="hinge" range="-0.3490658504 0.1745329252" frictionloss="0.17117010829" armature="0.0296987477637" damping="0.0286137304687"/>
                <inertial pos="8.342e-09 -0.00037364 0.02" mass="0.032674" fullinertia="1.20385e-05 8.75802e-06 4.66865e-06 -3e-12 4e-12 1e-12"/>
                <!-- Part hex_socket_head_cap_screw_m2_5x0_45_x_6__ec244025d76f8b83b2775022a2cb3232_22 -->
                <!-- Part 07534_05x40_catpart_4 -->
                <geom type="mesh" class="visual" pos="-0 0.0249999 0.02" quat="0.707107 0 -0 -0.707107" mesh="07534_05x40_catpart" material="07534_05x40_catpart_material"/>
                <!-- Part ujoint_2 -->
                <geom type="mesh" class="visual" pos="-0 -0 0.02" quat="0 -0.707107 -0 -0.707107" mesh="ujoint" material="ujoint_material"/>
                <!-- Part hex_socket_head_cap_screw_m2_5x0_45_x_6__ec244025d76f8b83b2775022a2cb3232_23 -->
                <!-- Part spacer_ujoint_3 -->
                <geom type="mesh" class="visual" pos="-0 -0 0.02" quat="0.699514 -0 0.714619 0" mesh="spacer_ujoint" material="spacer_ujoint_material"/>
                <!-- Part hex_thin_nut_grade_a___b_m4x0_7__a8228d9ce5dcc05f24da0a2f74d882f3_8 -->
                <geom type="mesh" class="visual" pos="-0 -0.02204 0.02" quat="0.494631 -0.494631 0.505312 0.505312" mesh="hex_thin_nut_grade_a___b_m4x0_7__a8228d9ce5dcc05f24da0a2f74d882f3" material="hex_thin_nut_grade_a___b_m4x0_7__a8228d9ce5dcc05f24da0a2f74d882f3_material"/>
                <!-- Part part_3_5 -->
                <geom type="mesh" class="visual" pos="0 -0 0.0205" quat="0 -0.707107 -0 -0.707107" mesh="part_3" material="part_3_material"/>
                <!-- Part bearing_5_16_5_7 -->
                <geom type="mesh" class="visual" pos="0 -0.01594 0.02" quat="0.699514 -0 0.714619 0" mesh="bearing_5_16_5" material="bearing_5_16_5_material"/>
                <!-- Part bearing_15_21_4_13 -->
                <geom type="mesh" class="visual" pos="-0 -0 0.04" quat="0 -0 0.707107 -0.707107" mesh="bearing_15_21_4" material="bearing_15_21_4_material"/>
                <!-- Part hex_socket_head_cap_screw_m2_5x0_45_x_6__ec244025d76f8b83b2775022a2cb3232_24 -->
                <!-- Part hex_socket_head_cap_screw_m2_5x0_45_x_6__ec244025d76f8b83b2775022a2cb3232_25 -->
                <!-- Part part_3_6 -->
                <geom type="mesh" class="visual" pos="-0 -0 0.0195" quat="0 0.707107 0 -0.707107" mesh="part_3" material="part_3_material"/>
                <!-- Part hex_socket_head_cap_screw_m2_5x0_45_x_6__ec244025d76f8b83b2775022a2cb3232_26 -->
                <!-- Part hex_socket_head_cap_screw_m2_5x0_45_x_6__ec244025d76f8b83b2775022a2cb3232_27 -->
                <!-- Part bearing_5_16_5_8 -->
                <geom type="mesh" class="visual" pos="0 0.0209456 0.02" quat="0.999973 -0 -0.00732917 0" mesh="bearing_5_16_5" material="bearing_5_16_5_material"/>
                <!-- Part spacer_ujoint_4 -->
                <geom type="mesh" class="visual" pos="0 5.64895e-06 0.02" quat="0 -0.701905 -0 -0.71227" mesh="spacer_ujoint" material="spacer_ujoint_material"/>
                <!-- Part bearing_15_21_4_14 -->
                <geom type="mesh" class="visual" pos="-0 0 0" quat="0.707107 0.707107 0 -0" mesh="bearing_15_21_4" material="bearing_15_21_4_material"/>
                <!-- Link foot_subassembly_2 -->
                <body name="foot_subassembly_2" pos="0 -0.01594 0.02" quat="0.498399 0.498399 -0.501595 0.501595">
                  <!-- Joint from ankle_subassembly_2 to foot_subassembly_2 -->
                  <joint axis="0 0 1" name="anklex_left" type="hinge" range="-0.1745329252 0.1745329252" frictionloss="0.290252613159" armature="0.0300569538165" damping="0.209538497228"/>
                  <inertial pos="8.523e-09 -0.0138418 -0.052232" mass="0.122498" fullinertia="0.000163413 0.000162266 7.07692e-05 -1.15e-10 -3e-11 1.11374e-05"/>
                  <!-- Part hex_socket_head_cap_screw_m2_5x0_45_x_6__ec244025d76f8b83b2775022a2cb3232_28 -->
                  <!-- Part 27628_01_050_catpart_7 -->
                  <geom type="mesh" class="visual" pos="0.021 3.5379e-08 -0.0660002" quat="0 -0.707107 -0.707107 -0" mesh="27628_01_050_catpart" material="27628_01_050_catpart_material"/>
                  <!-- Part hex_socket_head_cap_screw_m2_5x0_45_x_6__ec244025d76f8b83b2775022a2cb3232_29 -->
                  <!-- Part 07534_05x20_catpart_7 -->
                  <geom type="mesh" class="visual" pos="0.036 0 -0.066" quat="0 -0 -1 -0" mesh="07534_05x20_catpart" material="07534_05x20_catpart_material"/>
                  <!-- Part 27628_01_050_catpart_8 -->
                  <geom type="mesh" class="visual" pos="-0.021 -1.895e-08 -0.066" quat="0 0.707107 0.707107 -0" mesh="27628_01_050_catpart" material="27628_01_050_catpart_material"/>
                  <!-- Part 07534_05x20_catpart_8 -->
                  <geom type="mesh" class="visual" pos="-0.036 0 -0.066" quat="1 0 0 0" mesh="07534_05x20_catpart" material="07534_05x20_catpart_material"/>
                  <!-- Part hat_small_2 -->
                  <geom type="mesh" class="visual" pos="0 -0.035 -0.0385" quat="0.5 -0.5 -0.5 -0.5" mesh="hat_small" material="hat_small_material"/>
                  <!-- Part hex_socket_head_cap_screw_m2_5x0_45_x_6__ec244025d76f8b83b2775022a2cb3232_30 -->
                  <!-- Part foot_2 -->
                  <geom type="mesh" class="visual" pos="0 -0.035 -0.0385" quat="0.5 -0.5 -0.5 -0.5" mesh="foot" material="foot_material"/>
                  <geom name="left_foot_collision" type="mesh" class="collision" pos="0 -0.035 -0.0385" quat="0.5 -0.5 -0.5 -0.5" mesh="foot" material="foot_material"/>
                  <!-- Frame foot_left -->
                  <site group="3" name="foot_left" pos="-6.3535e-08 -0.035 -0.0480606" quat="0.5 -0.5 0.5 0.5"/>
                </body>
              </body>
            </body>
          </body>
        </body>
      </body>
    </body>

  </worldbody>
  <asset>
    <mesh file="ethernet__3.stl"/>
    <mesh file="robstride02.stl"/>
    <mesh file="pcba_components_geometry__2.stl"/>
    <mesh file="tibias12.stl"/>
    <mesh file="1_1_06_eb463_509_fl46blw10_48v_5n_m_de_2__fl46blw10_48v_5n_m_de.stl"/>
    <mesh file="hex_thin_nut_grade_a___b_m4x0_7__a8228d9ce5dcc05f24da0a2f74d882f3.stl"/>
    <mesh file="robstrideo3.stl"/>
    <mesh file="pcie.stl"/>
    <mesh file="chips.stl"/>
    <mesh file="chips__2.stl"/>
    <mesh file="chips__10.stl"/>
    <mesh file="mounting_holes__3.stl"/>
    <mesh file="imu.stl"/>
    <mesh file="1_1_02_eb901_558_1.stl"/>
    <mesh file="pcba_components_geometry__7.stl"/>
    <mesh file="usbcan.stl"/>
    <mesh file="pcie__2.stl"/>
    <mesh file="pcba_components_geometry__3.stl"/>
    <mesh file="0001755652_1_1_30_gr_2202_asm_1_asm_1_1_30_gr_2202_asm_fl46blw10_48v_5n_m_de_2__fl46blw10_48v_5n_m_de.stl"/>
    <mesh file="0001755650_00mini_000_asm_1_asm_1_asm_00mini__20250103_a0001_asm_1_as_asm_1_1_30_gr_2202_asm_1_asm_1_1_30_gr_2202_asm_fl46blw10_48v_5n_m_de_2__fl46blw10_48v_5n_m_de.stl"/>
    <mesh file="part_3.stl"/>
    <mesh file="chips__9.stl"/>
    <mesh file="chips__6.stl"/>
    <mesh file="bearing_35_72_17.stl"/>
    <mesh file="hipz12_sym.stl"/>
    <mesh file="usb3_port__2.stl"/>
    <mesh file="xt_30_2x2_f.stl"/>
    <mesh file="femur_22_sym.stl"/>
    <mesh file="bearing_15_21_4.stl"/>
    <mesh file="part_7.stl"/>
    <mesh file="chips__5.stl"/>
    <mesh file="hipz22.stl"/>
    <mesh file="hdmi_micro__2.stl"/>
    <mesh file="foot.stl"/>
    <mesh file="mounting_holes.stl"/>
    <mesh file="pcba_components_geometry__4.stl"/>
    <mesh file="csi_dsi_connector.stl"/>
    <mesh file="bearing_5_16_5.stl"/>
    <mesh file="part_5.stl"/>
    <mesh file="usb2_port__2.stl"/>
    <mesh file="connector.stl"/>
    <mesh file="hipz12.stl"/>
    <mesh file="ir.stl"/>
    <mesh file="usb3_port.stl"/>
    <mesh file="knee_rod12.stl"/>
    <mesh file="1_1_06_eb903_538_1.stl"/>
    <mesh file="robstrideo0.stl"/>
    <mesh file="ir__2.stl"/>
    <mesh file="ethernet.stl"/>
    <mesh file="1_1_02_eb461_502_fl46blw10_48v_5n_m_de_2__fl46blw10_48v_5n_m_de.stl"/>
    <mesh file="csi_dsi_connector__2.stl"/>
    <mesh file="knee_rod22_sym.stl"/>
    <mesh file="ethernet__2.stl"/>
    <mesh file="knee_rod12_sym.stl"/>
    <mesh file="pcb.stl"/>
    <mesh file="poe_pins__3.stl"/>
    <mesh file="knee_rod22.stl"/>
    <mesh file="spacer_ujoint.stl"/>
    <mesh file="poe_geometry.stl"/>
    <mesh file="pcba_components_geometry__6.stl"/>
    <mesh file="tibias12_sym.stl"/>
    <mesh file="part_6.stl"/>
    <mesh file="femur_12_sym.stl"/>
    <mesh file="hipxy_sym.stl"/>
    <mesh file="tibias22_sym.stl"/>
    <mesh file="hat_small.stl"/>
    <mesh file="usb_2_bank_geometry.stl"/>
    <mesh file="pwr_connector.stl"/>
    <mesh file="0001755652_00mini_000_asm_1_asm_1_asm_00mini__20250103_a0001_asm_1_as_asm_1_1_30_gr_2202_asm_1_asm_1_1_30_gr_2202_asm_fl46blw10_48v_5n_m_de_2__fl46blw10_48v_5n_m_de.stl"/>
    <mesh file="usb_3_bank_geometry.stl"/>
    <mesh file="6706__300001_1_1_00mini_000_asm_1_asm_1_asm_00mini__20250103_a0001_asm_1_as_asm_1_1_30_gr_2202_asm_1_asm_1_1_30_gr_2202_asm_fl46blw10_48v_5n_m_de_2__fl46blw10_48v_5n_m_de.stl"/>
    <mesh file="rmdx43.stl"/>
    <mesh file="hdmi_micro.stl"/>
    <mesh file="chips__3.stl"/>
    <mesh file="bno055.stl"/>
    <mesh file="femur_12.stl"/>
    <mesh file="pcba_components_geometry__5.stl"/>
    <mesh file="chips__4.stl"/>
    <mesh file="tibias22.stl"/>
    <mesh file="femur_22.stl"/>
    <mesh file="poe_pins__2.stl"/>
    <mesh file="usb_c.stl"/>
    <mesh file="actuation_ankle.stl"/>
    <mesh file="1_1_06_eb903_537_af0_1.stl"/>
    <mesh file="part_11.stl"/>
    <mesh file="torso12.stl"/>
    <mesh file="chips__7.stl"/>
    <mesh file="hat_femur.stl"/>
    <mesh file="hat_big.stl"/>
    <mesh file="pmic.stl"/>
    <mesh file="usb2_port.stl"/>
    <mesh file="mounting_holes__2.stl"/>
    <mesh file="hipz22_sym.stl"/>
    <mesh file="1_1_06_eb463_507_fl46blw10_48v_5n_m_de_2__fl46blw10_48v_5n_m_de.stl"/>
    <mesh file="rp1.stl"/>
    <mesh file="knee_actuation.stl"/>
    <mesh file="mounting_holes__4.stl"/>
    <mesh file="pcba_components_geometry.stl"/>
    <mesh file="1_1_31_eb463_510_fl46blw10_48v_5n_m_de_2__fl46blw10_48v_5n_m_de.stl"/>
    <mesh file="1_1_31_qt_942_1.stl"/>
    <mesh file="poe_pins__4.stl"/>
    <mesh file="chips__11.stl"/>
    <mesh file="part_10.stl"/>
    <mesh file="switch.stl"/>
    <mesh file="chips__8.stl"/>
    <mesh file="ujoint.stl"/>
    <mesh file="27628_01_050_catpart.stl"/>
    <mesh file="torso22.stl"/>
    <mesh file="switch__2.stl"/>
    <mesh file="07534_05x40_catpart.stl"/>
    <mesh file="hipxy.stl"/>
    <mesh file="poe_pins.stl"/>
    <mesh file="ethernet__4.stl"/>
    <mesh file="uart.stl"/>
    <mesh file="07534_05x20_catpart.stl"/>
    <material name="torso22_material" rgba="1 0 0 1"/>
    <material name="bno055_material" rgba="0.301961 0.301961 0.301961 1"/>
    <material name="bearing_35_72_17_material" rgba="0.768627 0.886275 0.952941 1"/>
    <material name="robstrideo0_material" rgba="0.301961 0.301961 0.301961 1"/>
    <material name="imu_material" rgba="0.615686 0.811765 0.929412 1"/>
    <material name="part_11_material" rgba="0.231373 0.380392 0.705882 1"/>
    <material name="usbcan_material" rgba="0.615686 0.811765 0.929412 1"/>
    <material name="torso12_material" rgba="1 0 0 1"/>
    <material name="part_6_material" rgba="0.972549 0.529412 0.00392157 1"/>
    <material name="part_5_material" rgba="0.768627 0.886275 0.952941 1"/>
    <material name="part_10_material" rgba="0.231373 0.380392 0.705882 1"/>
    <material name="part_7_material" rgba="0.498039 0.498039 0.498039 1"/>
    <material name="xt_30_2x2_f_material" rgba="0.917647 0.917647 0.917647 1"/>
    <material name="mounting_holes_material" rgba="0.501961 0.501961 0 1"/>
    <material name="switch_material" rgba="0.545098 0.545098 0.545098 1"/>
    <material name="rp1_material" rgba="0.282353 0.282353 0.282353 1"/>
    <material name="hdmi_micro_material" rgba="0.156863 0.156863 0.156863 1"/>
    <material name="switch__2_material" rgba="0.282353 0.282353 0.282353 1"/>
    <material name="usb_c_material" rgba="0.545098 0.545098 0.545098 1"/>
    <material name="ethernet_material" rgba="0 1 0 1"/>
    <material name="pmic_material" rgba="0.282353 0.282353 0.282353 1"/>
    <material name="hdmi_micro__2_material" rgba="0.752941 0.752941 0.752941 1"/>
    <material name="mounting_holes__2_material" rgba="0.501961 0.501961 0 1"/>
    <material name="ethernet__2_material" rgba="1 0.501961 0 1"/>
    <material name="ir_material" rgba="0.282353 0.282353 0.282353 1"/>
    <material name="pcie_material" rgba="1 1 1 1"/>
    <material name="pwr_connector_material" rgba="1 1 1 1"/>
    <material name="pcie__2_material" rgba="0.501961 0.25098 0 1"/>
    <material name="pcb_material" rgba="0 0.501961 0.25098 1"/>
    <material name="uart_material" rgba="1 1 1 1"/>
    <material name="ethernet__3_material" rgba="0.686275 0.623529 0.560784 1"/>
    <material name="mounting_holes__3_material" rgba="0.501961 0.501961 0 1"/>
    <material name="ir__2_material" rgba="0.862745 0.862745 0.862745 1"/>
    <material name="mounting_holes__4_material" rgba="0.501961 0.501961 0 1"/>
    <material name="connector_material" rgba="1 1 1 1"/>
    <material name="ethernet__4_material" rgba="0.156863 0.156863 0.156863 1"/>
    <material name="pcba_components_geometry_material" rgba="0.862745 0.862745 0.862745 1"/>
    <material name="chips_material" rgba="0.282353 0.282353 0.282353 1"/>
    <material name="chips__2_material" rgba="0.862745 0.862745 0.862745 1"/>
    <material name="chips__3_material" rgba="0.282353 0.282353 0.282353 1"/>
    <material name="chips__4_material" rgba="0.862745 0.862745 0.862745 1"/>
    <material name="chips__5_material" rgba="0.282353 0.282353 0.282353 1"/>
    <material name="pcba_components_geometry__2_material" rgba="0.282353 0.282353 0.282353 1"/>
    <material name="pcba_components_geometry__3_material" rgba="0.282353 0.282353 0.282353 1"/>
    <material name="chips__6_material" rgba="0.282353 0.282353 0.282353 1"/>
    <material name="chips__7_material" rgba="0.862745 0.862745 0.862745 1"/>
    <material name="chips__8_material" rgba="0.862745 0.862745 0.862745 1"/>
    <material name="chips__9_material" rgba="0.282353 0.282353 0.282353 1"/>
    <material name="pcba_components_geometry__4_material" rgba="0.282353 0.282353 0.282353 1"/>
    <material name="chips__10_material" rgba="0.282353 0.282353 0.282353 1"/>
    <material name="chips__11_material" rgba="0.282353 0.282353 0.282353 1"/>
    <material name="pcba_components_geometry__5_material" rgba="0.282353 0.282353 0.282353 1"/>
    <material name="pcba_components_geometry__6_material" rgba="0.545098 0.545098 0.545098 1"/>
    <material name="pcba_components_geometry__7_material" rgba="0.282353 0.282353 0.282353 1"/>
    <material name="csi_dsi_connector_material" rgba="0.501961 0.25098 0 1"/>
    <material name="csi_dsi_connector__2_material" rgba="1 1 1 1"/>
    <material name="usb2_port_material" rgba="0.156863 0.156863 0.156863 1"/>
    <material name="usb2_port__2_material" rgba="0.752941 0.752941 0.752941 1"/>
    <material name="usb_2_bank_geometry_material" rgba="0.752941 0.752941 0.752941 1"/>
    <material name="poe_pins_material" rgba="0.501961 0.501961 0 1"/>
    <material name="poe_pins__2_material" rgba="0.501961 0.501961 0 1"/>
    <material name="poe_pins__3_material" rgba="0.501961 0.501961 0 1"/>
    <material name="poe_pins__4_material" rgba="0.501961 0.501961 0 1"/>
    <material name="poe_geometry_material" rgba="0.282353 0.282353 0.282353 1"/>
    <material name="usb3_port_material" rgba="0 0.501961 1 1"/>
    <material name="usb3_port__2_material" rgba="0.156863 0.156863 0.156863 1"/>
    <material name="usb_3_bank_geometry_material" rgba="0.752941 0.752941 0.752941 1"/>
    <material name="hipz12_material" rgba="1 0 0 1"/>
    <material name="robstride02_material" rgba="0.301961 0.301961 0.301961 1"/>
    <material name="hipz22_material" rgba="1 0 0 1"/>
    <material name="hipxy_material" rgba="1 0 0 1"/>
    <material name="knee_rod22_material" rgba="0.917647 0.917647 0.917647 1"/>
    <material name="bearing_15_21_4_material" rgba="0.647059 0.647059 0.647059 1"/>
    <material name="robstrideo3_material" rgba="0.301961 0.301961 0.301961 1"/>
    <material name="knee_rod12_material" rgba="0.917647 0.917647 0.917647 1"/>
    <material name="bearing_5_16_5_material" rgba="0.917647 0.917647 0.917647 1"/>
    <material name="knee_actuation_material" rgba="0.917647 0.917647 0.917647 1"/>
    <material name="femur_22_material" rgba="1 0 0 1"/>
    <material name="femur_12_material" rgba="1 0 0 1"/>
    <material name="hat_femur_material" rgba="1 0 0 1"/>
    <material name="part_3_material" rgba="1 0 0 1"/>
    <material name="1_1_31_qt_942_1_material" rgba="0.768627 0.886275 0.952941 1"/>
    <material name="1_1_06_eb903_538_1_material" rgba="0.498039 0.498039 0.498039 1"/>
    <material name="1_1_06_eb903_537_af0_1_material" rgba="0.768627 0.886275 0.952941 1"/>
    <material name="1_1_02_eb901_558_1_material" rgba="0.917647 0.917647 0.917647 1"/>
    <material name="rmdx43_material" rgba="0.301961 0.301961 0.301961 1"/>
    <material name="tibias22_material" rgba="1 0 0 1"/>
    <material name="27628_01_050_catpart_material" rgba="0.690196 0.690196 0.690196 1"/>
    <material name="hex_thin_nut_grade_a___b_m4x0_7__a8228d9ce5dcc05f24da0a2f74d882f3_material" rgba="0.603922 0.647059 0.686275 1"/>
    <material name="07534_05x40_catpart_material" rgba="0.690196 0.690196 0.690196 1"/>
    <material name="07534_05x20_catpart_material" rgba="0.690196 0.690196 0.690196 1"/>
    <material name="actuation_ankle_material" rgba="0.917647 0.917647 0.917647 1"/>
    <material name="hat_big_material" rgba="1 0 0 1"/>
    <material name="tibias12_material" rgba="1 0 0 1"/>
    <material name="1_1_31_eb463_510_fl46blw10_48v_5n_m_de_2__fl46blw10_48v_5n_m_de_material" rgba="1 1 1 1"/>
    <material name="1_1_02_eb461_502_fl46blw10_48v_5n_m_de_2__fl46blw10_48v_5n_m_de_material" rgba="1 1 1 1"/>
    <material name="1_1_06_eb463_509_fl46blw10_48v_5n_m_de_2__fl46blw10_48v_5n_m_de_material" rgba="1 1 1 1"/>
    <material name="1_1_06_eb463_507_fl46blw10_48v_5n_m_de_2__fl46blw10_48v_5n_m_de_material" rgba="1 1 1 1"/>
    <material name="0001755652_1_1_30_gr_2202_asm_1_asm_1_1_30_gr_2202_asm_fl46blw10_48v_5n_m_de_2__fl46blw10_48v_5n_m_de_material" rgba="1 1 1 1"/>
    <material name="0001755652_00mini_000_asm_1_asm_1_asm_00mini__20250103_a0001_asm_1_as_asm_1_1_30_gr_2202_asm_1_asm_1_1_30_gr_2202_asm_fl46blw10_48v_5n_m_de_2__fl46blw10_48v_5n_m_de_material" rgba="1 1 1 1"/>
    <material name="6706__300001_1_1_00mini_000_asm_1_asm_1_asm_00mini__20250103_a0001_asm_1_as_asm_1_1_30_gr_2202_asm_1_asm_1_1_30_gr_2202_asm_fl46blw10_48v_5n_m_de_2__fl46blw10_48v_5n_m_de_material" rgba="1 1 1 1"/>
    <material name="0001755650_00mini_000_asm_1_asm_1_asm_00mini__20250103_a0001_asm_1_as_asm_1_1_30_gr_2202_asm_1_asm_1_1_30_gr_2202_asm_fl46blw10_48v_5n_m_de_2__fl46blw10_48v_5n_m_de_material" rgba="1 1 1 1"/>
    <material name="ujoint_material" rgba="1 0 0 1"/>
    <material name="spacer_ujoint_material" rgba="0.917647 0.917647 0.917647 1"/>
    <material name="hat_small_material" rgba="1 0 0 1"/>
    <material name="foot_material" rgba="0.301961 0.301961 0.301961 1"/>
    <material name="hipz22_sym_material" rgba="1 0 0 1"/>
    <material name="hipz12_sym_material" rgba="1 0 0 1"/>
    <material name="hipxy_sym_material" rgba="1 0 0 1"/>
    <material name="knee_rod22_sym_material" rgba="0.917647 0.917647 0.917647 1"/>
    <material name="femur_12_sym_material" rgba="1 0 0 1"/>
    <material name="femur_22_sym_material" rgba="1 0 0 1"/>
    <material name="knee_rod12_sym_material" rgba="0.917647 0.917647 0.917647 1"/>
    <material name="tibias12_sym_material" rgba="1 0 0 1"/>
    <material name="tibias22_sym_material" rgba="1 0 0 1"/>
  </asset>
  <!-- <actuator>
    <position class="mjcf" name="hipz_right" joint="hipz_right" kp="30.0" forcerange="-88.0 88.0" inheritrange="1"/>
    <position class="mjcf" name="hipx_right" joint="hipx_right" kp="40.0" forcerange="-88.0 88.0" inheritrange="1"/>
    <position class="mjcf" name="hipy_right" joint="hipy_right" kp="60.0" forcerange="-88.0 88.0" inheritrange="1"/>
    <position class="mjcf" name="knee_right" joint="knee_right" kp="60.0" forcerange="-88.0 88.0" inheritrange="1"/>
    <position class="mjcf" name="ankley_right" joint="ankley_right" kp="20.0" forcerange="-44.0 44.0" inheritrange="1"/>
    <position class="mjcf" name="anklex_right" joint="anklex_right" kp="20.0" forcerange="-44.0 44.0" inheritrange="1"/>
    <position class="mjcf" name="hipz_left" joint="hipz_left" kp="30.0" forcerange="-88.0 88.0" inheritrange="1"/>
    <position class="mjcf" name="hipx_left" joint="hipx_left" kp="40.0" forcerange="-88.0 88.0" inheritrange="1"/>
    <position class="mjcf" name="hipy_left" joint="hipy_left" kp="60.0" forcerange="-88.0 88.0" inheritrange="1"/>
    <position class="mjcf" name="knee_left" joint="knee_left" kp="60.0" forcerange="-88.0 88.0" inheritrange="1"/>
    <position class="mjcf" name="ankley_left" joint="ankley_left" kp="20.0" forcerange="-44.0 44.0" inheritrange="1"/>
    <position class="mjcf" name="anklex_left" joint="anklex_left" kp="20.0" forcerange="-44.0 44.0" inheritrange="1"/>
  </actuator> -->
  <equality/>
</mujoco>
