<mujoco model="urdf">
  <compiler angle="radian"/>

  <asset>
    <mesh name="robstrideo0" file="assets/robstrideo0.stl"/>
    <mesh name="torso22" file="assets/torso22.stl"/>
    <mesh name="bearing_35_72_17" file="assets/bearing_35_72_17.stl"/>
    <mesh name="torso12" file="assets/torso12.stl"/>
    <mesh name="xt_30_2x2_f" file="assets/xt_30_2x2_f.stl"/>
    <mesh name="hipz12" file="assets/hipz12.stl"/>
    <mesh name="robstride02" file="assets/robstride02.stl"/>
    <mesh name="hipz22" file="assets/hipz22.stl"/>
    <mesh name="hipxy" file="assets/hipxy.stl"/>
    <mesh name="knee_rod22" file="assets/knee_rod22.stl"/>
    <mesh name="bearing_15_21_4" file="assets/bearing_15_21_4.stl"/>
    <mesh name="robstrideo3" file="assets/robstrideo3.stl"/>
    <mesh name="knee_rod12" file="assets/knee_rod12.stl"/>
    <mesh name="bearing_5_16_5" file="assets/bearing_5_16_5.stl"/>
    <mesh name="knee_actuation" file="assets/knee_actuation.stl"/>
    <mesh name="femur_22" file="assets/femur_22.stl"/>
    <mesh name="femur_12" file="assets/femur_12.stl"/>
    <mesh name="hat_femur" file="assets/hat_femur.stl"/>
    <mesh name="part_3" file="assets/part_3.stl"/>
    <mesh name="1_1_31_qt_942_1" file="assets/1_1_31_qt_942_1.stl"/>
    <mesh name="1_1_06_eb903_538_1" file="assets/1_1_06_eb903_538_1.stl"/>
    <mesh name="1_1_06_eb903_537_af0_1" file="assets/1_1_06_eb903_537_af0_1.stl"/>
    <mesh name="1_1_02_eb901_558_1" file="assets/1_1_02_eb901_558_1.stl"/>
    <mesh name="rmdx43" file="assets/rmdx43.stl"/>
    <mesh name="tibias22" file="assets/tibias22.stl"/>
    <mesh name="27628_01_050_catpart" file="assets/27628_01_050_catpart.stl"/>
    <mesh name="hex_thin_nut_grade_a___b_m4x0_7__a8228d9ce5dcc05f24da0a2f74d882f3" file="assets/hex_thin_nut_grade_a___b_m4x0_7__a8228d9ce5dcc05f24da0a2f74d882f3.stl"/>
    <mesh name="07534_05x40_catpart" file="assets/07534_05x40_catpart.stl"/>
    <mesh name="07534_05x20_catpart" file="assets/07534_05x20_catpart.stl"/>
    <mesh name="actuation_ankle" file="assets/actuation_ankle.stl"/>
    <mesh name="hat_big" file="assets/hat_big.stl"/>
    <mesh name="tibias12" file="assets/tibias12.stl"/>
    <mesh name="1_1_31_eb463_510_fl46blw10_48v_5n_m_de_2__fl46blw10_48v_5n_m_de" file="assets/1_1_31_eb463_510_fl46blw10_48v_5n_m_de_2__fl46blw10_48v_5n_m_de.stl"/>
    <mesh name="1_1_02_eb461_502_fl46blw10_48v_5n_m_de_2__fl46blw10_48v_5n_m_de" file="assets/1_1_02_eb461_502_fl46blw10_48v_5n_m_de_2__fl46blw10_48v_5n_m_de.stl"/>
    <mesh name="1_1_06_eb463_509_fl46blw10_48v_5n_m_de_2__fl46blw10_48v_5n_m_de" file="assets/1_1_06_eb463_509_fl46blw10_48v_5n_m_de_2__fl46blw10_48v_5n_m_de.stl"/>
    <mesh name="1_1_06_eb463_507_fl46blw10_48v_5n_m_de_2__fl46blw10_48v_5n_m_de" file="assets/1_1_06_eb463_507_fl46blw10_48v_5n_m_de_2__fl46blw10_48v_5n_m_de.stl"/>
    <mesh name="0001755652_1_1_30_gr_2202_asm_1_asm_1_1_30_gr_2202_asm_fl46blw10_48v_5n_m_de_2__fl46blw10_48v_5n_m_de" file="assets/0001755652_1_1_30_gr_2202_asm_1_asm_1_1_30_gr_2202_asm_fl46blw10_48v_5n_m_de_2__fl46blw10_48v_5n_m_de.stl"/>
    <mesh name="0001755652_00mini_000_asm_1_asm_1_asm_00mini__20250103_a0001_asm_1_as_asm_1_1_30_gr_2202_asm_1_asm_1_1_30_gr_2202_asm_fl46blw10_48v_5n_m_de_2__fl46blw10_48v_5n_m_de" file="assets/0001755652_00mini_000_asm_1_asm_1_asm_00mini__20250103_a0001_asm_1_as_asm_1_1_30_gr_2202_asm_1_asm_1_1_30_gr_2202_asm_fl46blw10_48v_5n_m_de_2__fl46blw10_48v_5n_m_de.stl"/>
    <mesh name="6706__300001_1_1_00mini_000_asm_1_asm_1_asm_00mini__20250103_a0001_asm_1_as_asm_1_1_30_gr_2202_asm_1_asm_1_1_30_gr_2202_asm_fl46blw10_48v_5n_m_de_2__fl46blw10_48v_5n_m_de" file="assets/6706__300001_1_1_00mini_000_asm_1_asm_1_asm_00mini__20250103_a0001_asm_1_as_asm_1_1_30_gr_2202_asm_1_asm_1_1_30_gr_2202_asm_fl46blw10_48v_5n_m_de_2__fl46blw10_48v_5n_m_de.stl"/>
    <mesh name="0001755650_00mini_000_asm_1_asm_1_asm_00mini__20250103_a0001_asm_1_as_asm_1_1_30_gr_2202_asm_1_asm_1_1_30_gr_2202_asm_fl46blw10_48v_5n_m_de_2__fl46blw10_48v_5n_m_de" file="assets/0001755650_00mini_000_asm_1_asm_1_asm_00mini__20250103_a0001_asm_1_as_asm_1_1_30_gr_2202_asm_1_asm_1_1_30_gr_2202_asm_fl46blw10_48v_5n_m_de_2__fl46blw10_48v_5n_m_de.stl"/>
    <mesh name="ujoint" file="assets/ujoint.stl"/>
    <mesh name="spacer_ujoint" file="assets/spacer_ujoint.stl"/>
    <mesh name="hat_small" file="assets/hat_small.stl"/>
    <mesh name="foot" file="assets/foot.stl"/>
    <mesh name="hipz22_sym" file="assets/hipz22_sym.stl"/>
    <mesh name="hipz12_sym" file="assets/hipz12_sym.stl"/>
    <mesh name="hipxy_sym" file="assets/hipxy_sym.stl"/>
    <mesh name="knee_rod22_sym" file="assets/knee_rod22_sym.stl"/>
    <mesh name="femur_12_sym" file="assets/femur_12_sym.stl"/>
    <mesh name="femur_22_sym" file="assets/femur_22_sym.stl"/>
    <mesh name="knee_rod12_sym" file="assets/knee_rod12_sym.stl"/>
    <mesh name="tibias12_sym" file="assets/tibias12_sym.stl"/>
    <mesh name="tibias22_sym" file="assets/tibias22_sym.stl"/>
    <mesh name="torso_mesh" file="assets/torso_mesh.stl"/>
  </asset>

  <worldbody>
    <geom pos="-0.673363 0.0109625 0.061034" quat="0.707105 0.707108 0 0" type="mesh" rgba="0.301961 0.301961 0.301961 1" mesh="robstrideo0"/>
    <geom pos="-0.000263039 0.233572 -0.0901625" quat="1.86697e-07 -1.31359e-06 0.99005 -0.140713" type="mesh" rgba="1 0 0 1" mesh="torso22"/>
    <geom pos="-0.000887454 -0.130401 0.0222352" quat="0.00131867 -0.00114353 -0.655473 -0.755216" type="mesh" rgba="0.768627 0.886275 0.952941 1" mesh="bearing_35_72_17"/>
    <geom pos="0.672086 -0.147255 0.0629195" quat="0.00131867 -0.00114353 -0.655473 -0.755216" type="mesh" rgba="0.301961 0.301961 0.301961 1" mesh="robstrideo0"/>
    <geom pos="0.672086 0.12555 0.0660044" quat="-0.00114353 0.00131866 0.755219 0.65547" type="mesh" rgba="0.301961 0.301961 0.301961 1" mesh="robstrideo0"/>
    <geom pos="-0.000263039 4.05842e-07 -0.056966" quat="1.75787e-12 1.32679e-06 1 1.32679e-06" type="mesh" rgba="1 0 0 1" mesh="torso12"/>
    <geom pos="-0.000263039 4.05842e-07 -0.056966" quat="1.75793e-12 1.32679e-06 1 1.32679e-06" type="mesh" rgba="1 0 0 1" mesh="torso22"/>
    <geom pos="-0.000887454 0.130402 0.0222352" quat="-0.00114353 0.00131866 0.755219 0.65547" type="mesh" rgba="0.768627 0.886275 0.952941 1" mesh="bearing_35_72_17"/>
    <geom pos="-3.97731e-05 -0.105809 0.0903709" quat="0.464295 0.534954 -0.533087 0.46268" type="mesh" rgba="0.917647 0.917647 0.917647 1" mesh="xt_30_2x2_f"/>
    <geom pos="0.025 0.503548 0.0499987" quat="-1 2.65359e-06 0 0" type="mesh" rgba="0.301961 0.301961 0.301961 1" mesh="torso_mesh"/>
    <body name="hipx_subassembly" pos="-0.000819037 -0.133159 0.04164" quat="0.821909 0.0571232 0.0414079 -0.565233">
      <inertial pos="-0.0179437 -0.0274254 -0.0837243" quat="0.401109 0.424615 -0.783452 0.212171" mass="0.794013" diaginertia="0.00115064 0.000967835 0.000726741"/>
      <joint name="hipz_right" pos="0 0 0" axis="0 0 1" range="-3.14159 3.14159" actuatorfrcrange="-10 10"/>
      <geom pos="-0.0280156 -0.000591536 -0.0506633" quat="-0.372266 -0.524563 0.593706 -0.483492" type="mesh" rgba="0.917647 0.917647 0.917647 1" mesh="xt_30_2x2_f"/>
      <geom pos="0 0 -0.1" quat="1.32679e-06 -1 0 0" type="mesh" rgba="1 0 0 1" mesh="hipz12"/>
      <geom pos="-0.575896 0.0494047 -0.172196" quat="0.792907 -0.60316 -0.052417 -0.0689069" type="mesh" rgba="0.301961 0.301961 0.301961 1" mesh="robstride02"/>
      <geom pos="-0.01759 -0.0267968 -0.104484" quat="0.603161 0.792907 -0.068907 0.0524169" type="mesh" rgba="0.768627 0.886275 0.952941 1" mesh="bearing_35_72_17"/>
      <geom pos="0 0 -0.1" quat="1.32679e-06 -1 0 0" type="mesh" rgba="1 0 0 1" mesh="hipz22"/>
      <body name="hipy_subassembly" pos="-0.01897 -0.0289 -0.09689" quat="0.388857 0.132751 0.0879726 -0.907429">
        <inertial pos="0.00476547 -0.00266343 -0.0607297" quat="0.916918 -0.328471 -0.0265972 0.225082" mass="0.241618" diaginertia="0.000514846 0.000474201 0.00039973"/>
        <joint name="hipx_right" pos="0 0 0" axis="0 0 1" range="-3.14159 3.14159" actuatorfrcrange="-10 10"/>
        <geom type="mesh" rgba="1 0 0 1" mesh="hipxy"/>
        <body name="tigh_subassembly" pos="0.012638 -0.0276823 -0.112055" quat="0.289458 0.00726303 0.73048 -0.618515">
          <inertial pos="0.0501976 0.0785779 -0.0353813" quat="0.64331 0.334215 -0.585819 0.362311" mass="2.5804" diaginertia="0.0237789 0.0223377 0.0035913"/>
          <joint name="hipy_right" pos="0 0 0" axis="0 0 1" range="-3.14159 3.14159" actuatorfrcrange="-10 10"/>
          <geom pos="0.210506 0.184547 -0.0305" quat="0.612371 0.612373 -0.353555 -0.353553" type="mesh" rgba="0.917647 0.917647 0.917647 1" mesh="knee_rod22"/>
          <geom pos="0.117923 0.320381 -0.0185" quat="0.612371 -0.612373 0.353555 -0.353553" type="mesh" rgba="0.647059 0.647059 0.647059 1" mesh="bearing_15_21_4"/>
          <geom pos="0.0130854 0.122429 -0.0245" quat="0.707105 -0.707108 0 0" type="mesh" rgba="0.647059 0.647059 0.647059 1" mesh="bearing_15_21_4"/>
          <geom pos="-0.437806 0.570998 -0.07" quat="0.683011 -0.683014 0.183013 -0.183012" type="mesh" rgba="0.301961 0.301961 0.301961 1" mesh="robstrideo3"/>
          <geom pos="0 0 -0.0635" quat="0.683011 0.683014 -0.183013 -0.183012" type="mesh" rgba="0.647059 0.647059 0.647059 1" mesh="bearing_15_21_4"/>
          <geom pos="0.0130854 0.122429 -0.0365" quat="0.707105 0.707108 0 0" type="mesh" rgba="0.647059 0.647059 0.647059 1" mesh="bearing_15_21_4"/>
          <geom pos="0.117923 0.320381 -0.0425" quat="0.612371 0.612373 -0.353555 -0.353553" type="mesh" rgba="0.647059 0.647059 0.647059 1" mesh="bearing_15_21_4"/>
          <geom pos="0.210506 0.184547 -0.0305" quat="0.612371 0.612373 -0.353555 -0.353553" type="mesh" rgba="0.917647 0.917647 0.917647 1" mesh="knee_rod12"/>
          <geom pos="0.17 0.294449 -0.05" quat="0.683011 -0.683014 0.183013 -0.183012" type="mesh" rgba="0.917647 0.917647 0.917647 1" mesh="bearing_5_16_5"/>
          <geom pos="0.058 0.324459 -0.0305" quat="0.707105 0.707108 0 0" type="mesh" rgba="0.917647 0.917647 0.917647 1" mesh="knee_actuation"/>
          <geom pos="0.17 0.294449 -0.01425" quat="0.683011 -0.683014 0.183013 -0.183012" type="mesh" rgba="0.917647 0.917647 0.917647 1" mesh="bearing_5_16_5"/>
          <geom pos="0.17 0.294449 -0.0305" quat="0.683011 0.683014 -0.183013 -0.183012" type="mesh" rgba="1 0 0 1" mesh="femur_22"/>
          <geom pos="0.17 0.294449 -0.0305" quat="0.683011 0.683014 -0.183013 -0.183012" type="mesh" rgba="1 0 0 1" mesh="femur_12"/>
          <geom pos="0.17 0.294449 -0.0305" quat="0.683011 0.683014 -0.183013 -0.183012" type="mesh" rgba="1 0 0 1" mesh="hat_femur"/>
          <geom pos="0 0 -0.0938" quat="0.183014 -0.683011 0.183014 0.683014" type="mesh" rgba="1 0 0 1" mesh="part_3"/>
          <geom pos="-0.495806 0.470539 -0.0275" quat="0.683011 -0.683014 0.183013 -0.183012" type="mesh" rgba="0.301961 0.301961 0.301961 1" mesh="robstrideo3"/>
          <geom pos="0 0 -0.04" quat="0.499998 0 0 -0.866027" type="mesh" rgba="0.768627 0.886275 0.952941 1" mesh="1_1_31_qt_942_1"/>
          <geom pos="0 0 -0.0566" quat="0.499998 0 0 -0.866027" type="mesh" rgba="0.498039 0.498039 0.498039 1" mesh="1_1_06_eb903_538_1"/>
          <geom pos="0.058 0.100459 -0.0825" quat="0.258821 0 0 0.965925" type="mesh" rgba="0.768627 0.886275 0.952941 1" mesh="1_1_31_qt_942_1"/>
          <geom pos="0.058 0.100459 -0.0991" quat="0.258821 0 0 0.965925" type="mesh" rgba="0.498039 0.498039 0.498039 1" mesh="1_1_06_eb903_538_1"/>
          <geom pos="0 0 -0.0375" quat="0.965926 0 0 -0.258819" type="mesh" rgba="0.768627 0.886275 0.952941 1" mesh="1_1_06_eb903_537_af0_1"/>
          <geom quat="1.32679e-06 1 0 0" type="mesh" rgba="0.917647 0.917647 0.917647 1" mesh="1_1_02_eb901_558_1"/>
          <geom pos="0.058 0.100459 -0.08" quat="0.499998 0 0 -0.866027" type="mesh" rgba="0.768627 0.886275 0.952941 1" mesh="1_1_06_eb903_537_af0_1"/>
          <geom pos="0.058 0.100459 -0.0425" quat="9.38184e-07 -0.707105 0.707108 -9.38187e-07" type="mesh" rgba="0.917647 0.917647 0.917647 1" mesh="1_1_02_eb901_558_1"/>
          <body name="shin_subassembly" pos="0.17 0.294449 -0.0305" quat="1.27794e-06 0.963177 -0.26887 -3.56735e-07">
            <inertial pos="-0.076547 -0.0486454 6.35117e-05" quat="-0.212792 0.669636 0.143815 0.696868" mass="0.593267" diaginertia="0.00177092 0.00174055 0.000241288"/>
            <joint name="knee_right" pos="0 0 0" axis="0 0 1" range="-3.14159 3.14159" actuatorfrcrange="-10 10"/>
            <geom pos="-0.2967 0.369726 0.019" quat="0.616798 0.6168 -0.345774 -0.345773" type="mesh" rgba="0.301961 0.301961 0.301961 1" mesh="rmdx43"/>
            <geom pos="-0.0609783 -0.00254913 -0.0142" quat="0.34577 0.616799 -0.345772 0.616801" type="mesh" rgba="0.917647 0.917647 0.917647 1" mesh="xt_30_2x2_f"/>
            <geom pos="-0.221803 -0.135659 0.019" quat="0.616798 -0.6168 0.345774 -0.345773" type="mesh" rgba="1 0 0 1" mesh="tibias22"/>
            <geom pos="0.00455194 -0.0324886 0.02" quat="0.658546 -0.658549 0.257517 -0.257517" type="mesh" rgba="0.690196 0.690196 0.690196 1" mesh="27628_01_050_catpart"/>
            <geom pos="0 0 0.0247602" type="mesh" rgba="0.603922 0.647059 0.686275 1" mesh="hex_thin_nut_grade_a___b_m4x0_7__a8228d9ce5dcc05f24da0a2f74d882f3"/>
            <geom pos="0 0 -0.025" quat="0.499998 -0.5 -0.5 -0.500002" type="mesh" rgba="0.690196 0.690196 0.690196 1" mesh="07534_05x40_catpart"/>
            <geom pos="-0.0406618 -0.0601422 -0.0112398" quat="1.32524e-06 -0.998828 0.0484075 -6.42269e-08" type="mesh" rgba="0.603922 0.647059 0.686275 1" mesh="hex_thin_nut_grade_a___b_m4x0_7__a8228d9ce5dcc05f24da0a2f74d882f3"/>
            <geom pos="-0.0406618 -0.0601422 -0.041" quat="0.0342291 0.706277 -0.0342293 0.706279" type="mesh" rgba="0.690196 0.690196 0.690196 1" mesh="07534_05x20_catpart"/>
            <geom pos="-0.0303217 0.125625 -0.019" quat="0.706277 0.706279 -0.0342294 -0.0342292" type="mesh" rgba="0.917647 0.917647 0.917647 1" mesh="actuation_ankle"/>
            <geom pos="-0.341913 0.342073 0.006" quat="0.616798 0.6168 -0.345774 -0.345773" type="mesh" rgba="0.301961 0.301961 0.301961 1" mesh="rmdx43"/>
            <geom pos="-0.221803 -0.135659 0.019" quat="0.616798 -0.6168 0.345774 -0.345773" type="mesh" rgba="1 0 0 1" mesh="hat_big"/>
            <geom pos="0.00455195 -0.0324886 0.041" quat="0.0342291 -0.706277 0.0342293 0.706279" type="mesh" rgba="0.690196 0.690196 0.690196 1" mesh="07534_05x20_catpart"/>
            <geom pos="0.00455195 -0.0324886 0.0134397" quat="0.998828 0 0 -0.0484075" type="mesh" rgba="0.603922 0.647059 0.686275 1" mesh="hex_thin_nut_grade_a___b_m4x0_7__a8228d9ce5dcc05f24da0a2f74d882f3"/>
            <geom pos="-0.221803 -0.135659 0.019" quat="0.616798 -0.6168 0.345774 -0.345773" type="mesh" rgba="1 0 0 1" mesh="tibias12"/>
            <geom pos="-0.105595 -0.0298375 0.0145" quat="0.616798 0.345773 0.6168 -0.345774" type="mesh" rgba="0.917647 0.917647 0.917647 1" mesh="xt_30_2x2_f"/>
            <geom pos="-0.105319 -0.208585 0.019" quat="0.706277 -0.706279 0.0342294 -0.0342292" type="mesh" rgba="0.917647 0.917647 0.917647 1" mesh="actuation_ankle"/>
            <geom pos="-0.0406619 -0.060142 -0.023" quat="0.642925 -0.642928 -0.294356 0.294355" type="mesh" rgba="0.690196 0.690196 0.690196 1" mesh="27628_01_050_catpart"/>
            <geom pos="-0.0904274 -0.0553071 -0.0195" quat="1.00853e-06 -0.760126 0.649776 -8.6212e-07" type="mesh" rgba="1 1 1 1" mesh="1_1_31_eb463_510_fl46blw10_48v_5n_m_de_2__fl46blw10_48v_5n_m_de"/>
            <geom pos="-0.0904274 -0.0553071 -0.0095" quat="1.00853e-06 -0.760126 0.649776 -8.6212e-07" type="mesh" rgba="1 1 1 1" mesh="1_1_02_eb461_502_fl46blw10_48v_5n_m_de_2__fl46blw10_48v_5n_m_de"/>
            <geom pos="-0.0904274 -0.0553071 0.022" quat="1.31753e-06 0.993018 -0.117964 -1.56514e-07" type="mesh" rgba="1 1 1 1" mesh="1_1_06_eb463_509_fl46blw10_48v_5n_m_de_2__fl46blw10_48v_5n_m_de"/>
            <geom pos="-0.0904274 -0.0553071 0.0085" quat="1.15734e-06 0.872285 -0.488997 -6.48799e-07" type="mesh" rgba="1 1 1 1" mesh="1_1_06_eb463_507_fl46blw10_48v_5n_m_de_2__fl46blw10_48v_5n_m_de"/>
            <geom pos="-0.0452137 -0.0276536 0.0195" quat="0.950924 0 0 -0.309426" type="mesh" rgba="1 1 1 1" mesh="1_1_31_eb463_510_fl46blw10_48v_5n_m_de_2__fl46blw10_48v_5n_m_de"/>
            <geom pos="-0.0452137 -0.0276536 0.0095" quat="0.950924 0 0 -0.309426" type="mesh" rgba="1 1 1 1" mesh="1_1_02_eb461_502_fl46blw10_48v_5n_m_de_2__fl46blw10_48v_5n_m_de"/>
            <geom pos="-0.0452137 -0.0276536 -0.022" quat="0.618755 0 0 -0.785584" type="mesh" rgba="1 1 1 1" mesh="1_1_06_eb463_509_fl46blw10_48v_5n_m_de_2__fl46blw10_48v_5n_m_de"/>
            <geom pos="-0.0452137 -0.0276536 -0.0085" quat="0.872285 0 0 -0.488997" type="mesh" rgba="1 1 1 1" mesh="1_1_06_eb463_507_fl46blw10_48v_5n_m_de_2__fl46blw10_48v_5n_m_de"/>
            <geom pos="-0.0823231 -0.0503503 -0.024" quat="0.488994 0 0 0.872287" type="mesh" rgba="1 1 1 1" mesh="0001755652_1_1_30_gr_2202_asm_1_asm_1_1_30_gr_2202_asm_fl46blw10_48v_5n_m_de_2__fl46blw10_48v_5n_m_de"/>
            <geom pos="-0.0987723 -0.0507669 -0.024" quat="0.488994 0 0 0.872287" type="mesh" rgba="1 1 1 1" mesh="0001755652_1_1_30_gr_2202_asm_1_asm_1_1_30_gr_2202_asm_fl46blw10_48v_5n_m_de_2__fl46blw10_48v_5n_m_de"/>
            <geom pos="-0.0533181 -0.0326103 0.024" quat="6.48795e-07 -0.488994 -0.872287 1.15735e-06" type="mesh" rgba="1 1 1 1" mesh="0001755652_1_1_30_gr_2202_asm_1_asm_1_1_30_gr_2202_asm_fl46blw10_48v_5n_m_de_2__fl46blw10_48v_5n_m_de"/>
            <geom pos="-0.0454542 -0.0181566 0.024" quat="6.48795e-07 -0.488994 -0.872287 1.15735e-06" type="mesh" rgba="1 1 1 1" mesh="0001755652_1_1_30_gr_2202_asm_1_asm_1_1_30_gr_2202_asm_fl46blw10_48v_5n_m_de_2__fl46blw10_48v_5n_m_de"/>
            <geom pos="-0.0901869 -0.0648041 -0.024" quat="0.488994 0 0 0.872287" type="mesh" rgba="1 1 1 1" mesh="0001755652_00mini_000_asm_1_asm_1_asm_00mini__20250103_a0001_asm_1_as_asm_1_1_30_gr_2202_asm_1_asm_1_1_30_gr_2202_asm_fl46blw10_48v_5n_m_de_2__fl46blw10_48v_5n_m_de"/>
            <geom pos="-0.0904274 -0.0553071 -0.0205" quat="0.488994 0 0 0.872287" type="mesh" rgba="1 1 1 1" mesh="6706__300001_1_1_00mini_000_asm_1_asm_1_asm_00mini__20250103_a0001_asm_1_as_asm_1_1_30_gr_2202_asm_1_asm_1_1_30_gr_2202_asm_fl46blw10_48v_5n_m_de_2__fl46blw10_48v_5n_m_de"/>
            <geom pos="-0.0904274 -0.0553071 -0.0209" quat="0.488994 0 0 0.872287" type="mesh" rgba="1 1 1 1" mesh="0001755650_00mini_000_asm_1_asm_1_asm_00mini__20250103_a0001_asm_1_as_asm_1_1_30_gr_2202_asm_1_asm_1_1_30_gr_2202_asm_fl46blw10_48v_5n_m_de_2__fl46blw10_48v_5n_m_de"/>
            <geom pos="-0.0368689 -0.0321937 0.024" quat="6.48795e-07 -0.488994 -0.872287 1.15735e-06" type="mesh" rgba="1 1 1 1" mesh="0001755652_00mini_000_asm_1_asm_1_asm_00mini__20250103_a0001_asm_1_as_asm_1_1_30_gr_2202_asm_1_asm_1_1_30_gr_2202_asm_fl46blw10_48v_5n_m_de_2__fl46blw10_48v_5n_m_de"/>
            <geom pos="-0.0452137 -0.0276536 0.0205" quat="6.48795e-07 -0.488994 -0.872287 1.15735e-06" type="mesh" rgba="1 1 1 1" mesh="6706__300001_1_1_00mini_000_asm_1_asm_1_asm_00mini__20250103_a0001_asm_1_as_asm_1_1_30_gr_2202_asm_1_asm_1_1_30_gr_2202_asm_fl46blw10_48v_5n_m_de_2__fl46blw10_48v_5n_m_de"/>
            <geom pos="-0.0452137 -0.0276536 0.0209" quat="6.48795e-07 -0.488994 -0.872287 1.15735e-06" type="mesh" rgba="1 1 1 1" mesh="0001755650_00mini_000_asm_1_asm_1_asm_00mini__20250103_a0001_asm_1_as_asm_1_1_30_gr_2202_asm_1_asm_1_1_30_gr_2202_asm_fl46blw10_48v_5n_m_de_2__fl46blw10_48v_5n_m_de"/>
            <body name="ankle_subassembly" pos="-0.221803 -0.135659 0.02" quat="1.10817e-06 -0.835222 -0.549913 7.29622e-07">
              <inertial pos="-1.62086e-08 -0.000727483 0.02" mass="0.0168168" diaginertia="5.19458e-06 4.86353e-06 8.35665e-07"/>
              <joint name="ankley_right" pos="0 0 0" axis="0 0 1" range="-3.14159 3.14159" actuatorfrcrange="-10 10"/>
              <geom pos="0 0.0249999 0.02" quat="9.38184e-07 -0.707105 0.707108 -9.38187e-07" type="mesh" rgba="0.690196 0.690196 0.690196 1" mesh="07534_05x40_catpart"/>
              <geom pos="0 0 0.02" quat="9.38184e-07 0.707105 9.38187e-07 -0.707108" type="mesh" rgba="1 0 0 1" mesh="ujoint"/>
              <geom pos="0 0 0.02" quat="0.71462 0 -0.699512 0" type="mesh" rgba="0.917647 0.917647 0.917647 1" mesh="spacer_ujoint"/>
              <geom pos="0 -0.02204 0.02" quat="0.505312 -0.505314 -0.494629 -0.494631" type="mesh" rgba="0.603922 0.647059 0.686275 1" mesh="hex_thin_nut_grade_a___b_m4x0_7__a8228d9ce5dcc05f24da0a2f74d882f3"/>
              <geom pos="0 0 0.0195" quat="9.38184e-07 0.707105 9.38187e-07 -0.707108" type="mesh" rgba="1 0 0 1" mesh="part_3"/>
              <geom pos="0 -0.01594 0.02" quat="0.71462 0 -0.699512 0" type="mesh" rgba="0.917647 0.917647 0.917647 1" mesh="bearing_5_16_5"/>
              <geom quat="0.707105 0.707108 0 0" type="mesh" rgba="0.647059 0.647059 0.647059 1" mesh="bearing_15_21_4"/>
              <geom pos="0 0 0.0205" quat="9.38184e-07 -0.707105 -9.38187e-07 -0.707108" type="mesh" rgba="1 0 0 1" mesh="part_3"/>
              <geom pos="0 0.0209456 0.02" quat="-0.00732918 -1.33648e-06 -0.999973 1.33648e-06" type="mesh" rgba="0.917647 0.917647 0.917647 1" mesh="bearing_5_16_5"/>
              <geom pos="0 5.64895e-06 0.02" quat="9.45034e-07 0.71227 9.31284e-07 -0.701906" type="mesh" rgba="0.917647 0.917647 0.917647 1" mesh="spacer_ujoint"/>
              <geom pos="0 0 0.04" quat="9.38184e-07 -9.38187e-07 -0.707108 0.707105" type="mesh" rgba="0.647059 0.647059 0.647059 1" mesh="bearing_15_21_4"/>
              <body name="foot_subassembly" pos="0 -0.01594 0.02" quat="0.499998 0.5 0.5 -0.500002">
                <inertial pos="8.52312e-09 -0.0138418 -0.052232" quat="0.705627 0.0421767 -0.042203 0.706067" mass="0.122498" diaginertia="0.000163602 0.000163413 6.9433e-05"/>
                <joint name="anklex_right" pos="0 0 0" axis="0 0 1" range="-3.14159 3.14159" actuatorfrcrange="-10 10"/>
                <geom pos="0.021 3.53792e-08 -0.0660002" quat="9.38184e-07 -0.707105 -0.707108 9.38187e-07" type="mesh" rgba="0.690196 0.690196 0.690196 1" mesh="27628_01_050_catpart"/>
                <geom pos="0.036 0 -0.066" quat="1.76043e-12 -1.32679e-06 -1 1.32679e-06" type="mesh" rgba="0.690196 0.690196 0.690196 1" mesh="07534_05x20_catpart"/>
                <geom pos="-0.021 -1.89504e-08 -0.066" quat="9.38184e-07 0.707105 0.707108 9.38187e-07" type="mesh" rgba="0.690196 0.690196 0.690196 1" mesh="27628_01_050_catpart"/>
                <geom pos="-0.036 0 -0.066" quat="1 0 0 0" type="mesh" rgba="0.690196 0.690196 0.690196 1" mesh="07534_05x20_catpart"/>
                <geom pos="0 -0.035 -0.0385" quat="0.499998 -0.5 -0.5 -0.500002" type="mesh" rgba="1 0 0 1" mesh="hat_small"/>
                <geom pos="0 -0.035 -0.0385" quat="0.499998 -0.5 -0.5 -0.500002" type="mesh" rgba="0.301961 0.301961 0.301961 1" mesh="foot"/>
              </body>
            </body>
          </body>
        </body>
      </body>
    </body>
    <body name="hipx_subassemby_sym" pos="-0.000819037 0.13316 0.04164" quat="0.826606 -0.0574674 0.0409289 0.558341">
      <inertial pos="-0.0179432 0.0274245 -0.0837272" quat="0.424685 0.401162 -0.212175 0.783386" mass="0.794016" diaginertia="0.0011506 0.000967878 0.000726822"/>
      <joint name="hipz_left" pos="0 0 0" axis="0 0 1" range="-3.14159 3.14159" actuatorfrcrange="-10 10"/>
      <geom pos="-0.575896 0.057308 -0.20175" quat="0.603161 -0.792907 -0.068907 -0.0524169" type="mesh" rgba="0.301961 0.301961 0.301961 1" mesh="robstride02"/>
      <geom pos="0 0 0.1" quat="1 0 0 0" type="mesh" rgba="1 0 0 1" mesh="hipz22_sym"/>
      <geom pos="0 0 0.1" quat="1 0 0 0" type="mesh" rgba="1 0 0 1" mesh="hipz12_sym"/>
      <geom pos="-0.0280156 0.0769561 -0.0718124" quat="0.498768 0.406176 -0.443127 0.624411" type="mesh" rgba="0.917647 0.917647 0.917647 1" mesh="xt_30_2x2_f"/>
      <geom pos="-0.01759 0.0267968 -0.104484" quat="0.792907 0.60316 -0.052417 0.0689069" type="mesh" rgba="0.768627 0.886275 0.952941 1" mesh="bearing_35_72_17"/>
      <body name="hipy_subassembly_sym" pos="-0.01897 0.0289 -0.09689" quat="0.378585 -0.131748 0.0894673 0.911763">
        <inertial pos="0.0047654 0.00266393 -0.0607296" quat="0.916914 0.328483 -0.0266015 -0.225077" mass="0.241619" diaginertia="0.000514848 0.000474202 0.000399736"/>
        <joint name="hipx_left" pos="0 0 0" axis="0 0 1" range="-3.14159 3.14159" actuatorfrcrange="-10 10"/>
        <geom quat="1.32679e-06 1 0 0" type="mesh" rgba="1 0 0 1" mesh="hipxy_sym"/>
        <body name="tigh_subassembly_sym" pos="0.012638 0.0276823 -0.112055" quat="-0.0583156 0.358704 0.636384 0.680402">
          <inertial pos="-0.0431321 -0.0830741 -0.0353867" quat="0.584181 0.376186 -0.634805 0.337993" mass="2.5804" diaginertia="0.0240047 0.0225643 0.00359599"/>
          <joint name="hipy_left" pos="0 0 0" axis="0 0 1" range="-3.14159 3.14159" actuatorfrcrange="-10 10"/>
          <geom pos="-0.058 -0.280519 0.0295" quat="0.707105 -0.707108 0 0" type="mesh" rgba="0.917647 0.917647 0.917647 1" mesh="knee_rod22_sym"/>
          <geom pos="-0.221927 -0.268257 -0.0185" quat="0.499998 -0.5 -0.500002 0.5" type="mesh" rgba="0.647059 0.647059 0.647059 1" mesh="bearing_15_21_4"/>
          <geom pos="0 0 -0.0938" quat="0.683011 0.183012 0.683014 -0.183013" type="mesh" rgba="1 0 0 1" mesh="part_3"/>
          <geom pos="-0.102915 -0.0784891 -0.0245" quat="0.707105 -0.707108 0 0" type="mesh" rgba="0.647059 0.647059 0.647059 1" mesh="bearing_15_21_4"/>
          <geom pos="0 0 -0.0675" quat="0.183014 -0.183014 -0.683014 0.683011" type="mesh" rgba="0.647059 0.647059 0.647059 1" mesh="bearing_15_21_4"/>
          <geom pos="-0.102915 -0.0784891 -0.0365" quat="0.707105 0.707108 0 0" type="mesh" rgba="0.647059 0.647059 0.647059 1" mesh="bearing_15_21_4"/>
          <geom pos="-0.221927 -0.268257 -0.0465" quat="0.499998 -0.5 -0.500002 0.5" type="mesh" rgba="0.647059 0.647059 0.647059 1" mesh="bearing_15_21_4"/>
          <geom pos="-0.17 -0.294449 0.0295" quat="0.683011 -0.683014 0.183013 -0.183012" type="mesh" rgba="1 0 0 1" mesh="femur_12_sym"/>
          <geom pos="-0.17 -0.294449 -0.045" quat="0.183014 0.183014 0.683014 0.683011" type="mesh" rgba="0.917647 0.917647 0.917647 1" mesh="bearing_5_16_5"/>
          <geom pos="-0.058 0.123541 -0.0305" quat="0.707105 0.707108 0 0" type="mesh" rgba="0.917647 0.917647 0.917647 1" mesh="knee_actuation"/>
          <geom pos="-0.17 -0.294449 0.0295" quat="0.683011 -0.683014 0.183013 -0.183012" type="mesh" rgba="1 0 0 1" mesh="femur_22_sym"/>
          <geom pos="-0.17 -0.294449 -0.0305" quat="0.183014 0.183014 0.683014 0.683011" type="mesh" rgba="1 0 0 1" mesh="hat_femur"/>
          <geom pos="-0.17 -0.294449 -0.013" quat="0.183014 -0.183014 -0.683014 0.683011" type="mesh" rgba="0.917647 0.917647 0.917647 1" mesh="bearing_5_16_5"/>
          <geom pos="0.655402 -0.194111 -0.0025" quat="0.183014 0.183014 0.683014 0.683011" type="mesh" rgba="0.301961 0.301961 0.301961 1" mesh="robstrideo3"/>
          <geom pos="-0.058 -0.280519 0.0295" quat="0.707105 -0.707108 0 0" type="mesh" rgba="0.917647 0.917647 0.917647 1" mesh="knee_rod12_sym"/>
          <geom pos="0.597402 -0.29457 -0.045" quat="0.183014 0.183014 0.683014 0.683011" type="mesh" rgba="0.301961 0.301961 0.301961 1" mesh="robstrideo3"/>
          <geom pos="0 0 -0.04" quat="0.499998 0 0 -0.866027" type="mesh" rgba="0.768627 0.886275 0.952941 1" mesh="1_1_31_qt_942_1"/>
          <geom pos="0 0 -0.0566" quat="0.499998 0 0 -0.866027" type="mesh" rgba="0.498039 0.498039 0.498039 1" mesh="1_1_06_eb903_538_1"/>
          <geom pos="-0.058 -0.100459 -0.0825" quat="0.965926 0 0 -0.258819" type="mesh" rgba="0.768627 0.886275 0.952941 1" mesh="1_1_31_qt_942_1"/>
          <geom pos="-0.058 -0.100459 -0.0991" quat="0.965926 0 0 -0.258819" type="mesh" rgba="0.498039 0.498039 0.498039 1" mesh="1_1_06_eb903_538_1"/>
          <geom pos="0 0 -0.0375" quat="0.965926 0 0 -0.258819" type="mesh" rgba="0.768627 0.886275 0.952941 1" mesh="1_1_06_eb903_537_af0_1"/>
          <geom quat="1.32679e-06 -1 0 0" type="mesh" rgba="0.917647 0.917647 0.917647 1" mesh="1_1_02_eb901_558_1"/>
          <geom pos="-0.058 -0.100459 -0.08" quat="0.866025 0 0 0.500001" type="mesh" rgba="0.768627 0.886275 0.952941 1" mesh="1_1_06_eb903_537_af0_1"/>
          <geom pos="-0.058 -0.100459 -0.0425" quat="9.38184e-07 -0.707105 -0.707108 9.38187e-07" type="mesh" rgba="0.917647 0.917647 0.917647 1" mesh="1_1_02_eb901_558_1"/>
          <body name="shin_subassembly_sym" pos="-0.17 -0.294449 -0.0305" quat="0.723236 0 0 -0.690601">
            <inertial pos="0.00133174 -0.0908013 -1.51262e-05" quat="0.516321 0.466893 -0.500826 0.51439" mass="0.593266" diaginertia="0.00176631 0.00174084 0.000233805"/>
            <joint name="knee_left" pos="0 0 0" axis="0 0 1" range="-3.14159 3.14159" actuatorfrcrange="-10 10"/>
            <geom pos="0.0212074 -0.0322876 0.0147" quat="0.270599 0.65328 0.2706 -0.653282" type="mesh" rgba="0.917647 0.917647 0.917647 1" mesh="xt_30_2x2_f"/>
            <geom pos="0.0300907 -0.0130682 -0.0195" quat="0.650204 0.650207 0.277909 0.277908" type="mesh" rgba="0.690196 0.690196 0.690196 1" mesh="27628_01_050_catpart"/>
            <geom pos="0 0 -0.025" quat="0.499998 -0.5 -0.5 -0.500002" type="mesh" rgba="0.690196 0.690196 0.690196 1" mesh="07534_05x40_catpart"/>
            <geom pos="0.0300908 -0.0660682 0.0405" quat="0.632813 -0.315509 0.632815 0.31551" type="mesh" rgba="0.690196 0.690196 0.690196 1" mesh="07534_05x20_catpart"/>
            <geom pos="0 -0.26 0.067" quat="0.707105 -0.707108 0 0" type="mesh" rgba="1 0 0 1" mesh="tibias12_sym"/>
            <geom pos="0.12299 -0.14568 0.0195" quat="0.632813 -0.632815 -0.31551 0.315509" type="mesh" rgba="0.917647 0.917647 0.917647 1" mesh="actuation_ankle"/>
            <geom pos="0.0300908 -0.0660682 0.0129398" quat="4.20999e-07 0.317305 0.948324 1.25823e-06" type="mesh" rgba="0.603922 0.647059 0.686275 1" mesh="hex_thin_nut_grade_a___b_m4x0_7__a8228d9ce5dcc05f24da0a2f74d882f3"/>
            <geom pos="0.470217 -0.113201 -0.006" quat="9.38184e-07 -9.38187e-07 0.707108 -0.707105" type="mesh" rgba="0.301961 0.301961 0.301961 1" mesh="rmdx43"/>
            <geom pos="0.0300908 -0.0130682 -0.0405" quat="0.632813 0.315509 -0.632815 0.31551" type="mesh" rgba="0.690196 0.690196 0.690196 1" mesh="07534_05x20_catpart"/>
            <geom pos="0.470217 -0.0457991 0.006" quat="9.38184e-07 9.38187e-07 -0.707108 -0.707105" type="mesh" rgba="0.301961 0.301961 0.301961 1" mesh="rmdx43"/>
            <geom pos="0 -0.26 0.067" quat="0.707105 -0.707108 0 0" type="mesh" rgba="1 0 0 1" mesh="tibias22_sym"/>
            <geom pos="0.0212074 -0.126712 -0.015" quat="0.65328 -0.270597 -0.653283 -0.270598" type="mesh" rgba="0.917647 0.917647 0.917647 1" mesh="xt_30_2x2_f"/>
            <geom pos="0 0 0.0247602" quat="1.76187e-12 -1.32679e-06 1 -1.32679e-06" type="mesh" rgba="0.603922 0.647059 0.686275 1" mesh="hex_thin_nut_grade_a___b_m4x0_7__a8228d9ce5dcc05f24da0a2f74d882f3"/>
            <geom pos="-0.12299 -0.0133205 -0.0195" quat="0.632813 0.632815 0.31551 0.315509" type="mesh" rgba="0.917647 0.917647 0.917647 1" mesh="actuation_ankle"/>
            <geom pos="0 -0.26 -0.019" quat="9.38184e-07 9.38187e-07 -0.707108 -0.707105" type="mesh" rgba="1 0 0 1" mesh="hat_big"/>
            <geom pos="0.0300907 -0.066068 0.0225" quat="4.69e-05 4.69002e-05 -0.707108 -0.707105" type="mesh" rgba="0.690196 0.690196 0.690196 1" mesh="27628_01_050_catpart"/>
            <geom pos="0.0300908 -0.0130682 -0.0129398" quat="0.317305 0 0 0.948324" type="mesh" rgba="0.603922 0.647059 0.686275 1" mesh="hex_thin_nut_grade_a___b_m4x0_7__a8228d9ce5dcc05f24da0a2f74d882f3"/>
            <geom pos="0 -0.106 0.019" quat="0.195092 0 0 0.980785" type="mesh" rgba="1 1 1 1" mesh="1_1_31_eb463_510_fl46blw10_48v_5n_m_de_2__fl46blw10_48v_5n_m_de"/>
            <geom pos="0 -0.106 0.009" quat="0.195092 0 0 0.980785" type="mesh" rgba="1 1 1 1" mesh="1_1_02_eb461_502_fl46blw10_48v_5n_m_de_2__fl46blw10_48v_5n_m_de"/>
            <geom pos="0 -0.106 -0.0225" quat="0.707105 0 0 0.707108" type="mesh" rgba="1 1 1 1" mesh="1_1_06_eb463_509_fl46blw10_48v_5n_m_de_2__fl46blw10_48v_5n_m_de"/>
            <geom pos="0 -0.106 -0.009" quat="0.382686 0 0 0.923879" type="mesh" rgba="1 1 1 1" mesh="1_1_06_eb463_507_fl46blw10_48v_5n_m_de_2__fl46blw10_48v_5n_m_de"/>
            <geom pos="0 -0.053 -0.019" quat="2.58847e-07 -0.195092 0.980785 -1.3013e-06" type="mesh" rgba="1 1 1 1" mesh="1_1_31_eb463_510_fl46blw10_48v_5n_m_de_2__fl46blw10_48v_5n_m_de"/>
            <geom pos="0 -0.053 -0.009" quat="2.58847e-07 -0.195092 0.980785 -1.3013e-06" type="mesh" rgba="1 1 1 1" mesh="1_1_02_eb461_502_fl46blw10_48v_5n_m_de_2__fl46blw10_48v_5n_m_de"/>
            <geom pos="0 -0.053 0.0225" quat="9.38184e-07 -0.707105 0.707108 -9.38187e-07" type="mesh" rgba="1 1 1 1" mesh="1_1_06_eb463_509_fl46blw10_48v_5n_m_de_2__fl46blw10_48v_5n_m_de"/>
            <geom pos="0 -0.053 0.009" quat="5.07745e-07 -0.382686 0.923879 -1.2258e-06" type="mesh" rgba="1 1 1 1" mesh="1_1_06_eb463_507_fl46blw10_48v_5n_m_de_2__fl46blw10_48v_5n_m_de"/>
            <geom pos="0.00671751 -0.0992825 0.0235" quat="1.2258e-06 0.92388 -0.382683 -5.07742e-07" type="mesh" rgba="1 1 1 1" mesh="0001755652_1_1_30_gr_2202_asm_1_asm_1_1_30_gr_2202_asm_fl46blw10_48v_5n_m_de_2__fl46blw10_48v_5n_m_de"/>
            <geom pos="0.00245878 -0.115176 0.0235" quat="1.2258e-06 0.92388 -0.382683 -5.07742e-07" type="mesh" rgba="1 1 1 1" mesh="0001755652_1_1_30_gr_2202_asm_1_asm_1_1_30_gr_2202_asm_fl46blw10_48v_5n_m_de_2__fl46blw10_48v_5n_m_de"/>
            <geom pos="0.00671751 -0.0597175 -0.0235" quat="0.92388 0 0 0.382683" type="mesh" rgba="1 1 1 1" mesh="0001755652_1_1_30_gr_2202_asm_1_asm_1_1_30_gr_2202_asm_fl46blw10_48v_5n_m_de_2__fl46blw10_48v_5n_m_de"/>
            <geom pos="0.00245878 -0.0438237 -0.0235" quat="0.92388 0 0 0.382683" type="mesh" rgba="1 1 1 1" mesh="0001755652_1_1_30_gr_2202_asm_1_asm_1_1_30_gr_2202_asm_fl46blw10_48v_5n_m_de_2__fl46blw10_48v_5n_m_de"/>
            <geom pos="-0.0091763 -0.103541 0.0235" quat="1.2258e-06 0.92388 -0.382683 -5.07742e-07" type="mesh" rgba="1 1 1 1" mesh="0001755652_00mini_000_asm_1_asm_1_asm_00mini__20250103_a0001_asm_1_as_asm_1_1_30_gr_2202_asm_1_asm_1_1_30_gr_2202_asm_fl46blw10_48v_5n_m_de_2__fl46blw10_48v_5n_m_de"/>
            <geom pos="0 -0.106 0.02" quat="1.2258e-06 0.92388 -0.382683 -5.07742e-07" type="mesh" rgba="1 1 1 1" mesh="6706__300001_1_1_00mini_000_asm_1_asm_1_asm_00mini__20250103_a0001_asm_1_as_asm_1_1_30_gr_2202_asm_1_asm_1_1_30_gr_2202_asm_fl46blw10_48v_5n_m_de_2__fl46blw10_48v_5n_m_de"/>
            <geom pos="0 -0.106 0.0204" quat="1.2258e-06 0.92388 -0.382683 -5.07742e-07" type="mesh" rgba="1 1 1 1" mesh="0001755650_00mini_000_asm_1_asm_1_asm_00mini__20250103_a0001_asm_1_as_asm_1_1_30_gr_2202_asm_1_asm_1_1_30_gr_2202_asm_fl46blw10_48v_5n_m_de_2__fl46blw10_48v_5n_m_de"/>
            <geom pos="-0.0091763 -0.0554588 -0.0235" quat="0.92388 0 0 0.382683" type="mesh" rgba="1 1 1 1" mesh="0001755652_00mini_000_asm_1_asm_1_asm_00mini__20250103_a0001_asm_1_as_asm_1_1_30_gr_2202_asm_1_asm_1_1_30_gr_2202_asm_fl46blw10_48v_5n_m_de_2__fl46blw10_48v_5n_m_de"/>
            <geom pos="0 -0.053 -0.02" quat="0.92388 0 0 0.382683" type="mesh" rgba="1 1 1 1" mesh="6706__300001_1_1_00mini_000_asm_1_asm_1_asm_00mini__20250103_a0001_asm_1_as_asm_1_1_30_gr_2202_asm_1_asm_1_1_30_gr_2202_asm_fl46blw10_48v_5n_m_de_2__fl46blw10_48v_5n_m_de"/>
            <geom pos="0 -0.053 -0.0204" quat="0.92388 0 0 0.382683" type="mesh" rgba="1 1 1 1" mesh="0001755650_00mini_000_asm_1_asm_1_asm_00mini__20250103_a0001_asm_1_as_asm_1_1_30_gr_2202_asm_1_asm_1_1_30_gr_2202_asm_fl46blw10_48v_5n_m_de_2__fl46blw10_48v_5n_m_de"/>
            <body name="ankle_subassembly_2" pos="0 -0.26 -0.02" quat="0.888105 0 0 -0.459641">
              <inertial pos="1.62086e-08 -0.000727483 0.02" mass="0.0168168" diaginertia="5.19458e-06 4.86353e-06 8.35665e-07"/>
              <joint name="ankley_left" pos="0 0 0" axis="0 0 1" range="-3.14159 3.14159" actuatorfrcrange="-10 10"/>
              <geom pos="0 0.0249999 0.02" quat="0.707105 0 0 -0.707108" type="mesh" rgba="0.690196 0.690196 0.690196 1" mesh="07534_05x40_catpart"/>
              <geom pos="0 0 0.02" quat="9.38184e-07 -0.707105 -9.38187e-07 -0.707108" type="mesh" rgba="1 0 0 1" mesh="ujoint"/>
              <geom pos="0 0 0.02" quat="0.699512 -2.00452e-08 0.71462 -2.00452e-08" type="mesh" rgba="0.917647 0.917647 0.917647 1" mesh="spacer_ujoint"/>
              <geom pos="0 -0.02204 0.02" quat="-0.49463 0.49463 -0.505313 -0.505313" type="mesh" rgba="0.603922 0.647059 0.686275 1" mesh="hex_thin_nut_grade_a___b_m4x0_7__a8228d9ce5dcc05f24da0a2f74d882f3"/>
              <geom pos="0 0 0.0205" quat="9.38184e-07 -0.707105 -9.38187e-07 -0.707108" type="mesh" rgba="1 0 0 1" mesh="part_3"/>
              <geom pos="0 -0.01594 0.02" quat="-0.699512 1.87626e-06 -0.71462 -1.87626e-06" type="mesh" rgba="0.917647 0.917647 0.917647 1" mesh="bearing_5_16_5"/>
              <geom pos="0 0 0.04" quat="9.38184e-07 -9.38187e-07 0.707108 -0.707105" type="mesh" rgba="0.647059 0.647059 0.647059 1" mesh="bearing_15_21_4"/>
              <geom pos="0 0 0.0195" quat="9.38184e-07 0.707105 9.38187e-07 -0.707108" type="mesh" rgba="1 0 0 1" mesh="part_3"/>
              <geom pos="0 0.0209456 0.02" quat="0.999973 0 -0.00732918 0" type="mesh" rgba="0.917647 0.917647 0.917647 1" mesh="bearing_5_16_5"/>
              <geom pos="0 5.64895e-06 0.02" quat="9.45034e-07 0.701906 -9.31284e-07 0.71227" type="mesh" rgba="0.917647 0.917647 0.917647 1" mesh="spacer_ujoint"/>
              <geom quat="0.707105 0.707108 0 0" type="mesh" rgba="0.647059 0.647059 0.647059 1" mesh="bearing_15_21_4"/>
              <body name="foot_subassembly_2" pos="0 -0.01594 0.02" quat="0.50173 0.501732 -0.498262 0.498264">
                <inertial pos="8.52312e-09 -0.0138418 -0.052232" quat="0.705627 0.0421767 -0.042203 0.706067" mass="0.122498" diaginertia="0.000163602 0.000163413 6.9433e-05"/>
                <joint name="anklex_left" pos="0 0 0" axis="0 0 1" range="-3.14159 3.14159" actuatorfrcrange="-10 10"/>
                <geom pos="0.021 3.53792e-08 -0.0660002" quat="9.38184e-07 -0.707105 -0.707108 9.38187e-07" type="mesh" rgba="0.690196 0.690196 0.690196 1" mesh="27628_01_050_catpart"/>
                <geom pos="0.036 0 -0.066" quat="1.76043e-12 1.32679e-06 1 1.32679e-06" type="mesh" rgba="0.690196 0.690196 0.690196 1" mesh="07534_05x20_catpart"/>
                <geom pos="-0.021 -1.89504e-08 -0.066" quat="9.38184e-07 0.707105 0.707108 9.38187e-07" type="mesh" rgba="0.690196 0.690196 0.690196 1" mesh="27628_01_050_catpart"/>
                <geom pos="-0.036 0 -0.066" quat="1 0 0 0" type="mesh" rgba="0.690196 0.690196 0.690196 1" mesh="07534_05x20_catpart"/>
                <geom pos="0 -0.035 -0.0385" quat="0.499998 -0.5 -0.5 -0.500002" type="mesh" rgba="1 0 0 1" mesh="hat_small"/>
                <geom pos="0 -0.035 -0.0385" quat="0.499998 -0.5 -0.5 -0.500002" type="mesh" rgba="0.301961 0.301961 0.301961 1" mesh="foot"/>
              </body>
            </body>
          </body>
        </body>
      </body>
    </body>
  </worldbody>
</mujoco>
