<?xml version="1.0" ?>
<!-- Generated using onshape-to-robot -->
<!-- Onshape https://cad.onshape.com/documents/fb645318a27646d1d8840be6/w/d1cae8805fb652b4d1614997/e/804a1da43f242001a05129b4 -->
<mujoco model="mjcf">
  <compiler angle="radian" meshdir="assets" autolimits="true"/>
  <default>
    <default class="mjcf">
      <joint frictionloss="0.1" armature="0.005"/>
      <position kp="50" dampratio="1"/>
      <default class="visual">
        <geom type="mesh" contype="0" conaffinity="0" group="2"/>
      </default>
      <default class="collision">
        <geom group="3" type="capsule" contype="1" conaffinity="1"/>
      </default>
    </default>
  </default>
  <worldbody>
    <!-- Link torso_subassembly -->
    <body name="torso_subassembly" pos="0 0 0.72" quat="1 0 0 0" childclass="mjcf">
      <freejoint name="torso_subassembly_freejoint"/>
      <inertial pos="-0.000668828 4.08197e-07 0.0384522" mass="1.68455" fullinertia="0.0196473 0.00141686 0.0199217 -3.02227e-10 9.19521e-07 1.31114e-10"/>
      <!-- Part robstrideo0 -->
      <geom type="mesh" class="visual" pos="-0.673363 0.0109625 0.061034" quat="0.707107 0.707107 1.77636e-15 -1.78468e-15" mesh="robstrideo0" material="robstrideo0_material"/>
      <!-- Part rs00 -->
      <!-- Part torso22 -->
      <geom type="mesh" class="visual" pos="-0.000263039 0.233572 -0.0901625" quat="1.22125e-15 7.8165e-17 -0.990051 0.140711" mesh="torso22" material="torso22_material"/>
      <!-- Part hex_socket_head_cap_screw_m4x0_70_x_20__832e47d784177ea3f1dabbaab534416e -->
      <!-- Part rs00_2 -->
      <!-- Part hex_socket_head_cap_screw_m4x0_70_x_20__832e47d784177ea3f1dabbaab534416e_2 -->
      <!-- Part hex_socket_head_cap_screw_m3x0_50_x_8__d566997e1880d7fd3377c5b0ee12206c -->
      <!-- Part hex_socket_head_cap_screw_m3x0_50_x_8__d566997e1880d7fd3377c5b0ee12206c_2 -->
      <!-- Part bearing_35_72_17 -->
      <geom type="mesh" class="visual" pos="-0.000887454 -0.130401 0.0222352" quat="0.0013181 -0.00114402 -0.655472 -0.755218" mesh="bearing_35_72_17" material="bearing_35_72_17_material"/>
      <!-- Part hex_socket_head_cap_screw_m4x0_70_x_20__832e47d784177ea3f1dabbaab534416e_3 -->
      <!-- Part hex_socket_head_cap_screw_m4x0_70_x_20__832e47d784177ea3f1dabbaab534416e_4 -->
      <!-- Part hex_socket_head_cap_screw_m4x0_70_x_20__832e47d784177ea3f1dabbaab534416e_5 -->
      <!-- Part robstrideo0_2 -->
      <geom type="mesh" class="visual" pos="0.672086 -0.147255 0.0629195" quat="0.0013181 -0.00114402 -0.655472 -0.755218" mesh="robstrideo0" material="robstrideo0_material"/>
      <!-- Part hex_socket_head_cap_screw_m3x0_50_x_8__d566997e1880d7fd3377c5b0ee12206c_3 -->
      <!-- Part hex_socket_head_cap_screw_m4x0_70_x_20__832e47d784177ea3f1dabbaab534416e_6 -->
      <!-- Part hex_socket_head_cap_screw_m3x0_50_x_8__d566997e1880d7fd3377c5b0ee12206c_4 -->
      <!-- Part hex_socket_head_cap_screw_m4x0_70_x_20__832e47d784177ea3f1dabbaab534416e_7 -->
      <!-- Part hex_socket_head_cap_screw_m4x0_70_x_20__832e47d784177ea3f1dabbaab534416e_8 -->
      <!-- Part hex_socket_head_cap_screw_m3x0_50_x_8__d566997e1880d7fd3377c5b0ee12206c_5 -->
      <!-- Part hex_socket_head_cap_screw_m4x0_70_x_20__832e47d784177ea3f1dabbaab534416e_9 -->
      <!-- Part hex_socket_head_cap_screw_m3x0_50_x_8__d566997e1880d7fd3377c5b0ee12206c_6 -->
      <!-- Part robstrideo0_3 -->
      <geom type="mesh" class="visual" pos="0.672086 0.12555 0.0660044" quat="0.00114402 -0.0013181 -0.755218 -0.655472" mesh="robstrideo0" material="robstrideo0_material"/>
      <!-- Part hex_socket_head_cap_screw_m3x0_50_x_8__d566997e1880d7fd3377c5b0ee12206c_7 -->
      <!-- Part hex_socket_head_cap_screw_m3x0_50_x_8__d566997e1880d7fd3377c5b0ee12206c_8 -->
      <!-- Part hex_socket_head_cap_screw_m4x0_70_x_20__832e47d784177ea3f1dabbaab534416e_10 -->
      <!-- Part torso12 -->
      <geom type="mesh" class="visual" pos="-0.000263039 4.05842e-07 -0.056966" quat="8.88178e-16 -1.12371e-16 -1 -1.66533e-15" mesh="torso12" material="torso12_material"/>
      <!-- Part hex_socket_head_cap_screw_m4x0_70_x_20__832e47d784177ea3f1dabbaab534416e_11 -->
      <!-- Part hex_socket_head_cap_screw_m4x0_70_x_20__832e47d784177ea3f1dabbaab534416e_12 -->
      <!-- Part torso22_2 -->
      <geom type="mesh" class="visual" pos="-0.000263039 4.05842e-07 -0.056966" quat="1.22125e-15 -1.08082e-16 -1 -1.22125e-15" mesh="torso22" material="torso22_material"/>
      <!-- Part hex_socket_head_cap_screw_m4x0_70_x_20__832e47d784177ea3f1dabbaab534416e_13 -->
      <!-- Part bearing_35_72_17_2 -->
      <geom type="mesh" class="visual" pos="-0.000887454 0.130402 0.0222352" quat="0.00114402 -0.0013181 -0.755218 -0.655472" mesh="bearing_35_72_17" material="bearing_35_72_17_material"/>
      <!-- Part hex_socket_head_cap_screw_m3x0_50_x_8__d566997e1880d7fd3377c5b0ee12206c_9 -->
      <!-- Part hex_socket_head_cap_screw_m3x0_50_x_8__d566997e1880d7fd3377c5b0ee12206c_10 -->
      <!-- Part hex_socket_head_cap_screw_m3x0_50_x_8__d566997e1880d7fd3377c5b0ee12206c_11 -->
      <!-- Part hex_socket_head_cap_screw_m4x0_70_x_20__832e47d784177ea3f1dabbaab534416e_14 -->
      <!-- Part xt_30_2x2_f -->
      <geom type="mesh" class="visual" pos="-3.97731e-05 -0.105809 0.0903709" quat="0.464297 0.534952 -0.533088 0.46268" mesh="xt_30_2x2_f" material="xt_30_2x2_f_material"/>
      <!-- Part hex_socket_head_cap_screw_m4x0_70_x_20__832e47d784177ea3f1dabbaab534416e_15 -->
      <!-- Part hex_socket_head_cap_screw_m4x0_70_x_20__832e47d784177ea3f1dabbaab534416e_16 -->
      <!-- Part hex_socket_head_cap_screw_m3x0_50_x_8__d566997e1880d7fd3377c5b0ee12206c_12 -->
      <!-- Frame imu -->
      <site group="3" name="imu" pos="1.28979e-17 1.37152e-17 -3.20924e-17" quat="1 -0 2.44249e-15 -0"/>
      <!-- Link hipx_subassembly -->
      <body name="hipx_subassembly" pos="-0.000819037 -0.133159 0.04164" quat="0.821908 0.0571233 0.0414078 -0.565234">
        <!-- Joint from torso_subassembly to hipx_subassembly -->
        <joint axis="0 0 1" name="hipz_right" type="hinge"/>
        <inertial pos="-0.0179437 -0.0274254 -0.0837243" mass="0.794013" fullinertia="0.00093782 0.000903422 0.00100397 -4.40032e-05 -0.00011053 -0.000168643"/>
        <!-- Part rs02 -->
        <!-- Part hex_socket_head_cap_screw_m4x0_70_x_40__14321d45d56569246e7feb4574a6bae6 -->
        <!-- Part hex_socket_head_cap_screw_m3x0_50_x_8__d566997e1880d7fd3377c5b0ee12206c_13 -->
        <!-- Part hex_socket_head_cap_screw_m3x0_50_x_8__d566997e1880d7fd3377c5b0ee12206c_14 -->
        <!-- Part hex_socket_head_cap_screw_m4x0_70_x_40__14321d45d56569246e7feb4574a6bae6_2 -->
        <!-- Part hex_socket_head_cap_screw_m3x0_50_x_8__d566997e1880d7fd3377c5b0ee12206c_15 -->
        <!-- Part xt_30_2x2_f_2 -->
        <geom type="mesh" class="visual" pos="-0.0280156 -0.000591536 -0.0506633" quat="0.372266 0.524562 -0.593709 0.48349" mesh="xt_30_2x2_f" material="xt_30_2x2_f_material"/>
        <!-- Part hex_socket_head_cap_screw_m3x0_50_x_8__d566997e1880d7fd3377c5b0ee12206c_16 -->
        <!-- Part hex_socket_head_cap_screw_m4x0_70_x_40__14321d45d56569246e7feb4574a6bae6_3 -->
        <!-- Part hex_socket_head_cap_screw_m4x0_70_x_40__14321d45d56569246e7feb4574a6bae6_4 -->
        <!-- Part hex_socket_head_cap_screw_m3x0_50_x_8__d566997e1880d7fd3377c5b0ee12206c_17 -->
        <!-- Part hipz12 -->
        <geom type="mesh" class="visual" pos="-1.38778e-17 -6.93889e-18 -0.1" quat="0 1 0 0" mesh="hipz12" material="hipz12_material"/>
        <!-- Part hex_socket_head_cap_screw_m4x0_70_x_40__14321d45d56569246e7feb4574a6bae6_5 -->
        <!-- Part hex_socket_head_cap_screw_m3x0_50_x_8__d566997e1880d7fd3377c5b0ee12206c_18 -->
        <!-- Part hex_socket_head_cap_screw_m3x0_50_x_8__d566997e1880d7fd3377c5b0ee12206c_19 -->
        <!-- Part robstride02 -->
        <geom type="mesh" class="visual" pos="-0.575896 0.0494047 -0.172196" quat="0.792908 -0.60316 -0.0524169 -0.0689068" mesh="robstride02" material="robstride02_material"/>
        <!-- Part hex_socket_head_cap_screw_m4x0_70_x_40__14321d45d56569246e7feb4574a6bae6_6 -->
        <!-- Part hex_socket_head_cap_screw_m3x0_50_x_8__d566997e1880d7fd3377c5b0ee12206c_20 -->
        <!-- Part hex_socket_head_cap_screw_m4x0_70_x_40__14321d45d56569246e7feb4574a6bae6_7 -->
        <!-- Part hex_socket_head_cap_screw_m4x0_70_x_40__14321d45d56569246e7feb4574a6bae6_8 -->
        <!-- Part hex_socket_head_cap_screw_m3x0_50_x_8__d566997e1880d7fd3377c5b0ee12206c_21 -->
        <!-- Part bearing_35_72_17_3 -->
        <geom type="mesh" class="visual" pos="-0.01759 -0.0267968 -0.104484" quat="0.60316 0.792908 -0.0689068 0.0524169" mesh="bearing_35_72_17" material="bearing_35_72_17_material"/>
        <!-- Part hex_socket_head_cap_screw_m3x0_50_x_8__d566997e1880d7fd3377c5b0ee12206c_22 -->
        <!-- Part hex_socket_head_cap_screw_m3x0_50_x_8__d566997e1880d7fd3377c5b0ee12206c_23 -->
        <!-- Part hex_socket_head_cap_screw_m4x0_70_x_40__14321d45d56569246e7feb4574a6bae6_9 -->
        <!-- Part hex_socket_head_cap_screw_m3x0_50_x_8__d566997e1880d7fd3377c5b0ee12206c_24 -->
        <!-- Part hipz22 -->
        <geom type="mesh" class="visual" pos="0 -6.93889e-18 -0.1" quat="1.94496e-17 1 -1.41046e-16 -3.7639e-17" mesh="hipz22" material="hipz22_material"/>
        <!-- Part hex_socket_head_cap_screw_m3x0_50_x_8__d566997e1880d7fd3377c5b0ee12206c_25 -->
        <!-- Part hex_socket_head_cap_screw_m3x0_50_x_8__d566997e1880d7fd3377c5b0ee12206c_26 -->
        <!-- Part hex_socket_head_cap_screw_m3x0_50_x_8__d566997e1880d7fd3377c5b0ee12206c_27 -->
        <!-- Part hex_socket_head_cap_screw_m4x0_70_x_40__14321d45d56569246e7feb4574a6bae6_10 -->
        <!-- Link hipy_subassembly -->
        <body name="hipy_subassembly" pos="-0.01897 -0.0289 -0.09689" quat="0.388859 0.13275 0.0879729 -0.907429">
          <!-- Joint from hipx_subassembly to hipy_subassembly -->
          <joint axis="0 0 1" name="hipx_right" type="hinge"/>
          <inertial pos="0.00476547 -0.00266343 -0.0607297" mass="0.241618" fullinertia="0.000504044 0.000455767 0.000428966 2.43362e-05 7.84949e-06 -3.61499e-05"/>
          <!-- Part hex_socket_head_cap_screw_m4x0_70_x_20__832e47d784177ea3f1dabbaab534416e_17 -->
          <!-- Part hipxy -->
          <geom type="mesh" class="visual" pos="-2.1684e-18 0 0" quat="1 0 -2.77556e-17 -2.34188e-17" mesh="hipxy" material="hipxy_material"/>
          <!-- Part hex_socket_head_cap_screw_m4x0_70_x_20__832e47d784177ea3f1dabbaab534416e_18 -->
          <!-- Part hex_socket_head_cap_screw_m4x0_70_x_20__832e47d784177ea3f1dabbaab534416e_19 -->
          <!-- Part hex_socket_head_cap_screw_m4x0_70_x_12__c825518ee8edf1afced0eee1b019b750 -->
          <!-- Part hex_socket_head_cap_screw_m4x0_70_x_20__832e47d784177ea3f1dabbaab534416e_20 -->
          <!-- Part hex_socket_head_cap_screw_m4x0_70_x_12__c825518ee8edf1afced0eee1b019b750_2 -->
          <!-- Part hex_socket_head_cap_screw_m4x0_70_x_12__c825518ee8edf1afced0eee1b019b750_3 -->
          <!-- Part hex_socket_head_cap_screw_m4x0_70_x_20__832e47d784177ea3f1dabbaab534416e_21 -->
          <!-- Part hex_socket_head_cap_screw_m4x0_70_x_20__832e47d784177ea3f1dabbaab534416e_22 -->
          <!-- Part hex_socket_head_cap_screw_m4x0_70_x_12__c825518ee8edf1afced0eee1b019b750_4 -->
          <!-- Part hex_socket_head_cap_screw_m4x0_70_x_12__c825518ee8edf1afced0eee1b019b750_5 -->
          <!-- Part hex_socket_head_cap_screw_m4x0_70_x_12__c825518ee8edf1afced0eee1b019b750_6 -->
          <!-- Link tigh_subassembly -->
          <body name="tigh_subassembly" pos="0.012638 -0.0276823 -0.112055" quat="0.289457 0.00726416 0.730479 -0.618516">
            <!-- Joint from hipy_subassembly to tigh_subassembly -->
            <joint axis="0 0 1" name="hipy_right" type="hinge"/>
            <inertial pos="0.0501976 0.0785779 -0.0353813" mass="2.5804" fullinertia="0.0174359 0.00865749 0.0236145 -0.0081889 0.000938636 0.00155247"/>
            <!-- Part hex_socket_head_cap_screw_m3x0_50_x_10__9c80fcbba574884e63b580474e1ee150 -->
            <!-- Part hex_socket_head_cap_screw_m2_5x0_45_x_6__ec244025d76f8b83b2775022a2cb3232 -->
            <!-- Part hex_socket_head_cap_screw_m4x0_70_x_8__a416dc2a8d778a4ef6150c0739aa89d1 -->
            <!-- Part hex_socket_head_cap_screw_m2_5x0_45_x_6__ec244025d76f8b83b2775022a2cb3232_2 -->
            <!-- Part hex_socket_head_cap_screw_m4x0_70_x_8__a416dc2a8d778a4ef6150c0739aa89d1_2 -->
            <!-- Part hex_socket_head_cap_screw_m3x0_50_x_10__9c80fcbba574884e63b580474e1ee150_2 -->
            <!-- Part hex_socket_head_cap_screw_m4x0_70_x_16__8d628c0d7a90368385b1c4c7479647eb -->
            <!-- Part hex_socket_head_cap_screw_m4x0_70_x_8__a416dc2a8d778a4ef6150c0739aa89d1_3 -->
            <!-- Part hex_socket_head_cap_screw_m4x0_70_x_16__8d628c0d7a90368385b1c4c7479647eb_2 -->
            <!-- Part hex_socket_head_cap_screw_m4x0_70_x_8__a416dc2a8d778a4ef6150c0739aa89d1_4 -->
            <!-- Part knee_rod22 -->
            <geom type="mesh" class="visual" pos="0.210506 0.184547 -0.0305" quat="0.612372 0.612372 -0.353553 -0.353553" mesh="knee_rod22" material="knee_rod22_material"/>
            <!-- Part hex_socket_head_cap_screw_m4x0_70_x_8__a416dc2a8d778a4ef6150c0739aa89d1_5 -->
            <!-- Part hex_socket_head_cap_screw_m4x0_70_x_16__8d628c0d7a90368385b1c4c7479647eb_3 -->
            <!-- Part hex_socket_head_cap_screw_m4x0_70_x_16__8d628c0d7a90368385b1c4c7479647eb_4 -->
            <!-- Part hex_socket_head_cap_screw_m4x0_70_x_8__a416dc2a8d778a4ef6150c0739aa89d1_6 -->
            <!-- Part bearing_15_21_4 -->
            <geom type="mesh" class="visual" pos="0.117923 0.320381 -0.0185" quat="0.612372 -0.612372 0.353553 -0.353553" mesh="bearing_15_21_4" material="bearing_15_21_4_material"/>
            <!-- Part bearing_15_21_4_2 -->
            <geom type="mesh" class="visual" pos="0.0130854 0.122429 -0.0245" quat="0.707107 -0.707107 6.60583e-14 -9.76421e-14" mesh="bearing_15_21_4" material="bearing_15_21_4_material"/>
            <!-- Part hex_socket_head_cap_screw_m2_5x0_45_x_6__ec244025d76f8b83b2775022a2cb3232_3 -->
            <!-- Part hex_socket_head_cap_screw_m4x0_70_x_8__a416dc2a8d778a4ef6150c0739aa89d1_7 -->
            <!-- Part robstrideo3 -->
            <geom type="mesh" class="visual" pos="-0.437806 0.570998 -0.07" quat="0.683013 -0.683013 0.183013 -0.183013" mesh="robstrideo3" material="robstrideo3_material"/>
            <!-- Part hex_socket_head_cap_screw_m4x0_70_x_16__8d628c0d7a90368385b1c4c7479647eb_5 -->
            <!-- Part bearing_15_21_4_3 -->
            <geom type="mesh" class="visual" pos="1.88044e-15 -9.85323e-15 -0.0635" quat="0.683013 0.683013 -0.183013 -0.183013" mesh="bearing_15_21_4" material="bearing_15_21_4_material"/>
            <!-- Part bearing_15_21_4_4 -->
            <geom type="mesh" class="visual" pos="0.0130854 0.122429 -0.0365" quat="0.707107 0.707107 -9.73666e-14 -6.65354e-14" mesh="bearing_15_21_4" material="bearing_15_21_4_material"/>
            <!-- Part hex_socket_head_cap_screw_m4x0_70_x_40__14321d45d56569246e7feb4574a6bae6_11 -->
            <!-- Part bearing_15_21_4_5 -->
            <geom type="mesh" class="visual" pos="0.117923 0.320381 -0.0425" quat="0.612372 0.612372 -0.353553 -0.353553" mesh="bearing_15_21_4" material="bearing_15_21_4_material"/>
            <!-- Part hex_socket_head_cap_screw_m4x0_70_x_40__14321d45d56569246e7feb4574a6bae6_12 -->
            <!-- Part hex_socket_head_cap_screw_m4x0_70_x_8__a416dc2a8d778a4ef6150c0739aa89d1_8 -->
            <!-- Part hex_socket_head_cap_screw_m2_5x0_45_x_6__ec244025d76f8b83b2775022a2cb3232_4 -->
            <!-- Part hex_socket_head_cap_screw_m2_5x0_45_x_6__ec244025d76f8b83b2775022a2cb3232_5 -->
            <!-- Part hex_socket_head_cap_screw_m4x0_70_x_8__a416dc2a8d778a4ef6150c0739aa89d1_9 -->
            <!-- Part knee_rod12 -->
            <geom type="mesh" class="visual" pos="0.210506 0.184547 -0.0305" quat="0.612372 0.612372 -0.353553 -0.353553" mesh="knee_rod12" material="knee_rod12_material"/>
            <!-- Part hex_socket_head_cap_screw_m4x0_70_x_8__a416dc2a8d778a4ef6150c0739aa89d1_10 -->
            <!-- Part bearing_5_16_5 -->
            <geom type="mesh" class="visual" pos="0.17 0.294449 -0.05" quat="0.683013 -0.683013 0.183013 -0.183013" mesh="bearing_5_16_5" material="bearing_5_16_5_material"/>
            <!-- Part hex_socket_head_cap_screw_m4x0_70_x_8__a416dc2a8d778a4ef6150c0739aa89d1_11 -->
            <!-- Part hex_socket_head_cap_screw_m4x0_70_x_8__a416dc2a8d778a4ef6150c0739aa89d1_12 -->
            <!-- Part hex_socket_head_cap_screw_m4x0_70_x_8__a416dc2a8d778a4ef6150c0739aa89d1_13 -->
            <!-- Part hex_socket_head_cap_screw_m4x0_70_x_40__14321d45d56569246e7feb4574a6bae6_13 -->
            <!-- Part knee_actuation -->
            <geom type="mesh" class="visual" pos="0.058 0.324459 -0.0305" quat="0.707107 0.707107 -9.74776e-14 -6.61751e-14" mesh="knee_actuation" material="knee_actuation_material"/>
            <!-- Part hex_socket_head_cap_screw_m4x0_70_x_16__8d628c0d7a90368385b1c4c7479647eb_6 -->
            <!-- Part hex_socket_head_cap_screw_m3x0_50_x_10__9c80fcbba574884e63b580474e1ee150_3 -->
            <!-- Part hex_socket_head_cap_screw_m4x0_70_x_8__a416dc2a8d778a4ef6150c0739aa89d1_14 -->
            <!-- Part bearing_5_16_5_2 -->
            <geom type="mesh" class="visual" pos="0.17 0.294449 -0.01425" quat="0.683013 -0.683013 0.183013 -0.183013" mesh="bearing_5_16_5" material="bearing_5_16_5_material"/>
            <!-- Part femur_22 -->
            <geom type="mesh" class="visual" pos="0.17 0.294449 -0.0305" quat="0.683013 0.683013 -0.183013 -0.183013" mesh="femur_22" material="femur_22_material"/>
            <!-- Part hex_socket_head_cap_screw_m4x0_70_x_40__14321d45d56569246e7feb4574a6bae6_14 -->
            <!-- Part femur_12 -->
            <geom type="mesh" class="visual" pos="0.17 0.294449 -0.0305" quat="0.683013 0.683013 -0.183013 -0.183013" mesh="femur_12" material="femur_12_material"/>
            <geom name="femur_12_collision" type="capsule" size="0.05 0.18" class="collision" pos="0.17 0.294449 -0.0305" quat="0.683013 0.683013 -0.183013 -0.183013"/>
            <!-- Part hat_femur -->
            <geom type="mesh" class="visual" pos="0.17 0.294449 -0.0305" quat="0.683013 0.683013 -0.183013 -0.183013" mesh="hat_femur" material="hat_femur_material"/>
            <!-- Part part_3 -->
            <geom type="mesh" class="visual" pos="2.31759e-15 -1.74027e-14 -0.0938" quat="0.183013 -0.683013 0.183013 0.683013" mesh="part_3" material="part_3_material"/>
            <!-- Part robstrideo3_2 -->
            <geom type="mesh" class="visual" pos="-0.495806 0.470539 -0.0275" quat="0.683013 -0.683013 0.183013 -0.183013" mesh="robstrideo3" material="robstrideo3_material"/>
            <!-- Part hex_socket_head_cap_screw_m2_5x0_45_x_6__ec244025d76f8b83b2775022a2cb3232_6 -->
            <!-- Part 1_1_31_qt_942_1 -->
            <geom type="mesh" class="visual" pos="3.73659e-15 -4.35763e-15 -0.04" quat="0.5 -3.0895e-14 -7.86038e-14 -0.866025" mesh="1_1_31_qt_942_1" material="1_1_31_qt_942_1_material"/>
            <!-- Part 1_1_06_eb903_538_1 -->
            <geom type="mesh" class="visual" pos="4.34722e-15 -5.88418e-15 -0.0566" quat="0.5 -3.0895e-14 -7.86038e-14 -0.866025" mesh="1_1_06_eb903_538_1" material="1_1_06_eb903_538_1_material"/>
            <!-- Part 1_1_31_qt_942_1_2 -->
            <geom type="mesh" class="visual" pos="0.058 0.100459 -0.0825" quat="0.258819 -3.5335e-14 1.70308e-13 0.965926" mesh="1_1_31_qt_942_1" material="1_1_31_qt_942_1_material"/>
            <!-- Part 1_1_06_eb903_538_1_2 -->
            <geom type="mesh" class="visual" pos="0.058 0.100459 -0.0991" quat="0.258819 -3.5335e-14 1.70308e-13 0.965926" mesh="1_1_06_eb903_538_1" material="1_1_06_eb903_538_1_material"/>
            <!-- Part 1_1_06_eb903_537_af0_1 -->
            <geom type="mesh" class="visual" pos="2.5327e-15 -4.05231e-15 -0.0375" quat="0.965926 -1.20584e-13 -4.55191e-14 -0.258819" mesh="1_1_06_eb903_537_af0_1" material="1_1_06_eb903_537_af0_1_material"/>
            <!-- Part 1_1_02_eb901_558_1 -->
            <geom type="mesh" class="visual" pos="6.93889e-18 0 0" quat="0 1 0 0" mesh="1_1_02_eb901_558_1" material="1_1_02_eb901_558_1_material"/>
            <!-- Part 1_1_06_eb903_537_af0_1_2 -->
            <geom type="mesh" class="visual" pos="0.058 0.100459 -0.08" quat="0.5 -5.24326e-14 -1.12688e-13 -0.866025" mesh="1_1_06_eb903_537_af0_1" material="1_1_06_eb903_537_af0_1_material"/>
            <!-- Part 1_1_02_eb901_558_1_2 -->
            <geom type="mesh" class="visual" pos="0.058 0.100459 -0.0425" quat="6.83945e-14 0.707107 -0.707107 1.00345e-13" mesh="1_1_02_eb901_558_1" material="1_1_02_eb901_558_1_material"/>
            <!-- Link shin_subassembly -->
            <body name="shin_subassembly" pos="0.17 0.294449 -0.0305" quat="1.16249e-13 0.963177 -0.26887 4.36995e-14">
              <!-- Joint from tigh_subassembly to shin_subassembly -->
              <joint axis="0 0 1" name="knee_right" type="hinge"/>
              <inertial pos="-0.076547 -0.0486454 6.35117e-05" mass="0.593267" fullinertia="0.000600304 0.00138759 0.00176486 -0.000634649 -8.1197e-05 -4.81249e-05"/>
              <!-- Part hex_socket_head_cap_screw_m2_5x0_45_x_8__dec2226ceabd7d7ca0bb403ec234d89b -->
              <!-- Part rmdx43 -->
              <geom type="mesh" class="visual" pos="-0.2967 0.369726 0.019" quat="0.616799 0.616799 -0.345773 -0.345773" mesh="rmdx43" material="rmdx43_material"/>
              <!-- Part xt_30_2x2_f_3 -->
              <geom type="mesh" class="visual" pos="-0.0609783 -0.00254913 -0.0142" quat="0.345773 0.616799 -0.345773 0.616799" mesh="xt_30_2x2_f" material="xt_30_2x2_f_material"/>
              <!-- Part hex_socket_head_cap_screw_m3x0_50_x_20__7252065e4445f5ec71347b53fcae11e4 -->
              <!-- Part hex_socket_head_cap_screw_m3x0_50_x_10__9c80fcbba574884e63b580474e1ee150_4 -->
              <!-- Part tibias22 -->
              <geom type="mesh" class="visual" pos="-0.221803 -0.135659 0.019" quat="0.616799 -0.616799 0.345773 -0.345773" mesh="tibias22" material="tibias22_material"/>
              <!-- Part 27628_01_050_catpart -->
              <geom type="mesh" class="visual" pos="0.00455194 -0.0324886 0.02" quat="0.658548 -0.658548 0.257517 -0.257517" mesh="27628_01_050_catpart" material="27628_01_050_catpart_material"/>
              <!-- Part hex_socket_head_cap_screw_m3x0_50_x_10__9c80fcbba574884e63b580474e1ee150_5 -->
              <!-- Part hex_socket_head_cap_screw_m3x0_50_x_10__9c80fcbba574884e63b580474e1ee150_6 -->
              <!-- Part hex_socket_head_cap_screw_m3x0_50_x_10__9c80fcbba574884e63b580474e1ee150_7 -->
              <!-- Part hex_thin_nut_grade_a___b_m4x0_7__a8228d9ce5dcc05f24da0a2f74d882f3 -->
              <geom type="mesh" class="visual" pos="-2.77556e-17 0 0.0247602" quat="1 8.23207e-17 -2.22045e-16 -4.44089e-16" mesh="hex_thin_nut_grade_a___b_m4x0_7__a8228d9ce5dcc05f24da0a2f74d882f3" material="hex_thin_nut_grade_a___b_m4x0_7__a8228d9ce5dcc05f24da0a2f74d882f3_material"/>
              <!-- Part 07534_05x40_catpart -->
              <geom type="mesh" class="visual" pos="-2.77556e-17 0 -0.025" quat="0.5 -0.5 -0.5 -0.5" mesh="07534_05x40_catpart" material="07534_05x40_catpart_material"/>
              <!-- Part hex_thin_nut_grade_a___b_m4x0_7__a8228d9ce5dcc05f24da0a2f74d882f3_2 -->
              <geom type="mesh" class="visual" pos="-0.0406618 -0.0601422 -0.0112398" quat="4.96192e-16 -0.998828 0.0484075 -9.89306e-17" mesh="hex_thin_nut_grade_a___b_m4x0_7__a8228d9ce5dcc05f24da0a2f74d882f3" material="hex_thin_nut_grade_a___b_m4x0_7__a8228d9ce5dcc05f24da0a2f74d882f3_material"/>
              <!-- Part hex_socket_head_cap_screw_m3x0_50_x_20__7252065e4445f5ec71347b53fcae11e4_2 -->
              <!-- Part hex_socket_head_cap_screw_m3x0_50_x_10__9c80fcbba574884e63b580474e1ee150_8 -->
              <!-- Part 07534_05x20_catpart -->
              <geom type="mesh" class="visual" pos="-0.0406618 -0.0601422 -0.041" quat="0.0342293 0.706278 -0.0342293 0.706278" mesh="07534_05x20_catpart" material="07534_05x20_catpart_material"/>
              <!-- Part actuation_ankle -->
              <geom type="mesh" class="visual" pos="-0.0303217 0.125625 -0.019" quat="0.706278 0.706278 -0.0342293 -0.0342293" mesh="actuation_ankle" material="actuation_ankle_material"/>
              <!-- Part hex_socket_head_cap_screw_m3x0_50_x_30__cb22dc4460edbee8e1cbddf29677c00f -->
              <!-- Part rmdx43_2 -->
              <geom type="mesh" class="visual" pos="-0.341913 0.342073 0.006" quat="0.616799 0.616799 -0.345773 -0.345773" mesh="rmdx43" material="rmdx43_material"/>
              <!-- Part hex_socket_head_cap_screw_m3x0_50_x_10__9c80fcbba574884e63b580474e1ee150_9 -->
              <!-- Part hex_socket_head_cap_screw_m3x0_50_x_20__7252065e4445f5ec71347b53fcae11e4_3 -->
              <!-- Part hex_socket_head_cap_screw_m3x0_50_x_10__9c80fcbba574884e63b580474e1ee150_10 -->
              <!-- Part hex_socket_head_cap_screw_m3x0_50_x_10__9c80fcbba574884e63b580474e1ee150_11 -->
              <!-- Part hex_socket_head_cap_screw_m3x0_50_x_10__9c80fcbba574884e63b580474e1ee150_12 -->
              <!-- Part hex_socket_head_cap_screw_m4x0_70_x_12__c825518ee8edf1afced0eee1b019b750_7 -->
              <!-- Part hex_socket_head_cap_screw_m3x0_50_x_20__7252065e4445f5ec71347b53fcae11e4_4 -->
              <!-- Part hex_socket_head_cap_screw_m3x0_50_x_20__7252065e4445f5ec71347b53fcae11e4_5 -->
              <!-- Part hex_socket_head_cap_screw_m3x0_50_x_10__9c80fcbba574884e63b580474e1ee150_13 -->
              <!-- Part hex_socket_head_cap_screw_m3x0_50_x_10__9c80fcbba574884e63b580474e1ee150_14 -->
              <!-- Part hex_socket_head_cap_screw_m3x0_50_x_10__9c80fcbba574884e63b580474e1ee150_15 -->
              <!-- Part hex_socket_head_cap_screw_m3x0_50_x_10__9c80fcbba574884e63b580474e1ee150_16 -->
              <!-- Part hex_socket_head_cap_screw_m3x0_50_x_20__7252065e4445f5ec71347b53fcae11e4_6 -->
              <!-- Part hex_socket_head_cap_screw_m3x0_50_x_10__9c80fcbba574884e63b580474e1ee150_17 -->
              <!-- Part hex_socket_head_cap_screw_m3x0_50_x_10__9c80fcbba574884e63b580474e1ee150_18 -->
              <!-- Part hex_socket_head_cap_screw_m3x0_50_x_10__9c80fcbba574884e63b580474e1ee150_19 -->
              <!-- Part hex_socket_head_cap_screw_m2_5x0_45_x_8__dec2226ceabd7d7ca0bb403ec234d89b_2 -->
              <!-- Part hex_socket_head_cap_screw_m4x0_70_x_12__c825518ee8edf1afced0eee1b019b750_8 -->
              <!-- Part hat_big -->
              <geom type="mesh" class="visual" pos="-0.221803 -0.135659 0.019" quat="0.616799 -0.616799 0.345773 -0.345773" mesh="hat_big" material="hat_big_material"/>
              <!-- Part 07534_05x20_catpart_2 -->
              <geom type="mesh" class="visual" pos="0.00455195 -0.0324886 0.041" quat="0.0342293 -0.706278 0.0342293 0.706278" mesh="07534_05x20_catpart" material="07534_05x20_catpart_material"/>
              <!-- Part hex_socket_head_cap_screw_m4x0_70_x_12__c825518ee8edf1afced0eee1b019b750_9 -->
              <!-- Part hex_thin_nut_grade_a___b_m4x0_7__a8228d9ce5dcc05f24da0a2f74d882f3_3 -->
              <geom type="mesh" class="visual" pos="0.00455195 -0.0324886 0.0134397" quat="0.998828 -1.03174e-13 1.0103e-13 -0.0484075" mesh="hex_thin_nut_grade_a___b_m4x0_7__a8228d9ce5dcc05f24da0a2f74d882f3" material="hex_thin_nut_grade_a___b_m4x0_7__a8228d9ce5dcc05f24da0a2f74d882f3_material"/>
              <!-- Part hex_socket_head_cap_screw_m2_5x0_45_x_8__dec2226ceabd7d7ca0bb403ec234d89b_3 -->
              <!-- Part tibias12 -->
              <geom type="mesh" class="visual" pos="-0.221803 -0.135659 0.019" quat="0.616799 -0.616799 0.345773 -0.345773" mesh="tibias12" material="tibias12_material"/>
              <!-- Part hex_socket_head_cap_screw_m3x0_50_x_10__9c80fcbba574884e63b580474e1ee150_20 -->
              <!-- Part hex_socket_head_cap_screw_m3x0_50_x_20__7252065e4445f5ec71347b53fcae11e4_7 -->
              <!-- Part hex_socket_head_cap_screw_m3x0_50_x_10__9c80fcbba574884e63b580474e1ee150_21 -->
              <!-- Part hex_socket_head_cap_screw_m3x0_50_x_10__9c80fcbba574884e63b580474e1ee150_22 -->
              <!-- Part xt_30_2x2_f_4 -->
              <geom type="mesh" class="visual" pos="-0.105595 -0.0298375 0.0145" quat="0.616799 0.345773 0.616799 -0.345773" mesh="xt_30_2x2_f" material="xt_30_2x2_f_material"/>
              <!-- Part hex_socket_head_cap_screw_m3x0_50_x_10__9c80fcbba574884e63b580474e1ee150_23 -->
              <!-- Part hex_socket_head_cap_screw_m3x0_50_x_20__7252065e4445f5ec71347b53fcae11e4_8 -->
              <!-- Part actuation_ankle_2 -->
              <geom type="mesh" class="visual" pos="-0.105319 -0.208585 0.019" quat="0.706278 -0.706278 0.0342293 -0.0342293" mesh="actuation_ankle" material="actuation_ankle_material"/>
              <!-- Part hex_socket_head_cap_screw_m3x0_50_x_10__9c80fcbba574884e63b580474e1ee150_24 -->
              <!-- Part hex_socket_head_cap_screw_m4x0_70_x_12__c825518ee8edf1afced0eee1b019b750_10 -->
              <!-- Part hex_socket_head_cap_screw_m3x0_50_x_20__7252065e4445f5ec71347b53fcae11e4_9 -->
              <!-- Part hex_socket_head_cap_screw_m3x0_50_x_20__7252065e4445f5ec71347b53fcae11e4_10 -->
              <!-- Part 27628_01_050_catpart_2 -->
              <geom type="mesh" class="visual" pos="-0.0406619 -0.060142 -0.023" quat="0.642927 -0.642927 -0.294356 0.294356" mesh="27628_01_050_catpart" material="27628_01_050_catpart_material"/>
              <!-- Part hex_socket_head_cap_screw_m3x0_50_x_10__9c80fcbba574884e63b580474e1ee150_25 -->
              <!-- Part hex_socket_head_cap_screw_m3x0_50_x_20__7252065e4445f5ec71347b53fcae11e4_11 -->
              <!-- Part hex_socket_head_cap_screw_m3x0_50_x_20__7252065e4445f5ec71347b53fcae11e4_12 -->
              <!-- Part hex_socket_head_cap_screw_m3x0_50_x_10__9c80fcbba574884e63b580474e1ee150_26 -->
              <!-- Part hex_socket_head_cap_screw_m3x0_50_x_10__9c80fcbba574884e63b580474e1ee150_27 -->
              <!-- Part 1_1_31_eb463_510_fl46blw10_48v_5n_m_de_2__fl46blw10_48v_5n_m_de -->
              <geom type="mesh" class="visual" pos="-0.0904274 -0.0553071 -0.0195" quat="5.12143e-15 -0.760127 0.649775 -3.05792e-15" mesh="1_1_31_eb463_510_fl46blw10_48v_5n_m_de_2__fl46blw10_48v_5n_m_de" material="1_1_31_eb463_510_fl46blw10_48v_5n_m_de_2__fl46blw10_48v_5n_m_de_material"/>
              <!-- Part 1_1_02_eb461_502_fl46blw10_48v_5n_m_de_2__fl46blw10_48v_5n_m_de -->
              <geom type="mesh" class="visual" pos="-0.0904274 -0.0553071 -0.0095" quat="5.12143e-15 -0.760127 0.649775 -3.05792e-15" mesh="1_1_02_eb461_502_fl46blw10_48v_5n_m_de_2__fl46blw10_48v_5n_m_de" material="1_1_02_eb461_502_fl46blw10_48v_5n_m_de_2__fl46blw10_48v_5n_m_de_material"/>
              <!-- Part 1_1_06_eb463_509_fl46blw10_48v_5n_m_de_2__fl46blw10_48v_5n_m_de -->
              <geom type="mesh" class="visual" pos="-0.0904274 -0.0553071 0.022" quat="4.22682e-14 0.993018 -0.117964 3.68066e-14" mesh="1_1_06_eb463_509_fl46blw10_48v_5n_m_de_2__fl46blw10_48v_5n_m_de" material="1_1_06_eb463_509_fl46blw10_48v_5n_m_de_2__fl46blw10_48v_5n_m_de_material"/>
              <!-- Part 1_1_06_eb463_507_fl46blw10_48v_5n_m_de_2__fl46blw10_48v_5n_m_de -->
              <geom type="mesh" class="visual" pos="-0.0904274 -0.0553071 0.0085" quat="8.88907e-16 0.872286 -0.488996 -1.06227e-16" mesh="1_1_06_eb463_507_fl46blw10_48v_5n_m_de_2__fl46blw10_48v_5n_m_de" material="1_1_06_eb463_507_fl46blw10_48v_5n_m_de_2__fl46blw10_48v_5n_m_de_material"/>
              <!-- Part 1_1_31_eb463_510_fl46blw10_48v_5n_m_de_2__fl46blw10_48v_5n_m_de_2 -->
              <geom type="mesh" class="visual" pos="-0.0452137 -0.0276536 0.0195" quat="0.950924 3.91045e-15 1.26565e-14 -0.309426" mesh="1_1_31_eb463_510_fl46blw10_48v_5n_m_de_2__fl46blw10_48v_5n_m_de" material="1_1_31_eb463_510_fl46blw10_48v_5n_m_de_2__fl46blw10_48v_5n_m_de_material"/>
              <!-- Part 1_1_02_eb461_502_fl46blw10_48v_5n_m_de_2__fl46blw10_48v_5n_m_de_2 -->
              <geom type="mesh" class="visual" pos="-0.0452137 -0.0276536 0.0095" quat="0.950924 3.91045e-15 1.26565e-14 -0.309426" mesh="1_1_02_eb461_502_fl46blw10_48v_5n_m_de_2__fl46blw10_48v_5n_m_de" material="1_1_02_eb461_502_fl46blw10_48v_5n_m_de_2__fl46blw10_48v_5n_m_de_material"/>
              <!-- Part 1_1_06_eb463_509_fl46blw10_48v_5n_m_de_2__fl46blw10_48v_5n_m_de_2 -->
              <geom type="mesh" class="visual" pos="-0.0452137 -0.0276536 -0.022" quat="0.618756 -2.42999e-14 -3.03091e-14 -0.785583" mesh="1_1_06_eb463_509_fl46blw10_48v_5n_m_de_2__fl46blw10_48v_5n_m_de" material="1_1_06_eb463_509_fl46blw10_48v_5n_m_de_2__fl46blw10_48v_5n_m_de_material"/>
              <!-- Part 1_1_06_eb463_507_fl46blw10_48v_5n_m_de_2__fl46blw10_48v_5n_m_de_2 -->
              <geom type="mesh" class="visual" pos="-0.0452137 -0.0276536 -0.0085" quat="0.872286 -1.30178e-15 5.38458e-15 -0.488996" mesh="1_1_06_eb463_507_fl46blw10_48v_5n_m_de_2__fl46blw10_48v_5n_m_de" material="1_1_06_eb463_507_fl46blw10_48v_5n_m_de_2__fl46blw10_48v_5n_m_de_material"/>
              <!-- Part 0001755652_1_1_30_gr_2202_asm_1_asm_1_1_30_gr_2202_asm_fl46blw10_48v_5n_m_de_2__fl46blw10_48v_5n_m_de -->
              <geom type="mesh" class="visual" pos="-0.0823231 -0.0503503 -0.024" quat="0.488996 -1.84287e-16 5.68989e-16 0.872286" mesh="0001755652_1_1_30_gr_2202_asm_1_asm_1_1_30_gr_2202_asm_fl46blw10_48v_5n_m_de_2__fl46blw10_48v_5n_m_de" material="0001755652_1_1_30_gr_2202_asm_1_asm_1_1_30_gr_2202_asm_fl46blw10_48v_5n_m_de_2__fl46blw10_48v_5n_m_de_material"/>
              <!-- Part 0001755652_1_1_30_gr_2202_asm_1_asm_1_1_30_gr_2202_asm_fl46blw10_48v_5n_m_de_2__fl46blw10_48v_5n_m_de_2 -->
              <geom type="mesh" class="visual" pos="-0.0987723 -0.0507669 -0.024" quat="0.488996 -1.84287e-16 5.68989e-16 0.872286" mesh="0001755652_1_1_30_gr_2202_asm_1_asm_1_1_30_gr_2202_asm_fl46blw10_48v_5n_m_de_2__fl46blw10_48v_5n_m_de" material="0001755652_1_1_30_gr_2202_asm_1_asm_1_1_30_gr_2202_asm_fl46blw10_48v_5n_m_de_2__fl46blw10_48v_5n_m_de_material"/>
              <!-- Part 0001755652_1_1_30_gr_2202_asm_1_asm_1_1_30_gr_2202_asm_fl46blw10_48v_5n_m_de_2__fl46blw10_48v_5n_m_de_3 -->
              <geom type="mesh" class="visual" pos="-0.0533181 -0.0326103 0.024" quat="5.00613e-14 -0.488996 -0.872286 1.38802e-13" mesh="0001755652_1_1_30_gr_2202_asm_1_asm_1_1_30_gr_2202_asm_fl46blw10_48v_5n_m_de_2__fl46blw10_48v_5n_m_de" material="0001755652_1_1_30_gr_2202_asm_1_asm_1_1_30_gr_2202_asm_fl46blw10_48v_5n_m_de_2__fl46blw10_48v_5n_m_de_material"/>
              <!-- Part 0001755652_1_1_30_gr_2202_asm_1_asm_1_1_30_gr_2202_asm_fl46blw10_48v_5n_m_de_2__fl46blw10_48v_5n_m_de_4 -->
              <geom type="mesh" class="visual" pos="-0.0454542 -0.0181566 0.024" quat="5.00613e-14 -0.488996 -0.872286 1.38802e-13" mesh="0001755652_1_1_30_gr_2202_asm_1_asm_1_1_30_gr_2202_asm_fl46blw10_48v_5n_m_de_2__fl46blw10_48v_5n_m_de" material="0001755652_1_1_30_gr_2202_asm_1_asm_1_1_30_gr_2202_asm_fl46blw10_48v_5n_m_de_2__fl46blw10_48v_5n_m_de_material"/>
              <!-- Part 0001755652_00mini_000_asm_1_asm_1_asm_00mini__20250103_a0001_asm_1_as_asm_1_1_30_gr_2202_asm_1_asm_1_1_30_gr_2202_asm_fl46blw10_48v_5n_m_de_2__fl46blw10_48v_5n_m_de -->
              <geom type="mesh" class="visual" pos="-0.0901869 -0.0648041 -0.024" quat="0.488996 -1.84287e-16 5.68989e-16 0.872286" mesh="0001755652_00mini_000_asm_1_asm_1_asm_00mini__20250103_a0001_asm_1_as_asm_1_1_30_gr_2202_asm_1_asm_1_1_30_gr_2202_asm_fl46blw10_48v_5n_m_de_2__fl46blw10_48v_5n_m_de" material="0001755652_00mini_000_asm_1_asm_1_asm_00mini__20250103_a0001_asm_1_as_asm_1_1_30_gr_2202_asm_1_asm_1_1_30_gr_2202_asm_fl46blw10_48v_5n_m_de_2__fl46blw10_48v_5n_m_de_material"/>
              <!-- Part 6706__300001_1_1_00mini_000_asm_1_asm_1_asm_00mini__20250103_a0001_asm_1_as_asm_1_1_30_gr_2202_asm_1_asm_1_1_30_gr_2202_asm_fl46blw10_48v_5n_m_de_2__fl46blw10_48v_5n_m_de -->
              <geom type="mesh" class="visual" pos="-0.0904274 -0.0553071 -0.0205" quat="0.488996 -1.84287e-16 5.68989e-16 0.872286" mesh="6706__300001_1_1_00mini_000_asm_1_asm_1_asm_00mini__20250103_a0001_asm_1_as_asm_1_1_30_gr_2202_asm_1_asm_1_1_30_gr_2202_asm_fl46blw10_48v_5n_m_de_2__fl46blw10_48v_5n_m_de" material="6706__300001_1_1_00mini_000_asm_1_asm_1_asm_00mini__20250103_a0001_asm_1_as_asm_1_1_30_gr_2202_asm_1_asm_1_1_30_gr_2202_asm_fl46blw10_48v_5n_m_de_2__fl46blw10_48v_5n_m_de_material"/>
              <!-- Part 0001755650_00mini_000_asm_1_asm_1_asm_00mini__20250103_a0001_asm_1_as_asm_1_1_30_gr_2202_asm_1_asm_1_1_30_gr_2202_asm_fl46blw10_48v_5n_m_de_2__fl46blw10_48v_5n_m_de -->
              <geom type="mesh" class="visual" pos="-0.0904274 -0.0553071 -0.0209" quat="0.488996 -1.84287e-16 5.68989e-16 0.872286" mesh="0001755650_00mini_000_asm_1_asm_1_asm_00mini__20250103_a0001_asm_1_as_asm_1_1_30_gr_2202_asm_1_asm_1_1_30_gr_2202_asm_fl46blw10_48v_5n_m_de_2__fl46blw10_48v_5n_m_de" material="0001755650_00mini_000_asm_1_asm_1_asm_00mini__20250103_a0001_asm_1_as_asm_1_1_30_gr_2202_asm_1_asm_1_1_30_gr_2202_asm_fl46blw10_48v_5n_m_de_2__fl46blw10_48v_5n_m_de_material"/>
              <!-- Part 0001755652_00mini_000_asm_1_asm_1_asm_00mini__20250103_a0001_asm_1_as_asm_1_1_30_gr_2202_asm_1_asm_1_1_30_gr_2202_asm_fl46blw10_48v_5n_m_de_2__fl46blw10_48v_5n_m_de_2 -->
              <geom type="mesh" class="visual" pos="-0.0368689 -0.0321937 0.024" quat="5.00613e-14 -0.488996 -0.872286 1.38802e-13" mesh="0001755652_00mini_000_asm_1_asm_1_asm_00mini__20250103_a0001_asm_1_as_asm_1_1_30_gr_2202_asm_1_asm_1_1_30_gr_2202_asm_fl46blw10_48v_5n_m_de_2__fl46blw10_48v_5n_m_de" material="0001755652_00mini_000_asm_1_asm_1_asm_00mini__20250103_a0001_asm_1_as_asm_1_1_30_gr_2202_asm_1_asm_1_1_30_gr_2202_asm_fl46blw10_48v_5n_m_de_2__fl46blw10_48v_5n_m_de_material"/>
              <!-- Part 6706__300001_1_1_00mini_000_asm_1_asm_1_asm_00mini__20250103_a0001_asm_1_as_asm_1_1_30_gr_2202_asm_1_asm_1_1_30_gr_2202_asm_fl46blw10_48v_5n_m_de_2__fl46blw10_48v_5n_m_de_2 -->
              <geom type="mesh" class="visual" pos="-0.0452137 -0.0276536 0.0205" quat="5.00613e-14 -0.488996 -0.872286 1.38802e-13" mesh="6706__300001_1_1_00mini_000_asm_1_asm_1_asm_00mini__20250103_a0001_asm_1_as_asm_1_1_30_gr_2202_asm_1_asm_1_1_30_gr_2202_asm_fl46blw10_48v_5n_m_de_2__fl46blw10_48v_5n_m_de" material="6706__300001_1_1_00mini_000_asm_1_asm_1_asm_00mini__20250103_a0001_asm_1_as_asm_1_1_30_gr_2202_asm_1_asm_1_1_30_gr_2202_asm_fl46blw10_48v_5n_m_de_2__fl46blw10_48v_5n_m_de_material"/>
              <!-- Part 0001755650_00mini_000_asm_1_asm_1_asm_00mini__20250103_a0001_asm_1_as_asm_1_1_30_gr_2202_asm_1_asm_1_1_30_gr_2202_asm_fl46blw10_48v_5n_m_de_2__fl46blw10_48v_5n_m_de_2 -->
              <geom type="mesh" class="visual" pos="-0.0452137 -0.0276536 0.0209" quat="5.00613e-14 -0.488996 -0.872286 1.38802e-13" mesh="0001755650_00mini_000_asm_1_asm_1_asm_00mini__20250103_a0001_asm_1_as_asm_1_1_30_gr_2202_asm_1_asm_1_1_30_gr_2202_asm_fl46blw10_48v_5n_m_de_2__fl46blw10_48v_5n_m_de" material="0001755650_00mini_000_asm_1_asm_1_asm_00mini__20250103_a0001_asm_1_as_asm_1_1_30_gr_2202_asm_1_asm_1_1_30_gr_2202_asm_fl46blw10_48v_5n_m_de_2__fl46blw10_48v_5n_m_de_material"/>
              <!-- Link ankle_subassembly -->
              <body name="ankle_subassembly" pos="-0.221803 -0.135659 0.02" quat="1.9255e-14 -0.835223 -0.549911 1.06625e-14">
                <!-- Joint from shin_subassembly to ankle_subassembly -->
                <joint axis="0 0 1" name="ankley_right" type="hinge"/>
                <inertial pos="-1.62086e-08 -0.000727483 0.02" mass="0.0168168" fullinertia="5.19458e-06 4.86353e-06 8.35665e-07 2.61119e-12 4.35145e-12 -7.24871e-13"/>
                <!-- Part hex_socket_head_cap_screw_m2_5x0_45_x_6__ec244025d76f8b83b2775022a2cb3232_7 -->
                <!-- Part 07534_05x40_catpart_2 -->
                <geom type="mesh" class="visual" pos="1.66533e-15 0.0249999 0.02" quat="2.53512e-14 -0.707107 0.707107 5.19202e-16" mesh="07534_05x40_catpart" material="07534_05x40_catpart_material"/>
                <!-- Part ujoint -->
                <geom type="mesh" class="visual" pos="-7.77156e-16 2.46331e-16 0.02" quat="1.40018e-14 0.707107 5.54001e-14 -0.707107" mesh="ujoint" material="ujoint_material"/>
                <!-- Part hex_socket_head_cap_screw_m2_5x0_45_x_6__ec244025d76f8b83b2775022a2cb3232_8 -->
                <!-- Part spacer_ujoint -->
                <geom type="mesh" class="visual" pos="-1.22125e-15 -1.249e-16 0.02" quat="0.714619 -3.01541e-15 -0.699514 -3.53537e-15" mesh="spacer_ujoint" material="spacer_ujoint_material"/>
                <!-- Part hex_thin_nut_grade_a___b_m4x0_7__a8228d9ce5dcc05f24da0a2f74d882f3_4 -->
                <geom type="mesh" class="visual" pos="3.03091e-14 -0.02204 0.02" quat="0.505312 -0.505312 -0.494631 -0.494631" mesh="hex_thin_nut_grade_a___b_m4x0_7__a8228d9ce5dcc05f24da0a2f74d882f3" material="hex_thin_nut_grade_a___b_m4x0_7__a8228d9ce5dcc05f24da0a2f74d882f3_material"/>
                <!-- Part part_3_2 -->
                <geom type="mesh" class="visual" pos="2.10942e-15 -4.01762e-15 0.0195" quat="1.4945e-14 0.707107 5.65104e-14 -0.707107" mesh="part_3" material="part_3_material"/>
                <!-- Part bearing_5_16_5_3 -->
                <geom type="mesh" class="visual" pos="-5.44009e-15 -0.01594 0.02" quat="0.714619 -2.65206e-14 -0.699514 3.72445e-15" mesh="bearing_5_16_5" material="bearing_5_16_5_material"/>
                <!-- Part bearing_15_21_4_6 -->
                <geom type="mesh" class="visual" pos="0 0 0" quat="0.707107 0.707107 -0 -9.24202e-31" mesh="bearing_15_21_4" material="bearing_15_21_4_material"/>
                <!-- Part hex_socket_head_cap_screw_m2_5x0_45_x_6__ec244025d76f8b83b2775022a2cb3232_9 -->
                <!-- Part hex_socket_head_cap_screw_m2_5x0_45_x_6__ec244025d76f8b83b2775022a2cb3232_10 -->
                <!-- Part part_3_3 -->
                <geom type="mesh" class="visual" pos="2.55351e-15 -6.38378e-16 0.0205" quat="8.07281e-14 -0.707107 -5.21805e-15 -0.707107" mesh="part_3" material="part_3_material"/>
                <!-- Part hex_socket_head_cap_screw_m2_5x0_45_x_6__ec244025d76f8b83b2775022a2cb3232_11 -->
                <!-- Part hex_socket_head_cap_screw_m2_5x0_45_x_6__ec244025d76f8b83b2775022a2cb3232_12 -->
                <!-- Part bearing_5_16_5_4 -->
                <geom type="mesh" class="visual" pos="-6.99441e-15 0.0209456 0.02" quat="0.00732917 5.32405e-14 0.999973 -3.56035e-14" mesh="bearing_5_16_5" material="bearing_5_16_5_material"/>
                <!-- Part spacer_ujoint_2 -->
                <geom type="mesh" class="visual" pos="-6.66134e-15 5.64895e-06 0.02" quat="4.09903e-15 0.71227 -2.69784e-14 -0.701905" mesh="spacer_ujoint" material="spacer_ujoint_material"/>
                <!-- Part bearing_15_21_4_7 -->
                <geom type="mesh" class="visual" pos="7.77156e-16 1.87697e-15 0.04" quat="4.996e-16 5.26641e-16 0.707107 -0.707107" mesh="bearing_15_21_4" material="bearing_15_21_4_material"/>
                <!-- Link foot_subassembly -->
                <body name="foot_subassembly" pos="-5.55112e-15 -0.01594 0.02" quat="0.5 0.5 0.5 -0.5">
                  <!-- Joint from ankle_subassembly to foot_subassembly -->
                  <joint axis="0 0 1" name="anklex_right" type="hinge"/>
                  <inertial pos="8.52312e-09 -0.0138418 -0.052232" mass="0.122498" fullinertia="0.000163413 0.000162266 7.07692e-05 -1.15065e-10 -2.96383e-11 1.11374e-05"/>
                  <!-- Part hex_socket_head_cap_screw_m2_5x0_45_x_6__ec244025d76f8b83b2775022a2cb3232_13 -->
                  <!-- Part 27628_01_050_catpart_3 -->
                  <geom type="mesh" class="visual" pos="0.021 3.53792e-08 -0.0660002" quat="3.72484e-16 0.707107 0.707107 -4.65708e-16" mesh="27628_01_050_catpart" material="27628_01_050_catpart_material"/>
                  <!-- Part hex_socket_head_cap_screw_m2_5x0_45_x_6__ec244025d76f8b83b2775022a2cb3232_14 -->
                  <!-- Part 07534_05x20_catpart_3 -->
                  <geom type="mesh" class="visual" pos="0.036 1.11022e-16 -0.066" quat="3.33067e-16 1.89593e-15 -1 1.94289e-15" mesh="07534_05x20_catpart" material="07534_05x20_catpart_material"/>
                  <!-- Part 27628_01_050_catpart_4 -->
                  <geom type="mesh" class="visual" pos="-0.021 -1.89504e-08 -0.066" quat="7.03828e-18 0.707107 0.707107 2.43354e-16" mesh="27628_01_050_catpart" material="27628_01_050_catpart_material"/>
                  <!-- Part 07534_05x20_catpart_4 -->
                  <geom type="mesh" class="visual" pos="-0.036 2.22045e-16 -0.066" quat="1 -2.47817e-15 1.11022e-16 -1.17961e-15" mesh="07534_05x20_catpart" material="07534_05x20_catpart_material"/>
                  <!-- Part hat_small -->
                  <geom type="mesh" class="visual" pos="4.71845e-16 -0.035 -0.0385" quat="0.5 -0.5 -0.5 -0.5" mesh="hat_small" material="hat_small_material"/>
                  <!-- Part hex_socket_head_cap_screw_m2_5x0_45_x_6__ec244025d76f8b83b2775022a2cb3232_15 -->
                  <!-- Part foot -->
                  <geom type="mesh" class="visual" pos="1.11022e-16 -0.035 -0.0385" quat="0.5 -0.5 -0.5 -0.5" mesh="foot" material="foot_material"/>
                  <geom name="right_foot1_collision" class="collision" type="capsule" size="0.015 0.05" fromto="-0.032 -0.02 0.005 0.032 -0.02 0.005"/>
                  <geom name="right_foot2_collision" class="collision" type="capsule" size="0.015 0.05" fromto="-0.032 -0.02 -0.10 0.032 -0.02 -0.10"/>
                  <geom name="right_foot3_collision" class="collision" type="capsule" size="0.015 0.05" fromto="-0.032 -0.02 0.005 -0.032 -0.02 -0.10"/>
                  <geom name="right_foot4_collision" class="collision" type="capsule" size="0.015 0.05" fromto="0.032 -0.02 0.005 0.032 -0.02 -0.10"/>
                  <geom name="right_foot5_collision" class="collision" type="capsule" size="0.015 0.05" fromto="-0.032 -0.02 -0.02 0.032 -0.02 -0.02"/>
                  <geom name="right_foot6_collision" class="collision" type="capsule" size="0.015 0.05" fromto="-0.032 -0.02 -0.06 0.032 -0.02 -0.06"/>
                  <!-- Frame foot_right -->
                  <site group="3" name="foot_right" pos="-6.35351e-08 -0.035 -0.0480606" quat="0.5 -0.5 0.5 0.5"/>
                </body>
              </body>
            </body>
          </body>
        </body>
      </body>
      <!-- Link hipx_subassemby_sym -->
      <body name="hipx_subassemby_sym" pos="-0.000819037 0.13316 0.04164" quat="0.826605 -0.0574675 0.0409288 0.558343">
        <!-- Joint from torso_subassembly to hipx_subassemby_sym -->
        <joint axis="0 0 1" name="hipz_left" type="hinge"/>
        <inertial pos="-0.0179432 0.0274245 -0.0837272" mass="0.794016" fullinertia="0.00093784 0.000903443 0.00100402 4.40289e-05 -0.000110464 0.000168604"/>
        <!-- Part rs02_2 -->
        <!-- Part hex_socket_head_cap_screw_m4x0_70_x_40__14321d45d56569246e7feb4574a6bae6_15 -->
        <!-- Part robstride02_2 -->
        <geom type="mesh" class="visual" pos="-0.575896 0.057308 -0.20175" quat="0.60316 -0.792908 -0.0689068 -0.0524169" mesh="robstride02" material="robstride02_material"/>
        <!-- Part hex_socket_head_cap_screw_m3x0_50_x_8__d566997e1880d7fd3377c5b0ee12206c_28 -->
        <!-- Part hex_socket_head_cap_screw_m3x0_50_x_8__d566997e1880d7fd3377c5b0ee12206c_29 -->
        <!-- Part hex_socket_head_cap_screw_m3x0_50_x_8__d566997e1880d7fd3377c5b0ee12206c_30 -->
        <!-- Part hex_socket_head_cap_screw_m3x0_50_x_8__d566997e1880d7fd3377c5b0ee12206c_31 -->
        <!-- Part hipz22_sym -->
        <geom type="mesh" class="visual" pos="5.55112e-17 0 0.1" quat="1 -0 -1.38778e-17 1.82905e-16" mesh="hipz22_sym" material="hipz22_sym_material"/>
        <!-- Part hex_socket_head_cap_screw_m4x0_70_x_40__14321d45d56569246e7feb4574a6bae6_16 -->
        <!-- Part hipz12_sym -->
        <geom type="mesh" class="visual" pos="2.08167e-16 -2.08167e-17 0.1" quat="1 1.25831e-16 2.22045e-16 1.11022e-16" mesh="hipz12_sym" material="hipz12_sym_material"/>
        <!-- Part xt_30_2x2_f_5 -->
        <geom type="mesh" class="visual" pos="-0.0280156 0.0769561 -0.0718124" quat="0.498768 0.406175 -0.443127 0.624413" mesh="xt_30_2x2_f" material="xt_30_2x2_f_material"/>
        <!-- Part hex_socket_head_cap_screw_m3x0_50_x_8__d566997e1880d7fd3377c5b0ee12206c_32 -->
        <!-- Part hex_socket_head_cap_screw_m3x0_50_x_8__d566997e1880d7fd3377c5b0ee12206c_33 -->
        <!-- Part hex_socket_head_cap_screw_m3x0_50_x_8__d566997e1880d7fd3377c5b0ee12206c_34 -->
        <!-- Part hex_socket_head_cap_screw_m4x0_70_x_40__14321d45d56569246e7feb4574a6bae6_17 -->
        <!-- Part hex_socket_head_cap_screw_m3x0_50_x_8__d566997e1880d7fd3377c5b0ee12206c_35 -->
        <!-- Part hex_socket_head_cap_screw_m4x0_70_x_40__14321d45d56569246e7feb4574a6bae6_18 -->
        <!-- Part hex_socket_head_cap_screw_m4x0_70_x_40__14321d45d56569246e7feb4574a6bae6_19 -->
        <!-- Part hex_socket_head_cap_screw_m4x0_70_x_40__14321d45d56569246e7feb4574a6bae6_20 -->
        <!-- Part hex_socket_head_cap_screw_m3x0_50_x_8__d566997e1880d7fd3377c5b0ee12206c_36 -->
        <!-- Part hex_socket_head_cap_screw_m4x0_70_x_40__14321d45d56569246e7feb4574a6bae6_21 -->
        <!-- Part hex_socket_head_cap_screw_m3x0_50_x_8__d566997e1880d7fd3377c5b0ee12206c_37 -->
        <!-- Part hex_socket_head_cap_screw_m3x0_50_x_8__d566997e1880d7fd3377c5b0ee12206c_38 -->
        <!-- Part hex_socket_head_cap_screw_m4x0_70_x_40__14321d45d56569246e7feb4574a6bae6_22 -->
        <!-- Part bearing_35_72_17_4 -->
        <geom type="mesh" class="visual" pos="-0.01759 0.0267968 -0.104484" quat="0.792908 0.60316 -0.0524169 0.0689068" mesh="bearing_35_72_17" material="bearing_35_72_17_material"/>
        <!-- Part hex_socket_head_cap_screw_m3x0_50_x_8__d566997e1880d7fd3377c5b0ee12206c_39 -->
        <!-- Part hex_socket_head_cap_screw_m4x0_70_x_40__14321d45d56569246e7feb4574a6bae6_23 -->
        <!-- Part hex_socket_head_cap_screw_m3x0_50_x_8__d566997e1880d7fd3377c5b0ee12206c_40 -->
        <!-- Part hex_socket_head_cap_screw_m3x0_50_x_8__d566997e1880d7fd3377c5b0ee12206c_41 -->
        <!-- Part hex_socket_head_cap_screw_m4x0_70_x_40__14321d45d56569246e7feb4574a6bae6_24 -->
        <!-- Part hex_socket_head_cap_screw_m3x0_50_x_8__d566997e1880d7fd3377c5b0ee12206c_42 -->
        <!-- Link hipy_subassembly_sym -->
        <body name="hipy_subassembly_sym" pos="-0.01897 0.0289 -0.09689" quat="0.378583 -0.131748 0.089467 0.911764">
          <!-- Joint from hipx_subassemby_sym to hipy_subassembly_sym -->
          <joint axis="0 0 1" name="hipx_left" type="hinge"/>
          <inertial pos="0.0047654 0.00266393 -0.0607296" mass="0.241619" fullinertia="0.000504046 0.000455768 0.000428972 -2.43365e-05 7.8493e-06 3.61482e-05"/>
          <!-- Part hex_socket_head_cap_screw_m4x0_70_x_12__c825518ee8edf1afced0eee1b019b750_11 -->
          <!-- Part hex_socket_head_cap_screw_m4x0_70_x_12__c825518ee8edf1afced0eee1b019b750_12 -->
          <!-- Part hex_socket_head_cap_screw_m4x0_70_x_12__c825518ee8edf1afced0eee1b019b750_13 -->
          <!-- Part hex_socket_head_cap_screw_m4x0_70_x_12__c825518ee8edf1afced0eee1b019b750_14 -->
          <!-- Part hex_socket_head_cap_screw_m4x0_70_x_20__832e47d784177ea3f1dabbaab534416e_23 -->
          <!-- Part hex_socket_head_cap_screw_m4x0_70_x_20__832e47d784177ea3f1dabbaab534416e_24 -->
          <!-- Part hipxy_sym -->
          <geom type="mesh" class="visual" pos="-2.34188e-17 -2.77556e-17 6.93889e-18" quat="0 1 0 0" mesh="hipxy_sym" material="hipxy_sym_material"/>
          <!-- Part hex_socket_head_cap_screw_m4x0_70_x_12__c825518ee8edf1afced0eee1b019b750_15 -->
          <!-- Part hex_socket_head_cap_screw_m4x0_70_x_20__832e47d784177ea3f1dabbaab534416e_25 -->
          <!-- Part hex_socket_head_cap_screw_m4x0_70_x_12__c825518ee8edf1afced0eee1b019b750_16 -->
          <!-- Part hex_socket_head_cap_screw_m4x0_70_x_20__832e47d784177ea3f1dabbaab534416e_26 -->
          <!-- Part hex_socket_head_cap_screw_m4x0_70_x_20__832e47d784177ea3f1dabbaab534416e_27 -->
          <!-- Part hex_socket_head_cap_screw_m4x0_70_x_20__832e47d784177ea3f1dabbaab534416e_28 -->
          <!-- Link tigh_subassembly_sym -->
          <body name="tigh_subassembly_sym" pos="0.012638 0.0276823 -0.112055" quat="0.0583173 -0.358702 -0.636384 -0.680402">
            <!-- Joint from hipy_subassembly_sym to tigh_subassembly_sym -->
            <joint axis="0 0 1" name="hipy_left" type="hinge"/>
            <inertial pos="-0.0431321 -0.0830741 -0.0353867" mass="2.5804" fullinertia="0.0180602 0.00826187 0.0238429 -0.00802639 -0.00087206 -0.00158484"/>
            <!-- Part knee_rod22_sym -->
            <geom type="mesh" class="visual" pos="-0.058 -0.280519 0.0295" quat="0.707107 -0.707107 3.77476e-15 2.17998e-15" mesh="knee_rod22_sym" material="knee_rod22_sym_material"/>
            <!-- Part hex_socket_head_cap_screw_m4x0_70_x_16__8d628c0d7a90368385b1c4c7479647eb_7 -->
            <!-- Part hex_socket_head_cap_screw_m2_5x0_45_x_6__ec244025d76f8b83b2775022a2cb3232_16 -->
            <!-- Part hex_socket_head_cap_screw_m4x0_70_x_8__a416dc2a8d778a4ef6150c0739aa89d1_15 -->
            <!-- Part hex_socket_head_cap_screw_m4x0_70_x_8__a416dc2a8d778a4ef6150c0739aa89d1_16 -->
            <!-- Part hex_socket_head_cap_screw_m4x0_70_x_8__a416dc2a8d778a4ef6150c0739aa89d1_17 -->
            <!-- Part hex_socket_head_cap_screw_m2_5x0_45_x_6__ec244025d76f8b83b2775022a2cb3232_17 -->
            <!-- Part hex_socket_head_cap_screw_m4x0_70_x_16__8d628c0d7a90368385b1c4c7479647eb_8 -->
            <!-- Part hex_socket_head_cap_screw_m4x0_70_x_40__14321d45d56569246e7feb4574a6bae6_25 -->
            <!-- Part hex_socket_head_cap_screw_m4x0_70_x_8__a416dc2a8d778a4ef6150c0739aa89d1_18 -->
            <!-- Part hex_socket_head_cap_screw_m4x0_70_x_8__a416dc2a8d778a4ef6150c0739aa89d1_19 -->
            <!-- Part hex_socket_head_cap_screw_m4x0_70_x_8__a416dc2a8d778a4ef6150c0739aa89d1_20 -->
            <!-- Part hex_socket_head_cap_screw_m4x0_70_x_16__8d628c0d7a90368385b1c4c7479647eb_9 -->
            <!-- Part bearing_15_21_4_8 -->
            <geom type="mesh" class="visual" pos="-0.221927 -0.268257 -0.0185" quat="0.5 -0.5 -0.5 0.5" mesh="bearing_15_21_4" material="bearing_15_21_4_material"/>
            <!-- Part part_3_4 -->
            <geom type="mesh" class="visual" pos="-2.55351e-15 5.03764e-15 -0.0938" quat="0.683013 0.183013 0.683013 -0.183013" mesh="part_3" material="part_3_material"/>
            <!-- Part bearing_15_21_4_9 -->
            <geom type="mesh" class="visual" pos="-0.102915 -0.0784891 -0.0245" quat="0.707107 -0.707107 3.88578e-15 2.57215e-15" mesh="bearing_15_21_4" material="bearing_15_21_4_material"/>
            <!-- Part hex_socket_head_cap_screw_m4x0_70_x_40__14321d45d56569246e7feb4574a6bae6_26 -->
            <!-- Part hex_socket_head_cap_screw_m4x0_70_x_8__a416dc2a8d778a4ef6150c0739aa89d1_21 -->
            <!-- Part bearing_15_21_4_10 -->
            <geom type="mesh" class="visual" pos="-2.96985e-15 3.4972e-15 -0.0675" quat="0.183013 -0.183013 -0.683013 0.683013" mesh="bearing_15_21_4" material="bearing_15_21_4_material"/>
            <!-- Part bearing_15_21_4_11 -->
            <geom type="mesh" class="visual" pos="-0.102915 -0.0784891 -0.0365" quat="0.707107 0.707107 1.9984e-15 -3.61558e-15" mesh="bearing_15_21_4" material="bearing_15_21_4_material"/>
            <!-- Part bearing_15_21_4_12 -->
            <geom type="mesh" class="visual" pos="-0.221927 -0.268257 -0.0465" quat="0.5 -0.5 -0.5 0.5" mesh="bearing_15_21_4" material="bearing_15_21_4_material"/>
            <!-- Part hex_socket_head_cap_screw_m2_5x0_45_x_6__ec244025d76f8b83b2775022a2cb3232_18 -->
            <!-- Part hex_socket_head_cap_screw_m4x0_70_x_16__8d628c0d7a90368385b1c4c7479647eb_10 -->
            <!-- Part hex_socket_head_cap_screw_m4x0_70_x_8__a416dc2a8d778a4ef6150c0739aa89d1_22 -->
            <!-- Part hex_socket_head_cap_screw_m4x0_70_x_40__14321d45d56569246e7feb4574a6bae6_27 -->
            <!-- Part femur_12_sym -->
            <geom type="mesh" class="visual" pos="-0.17 -0.294449 0.0295" quat="0.683013 -0.683013 0.183013 -0.183013" mesh="femur_12_sym" material="femur_12_sym_material"/>
            <geom name="femur_12_sym_collision" type="capsule" size="0.05 0.18" class="collision" pos="-0.17 -0.294449 0.0295" quat="0.683013 -0.683013 0.183013 -0.183013"/>
            <!-- Part bearing_5_16_5_5 -->
            <geom type="mesh" class="visual" pos="-0.17 -0.294449 -0.045" quat="0.183013 0.183013 0.683013 0.683013" mesh="bearing_5_16_5" material="bearing_5_16_5_material"/>
            <!-- Part hex_socket_head_cap_screw_m3x0_50_x_10__9c80fcbba574884e63b580474e1ee150_28 -->
            <!-- Part hex_socket_head_cap_screw_m4x0_70_x_40__14321d45d56569246e7feb4574a6bae6_28 -->
            <!-- Part hex_socket_head_cap_screw_m4x0_70_x_16__8d628c0d7a90368385b1c4c7479647eb_11 -->
            <!-- Part hex_socket_head_cap_screw_m2_5x0_45_x_6__ec244025d76f8b83b2775022a2cb3232_19 -->
            <!-- Part hex_socket_head_cap_screw_m4x0_70_x_8__a416dc2a8d778a4ef6150c0739aa89d1_23 -->
            <!-- Part hex_socket_head_cap_screw_m2_5x0_45_x_6__ec244025d76f8b83b2775022a2cb3232_20 -->
            <!-- Part hex_socket_head_cap_screw_m4x0_70_x_16__8d628c0d7a90368385b1c4c7479647eb_12 -->
            <!-- Part knee_actuation_2 -->
            <geom type="mesh" class="visual" pos="-0.058 0.123541 -0.0305" quat="0.707107 0.707107 2.10942e-15 -3.85312e-15" mesh="knee_actuation" material="knee_actuation_material"/>
            <!-- Part femur_22_sym -->
            <geom type="mesh" class="visual" pos="-0.17 -0.294449 0.0295" quat="0.683013 -0.683013 0.183013 -0.183013" mesh="femur_22_sym" material="femur_22_sym_material"/>
            <!-- Part hat_femur_2 -->
            <geom type="mesh" class="visual" pos="-0.17 -0.294449 -0.0305" quat="0.183013 0.183013 0.683013 0.683013" mesh="hat_femur" material="hat_femur_material"/>
            <!-- Part hex_socket_head_cap_screw_m4x0_70_x_8__a416dc2a8d778a4ef6150c0739aa89d1_24 -->
            <!-- Part hex_socket_head_cap_screw_m3x0_50_x_10__9c80fcbba574884e63b580474e1ee150_29 -->
            <!-- Part bearing_5_16_5_6 -->
            <geom type="mesh" class="visual" pos="-0.17 -0.294449 -0.013" quat="0.183013 -0.183013 -0.683013 0.683013" mesh="bearing_5_16_5" material="bearing_5_16_5_material"/>
            <!-- Part robstrideo3_3 -->
            <geom type="mesh" class="visual" pos="0.655402 -0.194111 -0.0025" quat="0.183013 0.183013 0.683013 0.683013" mesh="robstrideo3" material="robstrideo3_material"/>
            <!-- Part hex_socket_head_cap_screw_m4x0_70_x_8__a416dc2a8d778a4ef6150c0739aa89d1_25 -->
            <!-- Part hex_socket_head_cap_screw_m4x0_70_x_8__a416dc2a8d778a4ef6150c0739aa89d1_26 -->
            <!-- Part hex_socket_head_cap_screw_m4x0_70_x_8__a416dc2a8d778a4ef6150c0739aa89d1_27 -->
            <!-- Part knee_rod12_sym -->
            <geom type="mesh" class="visual" pos="-0.058 -0.280519 0.0295" quat="0.707107 -0.707107 3.88578e-15 2.14635e-15" mesh="knee_rod12_sym" material="knee_rod12_sym_material"/>
            <!-- Part hex_socket_head_cap_screw_m3x0_50_x_10__9c80fcbba574884e63b580474e1ee150_30 -->
            <!-- Part hex_socket_head_cap_screw_m2_5x0_45_x_6__ec244025d76f8b83b2775022a2cb3232_21 -->
            <!-- Part hex_socket_head_cap_screw_m4x0_70_x_8__a416dc2a8d778a4ef6150c0739aa89d1_28 -->
            <!-- Part robstrideo3_4 -->
            <geom type="mesh" class="visual" pos="0.597402 -0.29457 -0.045" quat="0.183013 0.183013 0.683013 0.683013" mesh="robstrideo3" material="robstrideo3_material"/>
            <!-- Part 1_1_31_qt_942_1_3 -->
            <geom type="mesh" class="visual" pos="-4.03844e-15 2.27596e-15 -0.04" quat="0.5 2.01683e-14 -9.76996e-15 -0.866025" mesh="1_1_31_qt_942_1" material="1_1_31_qt_942_1_material"/>
            <!-- Part 1_1_06_eb903_538_1_3 -->
            <geom type="mesh" class="visual" pos="-3.6221e-15 3.44169e-15 -0.0566" quat="0.5 2.01683e-14 -9.76996e-15 -0.866025" mesh="1_1_06_eb903_538_1" material="1_1_06_eb903_538_1_material"/>
            <!-- Part 1_1_31_qt_942_1_4 -->
            <geom type="mesh" class="visual" pos="-0.058 -0.100459 -0.0825" quat="0.965926 1.61125e-13 -5.41789e-14 -0.258819" mesh="1_1_31_qt_942_1" material="1_1_31_qt_942_1_material"/>
            <!-- Part 1_1_06_eb903_538_1_4 -->
            <geom type="mesh" class="visual" pos="-0.058 -0.100459 -0.0991" quat="0.965926 1.61125e-13 -5.41789e-14 -0.258819" mesh="1_1_06_eb903_538_1" material="1_1_06_eb903_538_1_material"/>
            <!-- Part 1_1_06_eb903_537_af0_1_3 -->
            <geom type="mesh" class="visual" pos="-3.42781e-15 1.72085e-15 -0.0375" quat="0.965926 3.06327e-14 -2.22045e-16 -0.258819" mesh="1_1_06_eb903_537_af0_1" material="1_1_06_eb903_537_af0_1_material"/>
            <!-- Part 1_1_02_eb901_558_1_3 -->
            <geom type="mesh" class="visual" pos="1.38778e-17 -1.38778e-17 -1.38778e-17" quat="0 1 0 0" mesh="1_1_02_eb901_558_1" material="1_1_02_eb901_558_1_material"/>
            <!-- Part 1_1_06_eb903_537_af0_1_4 -->
            <geom type="mesh" class="visual" pos="-0.058 -0.100459 -0.08" quat="0.866025 2.1389e-14 -2.19824e-14 0.5" mesh="1_1_06_eb903_537_af0_1" material="1_1_06_eb903_537_af0_1_material"/>
            <!-- Part 1_1_02_eb901_558_1_4 -->
            <geom type="mesh" class="visual" pos="-0.058 -0.100459 -0.0425" quat="1.51113e-14 -0.707107 -0.707107 -9.01995e-15" mesh="1_1_02_eb901_558_1" material="1_1_02_eb901_558_1_material"/>
            <!-- Link shin_subassembly_sym -->
            <body name="shin_subassembly_sym" pos="-0.17 -0.294449 -0.0305" quat="0.723237 3.88595e-16 -3.33067e-16 -0.6906">
              <!-- Joint from tigh_subassembly_sym to shin_subassembly_sym -->
              <joint axis="0 0 1" name="knee_left" type="hinge"/>
              <inertial pos="0.00133174 -0.0908013 -1.51262e-05" mass="0.593266" fullinertia="0.00173882 0.000241815 0.00176032 -5.54293e-05 2.67934e-06 9.5357e-05"/>
              <!-- Part hex_socket_head_cap_screw_m3x0_50_x_20__7252065e4445f5ec71347b53fcae11e4_13 -->
              <!-- Part xt_30_2x2_f_6 -->
              <geom type="mesh" class="visual" pos="0.0212074 -0.0322876 0.0147" quat="0.270598 0.653281 0.270598 -0.653281" mesh="xt_30_2x2_f" material="xt_30_2x2_f_material"/>
              <!-- Part hex_socket_head_cap_screw_m3x0_50_x_20__7252065e4445f5ec71347b53fcae11e4_14 -->
              <!-- Part hex_socket_head_cap_screw_m3x0_50_x_20__7252065e4445f5ec71347b53fcae11e4_15 -->
              <!-- Part hex_socket_head_cap_screw_m3x0_50_x_10__9c80fcbba574884e63b580474e1ee150_31 -->
              <!-- Part 27628_01_050_catpart_5 -->
              <geom type="mesh" class="visual" pos="0.0300907 -0.0130682 -0.0195" quat="0.650205 0.650205 0.277908 0.277908" mesh="27628_01_050_catpart" material="27628_01_050_catpart_material"/>
              <!-- Part hex_socket_head_cap_screw_m3x0_50_x_20__7252065e4445f5ec71347b53fcae11e4_16 -->
              <!-- Part hex_socket_head_cap_screw_m3x0_50_x_30__cb22dc4460edbee8e1cbddf29677c00f_2 -->
              <!-- Part hex_socket_head_cap_screw_m3x0_50_x_10__9c80fcbba574884e63b580474e1ee150_32 -->
              <!-- Part hex_socket_head_cap_screw_m3x0_50_x_10__9c80fcbba574884e63b580474e1ee150_33 -->
              <!-- Part 07534_05x40_catpart_3 -->
              <geom type="mesh" class="visual" pos="5.55112e-17 -5.55112e-17 -0.025" quat="0.5 -0.5 -0.5 -0.5" mesh="07534_05x40_catpart" material="07534_05x40_catpart_material"/>
              <!-- Part hex_socket_head_cap_screw_m3x0_50_x_10__9c80fcbba574884e63b580474e1ee150_34 -->
              <!-- Part hex_socket_head_cap_screw_m3x0_50_x_10__9c80fcbba574884e63b580474e1ee150_35 -->
              <!-- Part hex_socket_head_cap_screw_m3x0_50_x_10__9c80fcbba574884e63b580474e1ee150_36 -->
              <!-- Part hex_socket_head_cap_screw_m3x0_50_x_10__9c80fcbba574884e63b580474e1ee150_37 -->
              <!-- Part hex_socket_head_cap_screw_m3x0_50_x_20__7252065e4445f5ec71347b53fcae11e4_17 -->
              <!-- Part 07534_05x20_catpart_5 -->
              <geom type="mesh" class="visual" pos="0.0300908 -0.0660682 0.0405" quat="0.632814 -0.315509 0.632814 0.315509" mesh="07534_05x20_catpart" material="07534_05x20_catpart_material"/>
              <!-- Part tibias12_sym -->
              <geom type="mesh" class="visual" pos="-2.77556e-16 -0.26 0.067" quat="0.707107 -0.707107 3.33067e-16 8.58655e-17" mesh="tibias12_sym" material="tibias12_sym_material"/>
              <!-- Part hex_socket_head_cap_screw_m2_5x0_45_x_8__dec2226ceabd7d7ca0bb403ec234d89b_4 -->
              <!-- Part actuation_ankle_3 -->
              <geom type="mesh" class="visual" pos="0.12299 -0.14568 0.0195" quat="0.632814 -0.632814 -0.315509 0.315509" mesh="actuation_ankle" material="actuation_ankle_material"/>
              <!-- Part hex_socket_head_cap_screw_m3x0_50_x_20__7252065e4445f5ec71347b53fcae11e4_18 -->
              <!-- Part hex_socket_head_cap_screw_m3x0_50_x_10__9c80fcbba574884e63b580474e1ee150_38 -->
              <!-- Part hex_socket_head_cap_screw_m3x0_50_x_10__9c80fcbba574884e63b580474e1ee150_39 -->
              <!-- Part hex_thin_nut_grade_a___b_m4x0_7__a8228d9ce5dcc05f24da0a2f74d882f3_5 -->
              <geom type="mesh" class="visual" pos="0.0300908 -0.0660682 0.0129398" quat="4.59953e-16 0.317305 0.948324 6.76383e-16" mesh="hex_thin_nut_grade_a___b_m4x0_7__a8228d9ce5dcc05f24da0a2f74d882f3" material="hex_thin_nut_grade_a___b_m4x0_7__a8228d9ce5dcc05f24da0a2f74d882f3_material"/>
              <!-- Part hex_socket_head_cap_screw_m3x0_50_x_10__9c80fcbba574884e63b580474e1ee150_40 -->
              <!-- Part hex_socket_head_cap_screw_m3x0_50_x_20__7252065e4445f5ec71347b53fcae11e4_19 -->
              <!-- Part hex_socket_head_cap_screw_m3x0_50_x_20__7252065e4445f5ec71347b53fcae11e4_20 -->
              <!-- Part hex_socket_head_cap_screw_m3x0_50_x_10__9c80fcbba574884e63b580474e1ee150_41 -->
              <!-- Part rmdx43_3 -->
              <geom type="mesh" class="visual" pos="0.470217 -0.113201 -0.006" quat="3.33067e-16 -5.56494e-16 -0.707107 0.707107" mesh="rmdx43" material="rmdx43_material"/>
              <!-- Part hex_socket_head_cap_screw_m2_5x0_45_x_8__dec2226ceabd7d7ca0bb403ec234d89b_5 -->
              <!-- Part hex_socket_head_cap_screw_m4x0_70_x_12__c825518ee8edf1afced0eee1b019b750_17 -->
              <!-- Part hex_socket_head_cap_screw_m3x0_50_x_20__7252065e4445f5ec71347b53fcae11e4_21 -->
              <!-- Part hex_socket_head_cap_screw_m4x0_70_x_12__c825518ee8edf1afced0eee1b019b750_18 -->
              <!-- Part hex_socket_head_cap_screw_m3x0_50_x_10__9c80fcbba574884e63b580474e1ee150_42 -->
              <!-- Part hex_socket_head_cap_screw_m3x0_50_x_10__9c80fcbba574884e63b580474e1ee150_43 -->
              <!-- Part hex_socket_head_cap_screw_m3x0_50_x_10__9c80fcbba574884e63b580474e1ee150_44 -->
              <!-- Part hex_socket_head_cap_screw_m4x0_70_x_12__c825518ee8edf1afced0eee1b019b750_19 -->
              <!-- Part hex_socket_head_cap_screw_m3x0_50_x_20__7252065e4445f5ec71347b53fcae11e4_22 -->
              <!-- Part hex_socket_head_cap_screw_m3x0_50_x_10__9c80fcbba574884e63b580474e1ee150_45 -->
              <!-- Part hex_socket_head_cap_screw_m3x0_50_x_10__9c80fcbba574884e63b580474e1ee150_46 -->
              <!-- Part 07534_05x20_catpart_6 -->
              <geom type="mesh" class="visual" pos="0.0300908 -0.0130682 -0.0405" quat="0.632814 0.315509 -0.632814 0.315509" mesh="07534_05x20_catpart" material="07534_05x20_catpart_material"/>
              <!-- Part rmdx43_4 -->
              <geom type="mesh" class="visual" pos="0.470217 -0.0457991 0.006" quat="1.11022e-16 -1.07995e-15 -0.707107 -0.707107" mesh="rmdx43" material="rmdx43_material"/>
              <!-- Part tibias22_sym -->
              <geom type="mesh" class="visual" pos="-6.10623e-16 -0.26 0.067" quat="0.707107 -0.707107 2.22045e-16 -3.23259e-16" mesh="tibias22_sym" material="tibias22_sym_material"/>
              <!-- Part hex_socket_head_cap_screw_m3x0_50_x_20__7252065e4445f5ec71347b53fcae11e4_23 -->
              <!-- Part hex_socket_head_cap_screw_m4x0_70_x_12__c825518ee8edf1afced0eee1b019b750_20 -->
              <!-- Part hex_socket_head_cap_screw_m3x0_50_x_10__9c80fcbba574884e63b580474e1ee150_47 -->
              <!-- Part xt_30_2x2_f_7 -->
              <geom type="mesh" class="visual" pos="0.0212074 -0.126712 -0.015" quat="0.653281 -0.270598 -0.653281 -0.270598" mesh="xt_30_2x2_f" material="xt_30_2x2_f_material"/>
              <!-- Part hex_thin_nut_grade_a___b_m4x0_7__a8228d9ce5dcc05f24da0a2f74d882f3_6 -->
              <geom type="mesh" class="visual" pos="0 0 0.0247602" quat="7.77156e-16 -2.1427e-16 1 -2.72005e-15" mesh="hex_thin_nut_grade_a___b_m4x0_7__a8228d9ce5dcc05f24da0a2f74d882f3" material="hex_thin_nut_grade_a___b_m4x0_7__a8228d9ce5dcc05f24da0a2f74d882f3_material"/>
              <!-- Part hex_socket_head_cap_screw_m3x0_50_x_10__9c80fcbba574884e63b580474e1ee150_48 -->
              <!-- Part hex_socket_head_cap_screw_m3x0_50_x_10__9c80fcbba574884e63b580474e1ee150_49 -->
              <!-- Part actuation_ankle_4 -->
              <geom type="mesh" class="visual" pos="-0.12299 -0.0133205 -0.0195" quat="0.632814 0.632814 0.315509 0.315509" mesh="actuation_ankle" material="actuation_ankle_material"/>
              <!-- Part hex_socket_head_cap_screw_m3x0_50_x_10__9c80fcbba574884e63b580474e1ee150_50 -->
              <!-- Part hex_socket_head_cap_screw_m3x0_50_x_10__9c80fcbba574884e63b580474e1ee150_51 -->
              <!-- Part hex_socket_head_cap_screw_m3x0_50_x_10__9c80fcbba574884e63b580474e1ee150_52 -->
              <!-- Part hex_socket_head_cap_screw_m3x0_50_x_10__9c80fcbba574884e63b580474e1ee150_53 -->
              <!-- Part hex_socket_head_cap_screw_m3x0_50_x_20__7252065e4445f5ec71347b53fcae11e4_24 -->
              <!-- Part hat_big_2 -->
              <geom type="mesh" class="visual" pos="-4.44089e-16 -0.26 -0.019" quat="1.11022e-16 2.74951e-16 0.707107 0.707107" mesh="hat_big" material="hat_big_material"/>
              <!-- Part hex_socket_head_cap_screw_m2_5x0_45_x_8__dec2226ceabd7d7ca0bb403ec234d89b_6 -->
              <!-- Part 27628_01_050_catpart_6 -->
              <geom type="mesh" class="visual" pos="0.0300907 -0.066068 0.0225" quat="4.65505e-05 4.65505e-05 -0.707107 -0.707107" mesh="27628_01_050_catpart" material="27628_01_050_catpart_material"/>
              <!-- Part hex_socket_head_cap_screw_m3x0_50_x_10__9c80fcbba574884e63b580474e1ee150_54 -->
              <!-- Part hex_thin_nut_grade_a___b_m4x0_7__a8228d9ce5dcc05f24da0a2f74d882f3_7 -->
              <geom type="mesh" class="visual" pos="0.0300908 -0.0130682 -0.0129398" quat="0.317305 3.55471e-16 2.83662e-14 0.948324" mesh="hex_thin_nut_grade_a___b_m4x0_7__a8228d9ce5dcc05f24da0a2f74d882f3" material="hex_thin_nut_grade_a___b_m4x0_7__a8228d9ce5dcc05f24da0a2f74d882f3_material"/>
              <!-- Part 1_1_31_eb463_510_fl46blw10_48v_5n_m_de_2__fl46blw10_48v_5n_m_de_3 -->
              <geom type="mesh" class="visual" pos="-2.9976e-15 -0.106 0.019" quat="0.19509 -4.58168e-14 7.37188e-14 0.980785" mesh="1_1_31_eb463_510_fl46blw10_48v_5n_m_de_2__fl46blw10_48v_5n_m_de" material="1_1_31_eb463_510_fl46blw10_48v_5n_m_de_2__fl46blw10_48v_5n_m_de_material"/>
              <!-- Part 1_1_02_eb461_502_fl46blw10_48v_5n_m_de_2__fl46blw10_48v_5n_m_de_3 -->
              <geom type="mesh" class="visual" pos="-2.88658e-15 -0.106 0.009" quat="0.19509 -4.58168e-14 7.37188e-14 0.980785" mesh="1_1_02_eb461_502_fl46blw10_48v_5n_m_de_2__fl46blw10_48v_5n_m_de" material="1_1_02_eb461_502_fl46blw10_48v_5n_m_de_2__fl46blw10_48v_5n_m_de_material"/>
              <!-- Part 1_1_06_eb463_509_fl46blw10_48v_5n_m_de_2__fl46blw10_48v_5n_m_de_3 -->
              <geom type="mesh" class="visual" pos="-1.11022e-16 -0.106 -0.0225" quat="0.707107 -6.78323e-17 9.64506e-16 0.707107" mesh="1_1_06_eb463_509_fl46blw10_48v_5n_m_de_2__fl46blw10_48v_5n_m_de" material="1_1_06_eb463_509_fl46blw10_48v_5n_m_de_2__fl46blw10_48v_5n_m_de_material"/>
              <!-- Part 1_1_06_eb463_507_fl46blw10_48v_5n_m_de_2__fl46blw10_48v_5n_m_de_3 -->
              <geom type="mesh" class="visual" pos="-3.88578e-16 -0.106 -0.009" quat="0.382683 -4.80316e-14 6.00631e-14 0.92388" mesh="1_1_06_eb463_507_fl46blw10_48v_5n_m_de_2__fl46blw10_48v_5n_m_de" material="1_1_06_eb463_507_fl46blw10_48v_5n_m_de_2__fl46blw10_48v_5n_m_de_material"/>
              <!-- Part 1_1_31_eb463_510_fl46blw10_48v_5n_m_de_2__fl46blw10_48v_5n_m_de_4 -->
              <geom type="mesh" class="visual" pos="5.55112e-17 -0.053 -0.019" quat="9.92002e-15 0.19509 -0.980785 1.32116e-13" mesh="1_1_31_eb463_510_fl46blw10_48v_5n_m_de_2__fl46blw10_48v_5n_m_de" material="1_1_31_eb463_510_fl46blw10_48v_5n_m_de_2__fl46blw10_48v_5n_m_de_material"/>
              <!-- Part 1_1_02_eb461_502_fl46blw10_48v_5n_m_de_2__fl46blw10_48v_5n_m_de_4 -->
              <geom type="mesh" class="visual" pos="1.66533e-15 -0.053 -0.009" quat="9.92002e-15 0.19509 -0.980785 1.32116e-13" mesh="1_1_02_eb461_502_fl46blw10_48v_5n_m_de_2__fl46blw10_48v_5n_m_de" material="1_1_02_eb461_502_fl46blw10_48v_5n_m_de_2__fl46blw10_48v_5n_m_de_material"/>
              <!-- Part 1_1_06_eb463_509_fl46blw10_48v_5n_m_de_2__fl46blw10_48v_5n_m_de_4 -->
              <geom type="mesh" class="visual" pos="-1.66533e-16 -0.053 0.0225" quat="2.72248e-16 0.707107 -0.707107 5.20262e-16" mesh="1_1_06_eb463_509_fl46blw10_48v_5n_m_de_2__fl46blw10_48v_5n_m_de" material="1_1_06_eb463_509_fl46blw10_48v_5n_m_de_2__fl46blw10_48v_5n_m_de_material"/>
              <!-- Part 1_1_06_eb463_507_fl46blw10_48v_5n_m_de_2__fl46blw10_48v_5n_m_de_4 -->
              <geom type="mesh" class="visual" pos="-3.88578e-16 -0.053 0.009" quat="3.24743e-14 0.382683 -0.92388 1.27556e-13" mesh="1_1_06_eb463_507_fl46blw10_48v_5n_m_de_2__fl46blw10_48v_5n_m_de" material="1_1_06_eb463_507_fl46blw10_48v_5n_m_de_2__fl46blw10_48v_5n_m_de_material"/>
              <!-- Part 0001755652_1_1_30_gr_2202_asm_1_asm_1_1_30_gr_2202_asm_fl46blw10_48v_5n_m_de_2__fl46blw10_48v_5n_m_de_5 -->
              <geom type="mesh" class="visual" pos="0.00671751 -0.0992825 0.0235" quat="6.04121e-14 0.92388 -0.382683 4.75782e-14" mesh="0001755652_1_1_30_gr_2202_asm_1_asm_1_1_30_gr_2202_asm_fl46blw10_48v_5n_m_de_2__fl46blw10_48v_5n_m_de" material="0001755652_1_1_30_gr_2202_asm_1_asm_1_1_30_gr_2202_asm_fl46blw10_48v_5n_m_de_2__fl46blw10_48v_5n_m_de_material"/>
              <!-- Part 0001755652_1_1_30_gr_2202_asm_1_asm_1_1_30_gr_2202_asm_fl46blw10_48v_5n_m_de_2__fl46blw10_48v_5n_m_de_6 -->
              <geom type="mesh" class="visual" pos="0.00245878 -0.115176 0.0235" quat="6.04121e-14 0.92388 -0.382683 4.75782e-14" mesh="0001755652_1_1_30_gr_2202_asm_1_asm_1_1_30_gr_2202_asm_fl46blw10_48v_5n_m_de_2__fl46blw10_48v_5n_m_de" material="0001755652_1_1_30_gr_2202_asm_1_asm_1_1_30_gr_2202_asm_fl46blw10_48v_5n_m_de_2__fl46blw10_48v_5n_m_de_material"/>
              <!-- Part 0001755652_1_1_30_gr_2202_asm_1_asm_1_1_30_gr_2202_asm_fl46blw10_48v_5n_m_de_2__fl46blw10_48v_5n_m_de_7 -->
              <geom type="mesh" class="visual" pos="0.00671751 -0.0597175 -0.0235" quat="0.92388 -2.03433e-14 1.92069e-14 0.382683" mesh="0001755652_1_1_30_gr_2202_asm_1_asm_1_1_30_gr_2202_asm_fl46blw10_48v_5n_m_de_2__fl46blw10_48v_5n_m_de" material="0001755652_1_1_30_gr_2202_asm_1_asm_1_1_30_gr_2202_asm_fl46blw10_48v_5n_m_de_2__fl46blw10_48v_5n_m_de_material"/>
              <!-- Part 0001755652_1_1_30_gr_2202_asm_1_asm_1_1_30_gr_2202_asm_fl46blw10_48v_5n_m_de_2__fl46blw10_48v_5n_m_de_8 -->
              <geom type="mesh" class="visual" pos="0.00245878 -0.0438237 -0.0235" quat="0.92388 -2.03433e-14 1.92069e-14 0.382683" mesh="0001755652_1_1_30_gr_2202_asm_1_asm_1_1_30_gr_2202_asm_fl46blw10_48v_5n_m_de_2__fl46blw10_48v_5n_m_de" material="0001755652_1_1_30_gr_2202_asm_1_asm_1_1_30_gr_2202_asm_fl46blw10_48v_5n_m_de_2__fl46blw10_48v_5n_m_de_material"/>
              <!-- Part 0001755652_00mini_000_asm_1_asm_1_asm_00mini__20250103_a0001_asm_1_as_asm_1_1_30_gr_2202_asm_1_asm_1_1_30_gr_2202_asm_fl46blw10_48v_5n_m_de_2__fl46blw10_48v_5n_m_de_3 -->
              <geom type="mesh" class="visual" pos="-0.0091763 -0.103541 0.0235" quat="6.04121e-14 0.92388 -0.382683 4.75782e-14" mesh="0001755652_00mini_000_asm_1_asm_1_asm_00mini__20250103_a0001_asm_1_as_asm_1_1_30_gr_2202_asm_1_asm_1_1_30_gr_2202_asm_fl46blw10_48v_5n_m_de_2__fl46blw10_48v_5n_m_de" material="0001755652_00mini_000_asm_1_asm_1_asm_00mini__20250103_a0001_asm_1_as_asm_1_1_30_gr_2202_asm_1_asm_1_1_30_gr_2202_asm_fl46blw10_48v_5n_m_de_2__fl46blw10_48v_5n_m_de_material"/>
              <!-- Part 6706__300001_1_1_00mini_000_asm_1_asm_1_asm_00mini__20250103_a0001_asm_1_as_asm_1_1_30_gr_2202_asm_1_asm_1_1_30_gr_2202_asm_fl46blw10_48v_5n_m_de_2__fl46blw10_48v_5n_m_de_3 -->
              <geom type="mesh" class="visual" pos="-2.94209e-15 -0.106 0.02" quat="6.04121e-14 0.92388 -0.382683 4.75782e-14" mesh="6706__300001_1_1_00mini_000_asm_1_asm_1_asm_00mini__20250103_a0001_asm_1_as_asm_1_1_30_gr_2202_asm_1_asm_1_1_30_gr_2202_asm_fl46blw10_48v_5n_m_de_2__fl46blw10_48v_5n_m_de" material="6706__300001_1_1_00mini_000_asm_1_asm_1_asm_00mini__20250103_a0001_asm_1_as_asm_1_1_30_gr_2202_asm_1_asm_1_1_30_gr_2202_asm_fl46blw10_48v_5n_m_de_2__fl46blw10_48v_5n_m_de_material"/>
              <!-- Part 0001755650_00mini_000_asm_1_asm_1_asm_00mini__20250103_a0001_asm_1_as_asm_1_1_30_gr_2202_asm_1_asm_1_1_30_gr_2202_asm_fl46blw10_48v_5n_m_de_2__fl46blw10_48v_5n_m_de_3 -->
              <geom type="mesh" class="visual" pos="-3.10862e-15 -0.106 0.0204" quat="6.04121e-14 0.92388 -0.382683 4.75782e-14" mesh="0001755650_00mini_000_asm_1_asm_1_asm_00mini__20250103_a0001_asm_1_as_asm_1_1_30_gr_2202_asm_1_asm_1_1_30_gr_2202_asm_fl46blw10_48v_5n_m_de_2__fl46blw10_48v_5n_m_de" material="0001755650_00mini_000_asm_1_asm_1_asm_00mini__20250103_a0001_asm_1_as_asm_1_1_30_gr_2202_asm_1_asm_1_1_30_gr_2202_asm_fl46blw10_48v_5n_m_de_2__fl46blw10_48v_5n_m_de_material"/>
              <!-- Part 0001755652_00mini_000_asm_1_asm_1_asm_00mini__20250103_a0001_asm_1_as_asm_1_1_30_gr_2202_asm_1_asm_1_1_30_gr_2202_asm_fl46blw10_48v_5n_m_de_2__fl46blw10_48v_5n_m_de_4 -->
              <geom type="mesh" class="visual" pos="-0.0091763 -0.0554588 -0.0235" quat="0.92388 -2.03433e-14 1.92069e-14 0.382683" mesh="0001755652_00mini_000_asm_1_asm_1_asm_00mini__20250103_a0001_asm_1_as_asm_1_1_30_gr_2202_asm_1_asm_1_1_30_gr_2202_asm_fl46blw10_48v_5n_m_de_2__fl46blw10_48v_5n_m_de" material="0001755652_00mini_000_asm_1_asm_1_asm_00mini__20250103_a0001_asm_1_as_asm_1_1_30_gr_2202_asm_1_asm_1_1_30_gr_2202_asm_fl46blw10_48v_5n_m_de_2__fl46blw10_48v_5n_m_de_material"/>
              <!-- Part 6706__300001_1_1_00mini_000_asm_1_asm_1_asm_00mini__20250103_a0001_asm_1_as_asm_1_1_30_gr_2202_asm_1_asm_1_1_30_gr_2202_asm_fl46blw10_48v_5n_m_de_2__fl46blw10_48v_5n_m_de_4 -->
              <geom type="mesh" class="visual" pos="8.88178e-16 -0.053 -0.02" quat="0.92388 -2.03433e-14 1.92069e-14 0.382683" mesh="6706__300001_1_1_00mini_000_asm_1_asm_1_asm_00mini__20250103_a0001_asm_1_as_asm_1_1_30_gr_2202_asm_1_asm_1_1_30_gr_2202_asm_fl46blw10_48v_5n_m_de_2__fl46blw10_48v_5n_m_de" material="6706__300001_1_1_00mini_000_asm_1_asm_1_asm_00mini__20250103_a0001_asm_1_as_asm_1_1_30_gr_2202_asm_1_asm_1_1_30_gr_2202_asm_fl46blw10_48v_5n_m_de_2__fl46blw10_48v_5n_m_de_material"/>
              <!-- Part 0001755650_00mini_000_asm_1_asm_1_asm_00mini__20250103_a0001_asm_1_as_asm_1_1_30_gr_2202_asm_1_asm_1_1_30_gr_2202_asm_fl46blw10_48v_5n_m_de_2__fl46blw10_48v_5n_m_de_4 -->
              <geom type="mesh" class="visual" pos="1.66533e-16 -0.053 -0.0204" quat="0.92388 -2.03433e-14 1.92069e-14 0.382683" mesh="0001755650_00mini_000_asm_1_asm_1_asm_00mini__20250103_a0001_asm_1_as_asm_1_1_30_gr_2202_asm_1_asm_1_1_30_gr_2202_asm_fl46blw10_48v_5n_m_de_2__fl46blw10_48v_5n_m_de" material="0001755650_00mini_000_asm_1_asm_1_asm_00mini__20250103_a0001_asm_1_as_asm_1_1_30_gr_2202_asm_1_asm_1_1_30_gr_2202_asm_fl46blw10_48v_5n_m_de_2__fl46blw10_48v_5n_m_de_material"/>
              <!-- Link ankle_subassembly_2 -->
              <body name="ankle_subassembly_2" pos="-3.88578e-16 -0.26 -0.02" quat="0.888105 -5.59873e-16 0 -0.459641">
                <!-- Joint from shin_subassembly_sym to ankle_subassembly_2 -->
                <joint axis="0 0 1" name="ankley_left" type="hinge"/>
                <inertial pos="1.62086e-08 -0.000727483 0.02" mass="0.0168168" fullinertia="5.19458e-06 4.86353e-06 8.35665e-07 -2.61119e-12 4.35145e-12 7.24871e-13"/>
                <!-- Part hex_socket_head_cap_screw_m2_5x0_45_x_6__ec244025d76f8b83b2775022a2cb3232_22 -->
                <!-- Part 07534_05x40_catpart_4 -->
                <geom type="mesh" class="visual" pos="-4.77396e-15 0.0249999 0.02" quat="0.707107 8.4179e-14 -6.29496e-14 -0.707107" mesh="07534_05x40_catpart" material="07534_05x40_catpart_material"/>
                <!-- Part ujoint_2 -->
                <geom type="mesh" class="visual" pos="-7.77156e-16 -4.65253e-15 0.02" quat="3.82286e-14 -0.707107 -7.20535e-14 -0.707107" mesh="ujoint" material="ujoint_material"/>
                <!-- Part hex_socket_head_cap_screw_m2_5x0_45_x_6__ec244025d76f8b83b2775022a2cb3232_23 -->
                <!-- Part spacer_ujoint_3 -->
                <geom type="mesh" class="visual" pos="2.22045e-16 -6.91114e-15 0.02" quat="0.699514 -5.29255e-14 0.714619 5.10095e-14" mesh="spacer_ujoint" material="spacer_ujoint_material"/>
                <!-- Part hex_thin_nut_grade_a___b_m4x0_7__a8228d9ce5dcc05f24da0a2f74d882f3_8 -->
                <geom type="mesh" class="visual" pos="-2.25375e-14 -0.02204 0.02" quat="0.494631 -0.494631 0.505312 0.505312" mesh="hex_thin_nut_grade_a___b_m4x0_7__a8228d9ce5dcc05f24da0a2f74d882f3" material="hex_thin_nut_grade_a___b_m4x0_7__a8228d9ce5dcc05f24da0a2f74d882f3_material"/>
                <!-- Part part_3_5 -->
                <geom type="mesh" class="visual" pos="1.11022e-15 -6.11663e-15 0.0205" quat="3.83736e-14 -0.707107 -7.21645e-14 -0.707107" mesh="part_3" material="part_3_material"/>
                <!-- Part bearing_5_16_5_7 -->
                <geom type="mesh" class="visual" pos="8.54872e-15 -0.01594 0.02" quat="0.699514 -5.26437e-14 0.714619 5.29386e-14" mesh="bearing_5_16_5" material="bearing_5_16_5_material"/>
                <!-- Part bearing_15_21_4_13 -->
                <geom type="mesh" class="visual" pos="-5.55112e-16 -8.67709e-15 0.04" quat="2.498e-16 -1.31492e-15 0.707107 -0.707107" mesh="bearing_15_21_4" material="bearing_15_21_4_material"/>
                <!-- Part hex_socket_head_cap_screw_m2_5x0_45_x_6__ec244025d76f8b83b2775022a2cb3232_24 -->
                <!-- Part hex_socket_head_cap_screw_m2_5x0_45_x_6__ec244025d76f8b83b2775022a2cb3232_25 -->
                <!-- Part part_3_6 -->
                <geom type="mesh" class="visual" pos="-2.33147e-15 -2.26555e-15 0.0195" quat="5.01835e-14 0.707107 5.31797e-14 -0.707107" mesh="part_3" material="part_3_material"/>
                <!-- Part hex_socket_head_cap_screw_m2_5x0_45_x_6__ec244025d76f8b83b2775022a2cb3232_26 -->
                <!-- Part hex_socket_head_cap_screw_m2_5x0_45_x_6__ec244025d76f8b83b2775022a2cb3232_27 -->
                <!-- Part bearing_5_16_5_8 -->
                <geom type="mesh" class="visual" pos="3.44169e-15 0.0209456 0.02" quat="0.999973 -2.00187e-14 -0.00732917 6.31509e-14" mesh="bearing_5_16_5" material="bearing_5_16_5_material"/>
                <!-- Part spacer_ujoint_4 -->
                <geom type="mesh" class="visual" pos="5.32907e-15 5.64895e-06 0.02" quat="4.00138e-14 -0.701905 -7.31637e-14 -0.71227" mesh="spacer_ujoint" material="spacer_ujoint_material"/>
                <!-- Part bearing_15_21_4_14 -->
                <geom type="mesh" class="visual" pos="0 0 0" quat="0.707107 0.707107 0 2.25061e-19" mesh="bearing_15_21_4" material="bearing_15_21_4_material"/>
                <!-- Link foot_subassembly_2 -->
                <body name="foot_subassembly_2" pos="8.54872e-15 -0.01594 0.02" quat="0.501732 0.501732 -0.498262 0.498262">
                  <!-- Joint from ankle_subassembly_2 to foot_subassembly_2 -->
                  <joint axis="0 0 1" name="anklex_left" type="hinge"/>
                  <inertial pos="8.52312e-09 -0.0138418 -0.052232" mass="0.122498" fullinertia="0.000163413 0.000162266 7.07692e-05 -1.15065e-10 -2.96383e-11 1.11374e-05"/>
                  <!-- Part hex_socket_head_cap_screw_m2_5x0_45_x_6__ec244025d76f8b83b2775022a2cb3232_28 -->
                  <!-- Part 27628_01_050_catpart_7 -->
                  <geom type="mesh" class="visual" pos="0.021 3.53792e-08 -0.0660002" quat="7.40815e-17 -0.707107 -0.707107 -7.17817e-17" mesh="27628_01_050_catpart" material="27628_01_050_catpart_material"/>
                  <!-- Part hex_socket_head_cap_screw_m2_5x0_45_x_6__ec244025d76f8b83b2775022a2cb3232_29 -->
                  <!-- Part 07534_05x20_catpart_7 -->
                  <geom type="mesh" class="visual" pos="0.036 0 -0.066" quat="2.22045e-16 5.16179e-18 1 2.22045e-16" mesh="07534_05x20_catpart" material="07534_05x20_catpart_material"/>
                  <!-- Part 27628_01_050_catpart_8 -->
                  <geom type="mesh" class="visual" pos="-0.021 -1.89504e-08 -0.066" quat="2.66399e-17 0.707107 0.707107 -6.15091e-18" mesh="27628_01_050_catpart" material="27628_01_050_catpart_material"/>
                  <!-- Part 07534_05x20_catpart_8 -->
                  <geom type="mesh" class="visual" pos="-0.036 0 -0.066" quat="1 5.63152e-17 1.66533e-16 1.59595e-16" mesh="07534_05x20_catpart" material="07534_05x20_catpart_material"/>
                  <!-- Part hat_small_2 -->
                  <geom type="mesh" class="visual" pos="2.35922e-16 -0.035 -0.0385" quat="0.5 -0.5 -0.5 -0.5" mesh="hat_small" material="hat_small_material"/>
                  <!-- Part hex_socket_head_cap_screw_m2_5x0_45_x_6__ec244025d76f8b83b2775022a2cb3232_30 -->
                  <!-- Part foot_2 -->
                  <geom type="mesh" class="visual" pos="1.249e-16 -0.035 -0.0385" quat="0.5 -0.5 -0.5 -0.5" mesh="foot" material="foot_material"/>
                  <geom name="left_foot1_collision" class="collision" type="capsule" size="0.015 0.05" fromto="-0.032 -0.02 0.005 0.032 -0.02 0.005"/>
                  <geom name="left_foot2_collision" class="collision" type="capsule" size="0.015 0.05" fromto="-0.032 -0.02 -0.10 0.032 -0.02 -0.10"/>
                  <geom name="left_foot3_collision" class="collision" type="capsule" size="0.015 0.05" fromto="-0.032 -0.02 0.005 -0.032 -0.02 -0.10"/>
                  <geom name="left_foot4_collision" class="collision" type="capsule" size="0.015 0.05" fromto="0.032 -0.02 0.005 0.032 -0.02 -0.10"/>
                  <geom name="left_foot5_collision" class="collision" type="capsule" size="0.015 0.05" fromto="-0.032 -0.02 -0.02 0.032 -0.02 -0.02"/>
                  <geom name="left_foot6_collision" class="collision" type="capsule" size="0.015 0.05" fromto="-0.032 -0.02 -0.06 0.032 -0.02 -0.06"/>
                  <!-- Frame foot_left -->
                  <site group="3" name="foot_left" pos="-6.35351e-08 -0.035 -0.0480606" quat="0.5 -0.5 0.5 0.5"/>
                </body>
              </body>
            </body>
          </body>
        </body>
      </body>
      <!-- Link torso_mesh -->
      <body name="torso_mesh" pos="0 0 -0.1" quat="1.2038e-27 1 -2.16621e-27 -2.53152e-15">
        <!-- Joint from torso_subassembly to torso_mesh -->
        <!-- Joint is "fixed", skipping it -->
        <inertial pos="-2.38855e-06 3.15368e-57 -0.229519" mass="4" fullinertia="0.0564008 0.0460323 0.0120348 6.54226e-46 -1.78695e-06 2.25397e-61"/>
        <!-- Part torso_mesh -->
        <geom type="mesh" class="visual" pos="0.025 -0.503548 -0.15" quat="0 1 0 0" mesh="torso_mesh" material="torso_mesh_material"/>
      </body>
    </body>
  </worldbody>
  <asset>
    <mesh file="actuation_ankle.stl"/>
    <mesh file="femur_22.stl"/>
    <mesh file="femur_12.stl"/>
    <mesh file="hipxy_sym.stl"/>
    <mesh file="27628_01_050_catpart.stl"/>
    <mesh file="0001755652_00mini_000_asm_1_asm_1_asm_00mini__20250103_a0001_asm_1_as_asm_1_1_30_gr_2202_asm_1_asm_1_1_30_gr_2202_asm_fl46blw10_48v_5n_m_de_2__fl46blw10_48v_5n_m_de.stl"/>
    <mesh file="1_1_06_eb463_509_fl46blw10_48v_5n_m_de_2__fl46blw10_48v_5n_m_de.stl"/>
    <mesh file="tibias22_sym.stl"/>
    <mesh file="hipxy.stl"/>
    <mesh file="femur_12_sym.stl"/>
    <mesh file="knee_actuation.stl"/>
    <mesh file="rmdx43.stl"/>
    <mesh file="bearing_35_72_17.stl"/>
    <mesh file="6706__300001_1_1_00mini_000_asm_1_asm_1_asm_00mini__20250103_a0001_asm_1_as_asm_1_1_30_gr_2202_asm_1_asm_1_1_30_gr_2202_asm_fl46blw10_48v_5n_m_de_2__fl46blw10_48v_5n_m_de.stl"/>
    <mesh file="07534_05x40_catpart.stl"/>
    <mesh file="torso22.stl"/>
    <mesh file="knee_rod22.stl"/>
    <mesh file="bearing_15_21_4.stl"/>
    <mesh file="torso12.stl"/>
    <mesh file="1_1_31_qt_942_1.stl"/>
    <mesh file="robstride02.stl"/>
    <mesh file="tibias12_sym.stl"/>
    <mesh file="xt_30_2x2_f.stl"/>
    <mesh file="hex_thin_nut_grade_a___b_m4x0_7__a8228d9ce5dcc05f24da0a2f74d882f3.stl"/>
    <mesh file="femur_22_sym.stl"/>
    <mesh file="foot.stl"/>
    <mesh file="1_1_02_eb901_558_1.stl"/>
    <mesh file="knee_rod12.stl"/>
    <mesh file="1_1_06_eb903_537_af0_1.stl"/>
    <mesh file="torso_mesh.stl"/>
    <mesh file="hipz22.stl"/>
    <mesh file="1_1_06_eb463_507_fl46blw10_48v_5n_m_de_2__fl46blw10_48v_5n_m_de.stl"/>
    <mesh file="0001755650_00mini_000_asm_1_asm_1_asm_00mini__20250103_a0001_asm_1_as_asm_1_1_30_gr_2202_asm_1_asm_1_1_30_gr_2202_asm_fl46blw10_48v_5n_m_de_2__fl46blw10_48v_5n_m_de.stl"/>
    <mesh file="bearing_5_16_5.stl"/>
    <mesh file="hat_big.stl"/>
    <mesh file="tibias22.stl"/>
    <mesh file="part_3.stl"/>
    <mesh file="1_1_02_eb461_502_fl46blw10_48v_5n_m_de_2__fl46blw10_48v_5n_m_de.stl"/>
    <mesh file="07534_05x20_catpart.stl"/>
    <mesh file="1_1_31_eb463_510_fl46blw10_48v_5n_m_de_2__fl46blw10_48v_5n_m_de.stl"/>
    <mesh file="hipz22_sym.stl"/>
    <mesh file="hipz12.stl"/>
    <mesh file="robstrideo0.stl"/>
    <mesh file="hat_small.stl"/>
    <mesh file="hat_femur.stl"/>
    <mesh file="1_1_06_eb903_538_1.stl"/>
    <mesh file="spacer_ujoint.stl"/>
    <mesh file="hipz12_sym.stl"/>
    <mesh file="0001755652_1_1_30_gr_2202_asm_1_asm_1_1_30_gr_2202_asm_fl46blw10_48v_5n_m_de_2__fl46blw10_48v_5n_m_de.stl"/>
    <mesh file="knee_rod22_sym.stl"/>
    <mesh file="tibias12.stl"/>
    <mesh file="ujoint.stl"/>
    <mesh file="knee_rod12_sym.stl"/>
    <mesh file="robstrideo3.stl"/>
    <material name="robstrideo0_material" rgba="0.301961 0.301961 0.301961 1"/>
    <material name="torso22_material" rgba="1 0 0 1"/>
    <material name="bearing_35_72_17_material" rgba="0.768627 0.886275 0.952941 1"/>
    <material name="torso12_material" rgba="1 0 0 1"/>
    <material name="xt_30_2x2_f_material" rgba="0.917647 0.917647 0.917647 1"/>
    <material name="hipz12_material" rgba="1 0 0 1"/>
    <material name="robstride02_material" rgba="0.301961 0.301961 0.301961 1"/>
    <material name="hipz22_material" rgba="1 0 0 1"/>
    <material name="hipxy_material" rgba="1 0 0 1"/>
    <material name="knee_rod22_material" rgba="0.917647 0.917647 0.917647 1"/>
    <material name="bearing_15_21_4_material" rgba="0.647059 0.647059 0.647059 1"/>
    <material name="robstrideo3_material" rgba="0.301961 0.301961 0.301961 1"/>
    <material name="knee_rod12_material" rgba="0.917647 0.917647 0.917647 1"/>
    <material name="bearing_5_16_5_material" rgba="0.917647 0.917647 0.917647 1"/>
    <material name="knee_actuation_material" rgba="0.917647 0.917647 0.917647 1"/>
    <material name="femur_22_material" rgba="1 0 0 1"/>
    <material name="femur_12_material" rgba="1 0 0 1"/>
    <material name="hat_femur_material" rgba="1 0 0 1"/>
    <material name="part_3_material" rgba="1 0 0 1"/>
    <material name="1_1_31_qt_942_1_material" rgba="0.768627 0.886275 0.952941 1"/>
    <material name="1_1_06_eb903_538_1_material" rgba="0.498039 0.498039 0.498039 1"/>
    <material name="1_1_06_eb903_537_af0_1_material" rgba="0.768627 0.886275 0.952941 1"/>
    <material name="1_1_02_eb901_558_1_material" rgba="0.917647 0.917647 0.917647 1"/>
    <material name="rmdx43_material" rgba="0.301961 0.301961 0.301961 1"/>
    <material name="tibias22_material" rgba="1 0 0 1"/>
    <material name="27628_01_050_catpart_material" rgba="0.690196 0.690196 0.690196 1"/>
    <material name="hex_thin_nut_grade_a___b_m4x0_7__a8228d9ce5dcc05f24da0a2f74d882f3_material" rgba="0.603922 0.647059 0.686275 1"/>
    <material name="07534_05x40_catpart_material" rgba="0.690196 0.690196 0.690196 1"/>
    <material name="07534_05x20_catpart_material" rgba="0.690196 0.690196 0.690196 1"/>
    <material name="actuation_ankle_material" rgba="0.917647 0.917647 0.917647 1"/>
    <material name="hat_big_material" rgba="1 0 0 1"/>
    <material name="tibias12_material" rgba="1 0 0 1"/>
    <material name="1_1_31_eb463_510_fl46blw10_48v_5n_m_de_2__fl46blw10_48v_5n_m_de_material" rgba="1 1 1 1"/>
    <material name="1_1_02_eb461_502_fl46blw10_48v_5n_m_de_2__fl46blw10_48v_5n_m_de_material" rgba="1 1 1 1"/>
    <material name="1_1_06_eb463_509_fl46blw10_48v_5n_m_de_2__fl46blw10_48v_5n_m_de_material" rgba="1 1 1 1"/>
    <material name="1_1_06_eb463_507_fl46blw10_48v_5n_m_de_2__fl46blw10_48v_5n_m_de_material" rgba="1 1 1 1"/>
    <material name="0001755652_1_1_30_gr_2202_asm_1_asm_1_1_30_gr_2202_asm_fl46blw10_48v_5n_m_de_2__fl46blw10_48v_5n_m_de_material" rgba="1 1 1 1"/>
    <material name="0001755652_00mini_000_asm_1_asm_1_asm_00mini__20250103_a0001_asm_1_as_asm_1_1_30_gr_2202_asm_1_asm_1_1_30_gr_2202_asm_fl46blw10_48v_5n_m_de_2__fl46blw10_48v_5n_m_de_material" rgba="1 1 1 1"/>
    <material name="6706__300001_1_1_00mini_000_asm_1_asm_1_asm_00mini__20250103_a0001_asm_1_as_asm_1_1_30_gr_2202_asm_1_asm_1_1_30_gr_2202_asm_fl46blw10_48v_5n_m_de_2__fl46blw10_48v_5n_m_de_material" rgba="1 1 1 1"/>
    <material name="0001755650_00mini_000_asm_1_asm_1_asm_00mini__20250103_a0001_asm_1_as_asm_1_1_30_gr_2202_asm_1_asm_1_1_30_gr_2202_asm_fl46blw10_48v_5n_m_de_2__fl46blw10_48v_5n_m_de_material" rgba="1 1 1 1"/>
    <material name="ujoint_material" rgba="1 0 0 1"/>
    <material name="spacer_ujoint_material" rgba="0.917647 0.917647 0.917647 1"/>
    <material name="hat_small_material" rgba="1 0 0 1"/>
    <material name="foot_material" rgba="0.301961 0.301961 0.301961 1"/>
    <material name="hipz22_sym_material" rgba="1 0 0 1"/>
    <material name="hipz12_sym_material" rgba="1 0 0 1"/>
    <material name="hipxy_sym_material" rgba="1 0 0 1"/>
    <material name="knee_rod22_sym_material" rgba="0.917647 0.917647 0.917647 1"/>
    <material name="femur_12_sym_material" rgba="1 0 0 1"/>
    <material name="femur_22_sym_material" rgba="1 0 0 1"/>
    <material name="knee_rod12_sym_material" rgba="0.917647 0.917647 0.917647 1"/>
    <material name="tibias12_sym_material" rgba="1 0 0 1"/>
    <material name="tibias22_sym_material" rgba="1 0 0 1"/>
    <material name="torso_mesh_material" rgba="0.301961 0.301961 0.301961 1"/>
  </asset>
  <equality/>


    <sensor>
    <gyro name="imu_ang_vel" site="imu"/>
    <velocimeter name="imu_lin_vel" site="imu"/>
    <accelerometer name="imu_lin_acc" site="imu"/>
    <subtreeangmom name="root_angmom" body="torso_mesh"/>
    </sensor>
  
  

</mujoco>
